Workbook
Name Excel_BuiltIn_Print_Area: '01F1_GTA_A'!$B$3:$P$127
Name Excel_BuiltIn_Print_Area: '01F1_GTA_P'!$B$3:$P$128
Name Excel_BuiltIn_Print_Area: '01F1_KGC_A'!$B$3:$P$126
Name Excel_BuiltIn_Print_Area: '01F1_KGC_P'!$B$3:$O$126
Name Excel_BuiltIn_Print_Area: '87B_AT'!$B$3:$O$40
Name Excel_BuiltIn_Print_Area: '87B_MT1'!$B$3:$P$55
Name Excel_BuiltIn_Print_Area: '87B_MT2'!$B$3:$O$55
Name Excel_BuiltIn_Print_Area: BC1_P1!$B$3:$O$72
Name Excel_BuiltIn_Print_Area: BC2_P1!$B$3:$P$72
Name Excel_BuiltIn_Print_Area: BC3_P2!$B$3:$O$72
Name Excel_BuiltIn_Print_Area: BC4_P2!$B$3:$O$72
Name Excel_BuiltIn_Print_Area: Capa!$B$3:$K$4
Name Excel_BuiltIn_Print_Area: Consistidos!$B$3:$L$44
Name Excel_BuiltIn_Print_Area: CTR!$B$3:$N$36
Name Excel_BuiltIn_Print_Area: GTD_11!$B$3:$O$94
Name Excel_BuiltIn_Print_Area: GTD_12!$B$3:$O$94
Name Excel_BuiltIn_Print_Area: GTD_13!$B$3:$O$94
Name Excel_BuiltIn_Print_Area: GTD_14!$B$3:$O$94
Name Excel_BuiltIn_Print_Area: GTD_15!$B$3:$O$94
Name Excel_BuiltIn_Print_Area: GTD_21!$B$3:$O$94
Name Excel_BuiltIn_Print_Area: GTD_22!$B$3:$O$94
Name Excel_BuiltIn_Print_Area: GTD_23!$B$3:$O$94
Name Excel_BuiltIn_Print_Area: GTD_24!$B$3:$O$94
Name Excel_BuiltIn_Print_Area: GTD_25!$B$3:$O$94
Name Excel_BuiltIn_Print_Area: IB_23kV!$B$3:$P$71
Name Excel_BuiltIn_Print_Area: PSACA_CC!$B$3:$N$79
Name Excel_BuiltIn_Print_Area: SPS_TR1_TR2!$B$3:$M$63
Name Excel_BuiltIn_Print_Area: TR1_A!$B$3:$P$203
Name Excel_BuiltIn_Print_Area: TR1_P!$B$3:$P$185
Name Excel_BuiltIn_Print_Area: TR1_RMT!$B$3:$P$28
Name Excel_BuiltIn_Print_Area: TR2_A!$B$3:$O$203
Name Excel_BuiltIn_Print_Area: TR2_P!$B$3:$N$185
Name Excel_BuiltIn_Print_Area: TR2_RMT!$B$3:$P$28
Name Excel_BuiltIn_Print_Area: 'TRF-1'!$B$3:$P$102
Name Excel_BuiltIn_Print_Area: 'TRF-2'!$B$3:$O$102
Name Excel_BuiltIn_Print_Area: TRF3_A!$B$3:$P$118
Name Excel_BuiltIn_Print_Area: TRF3_P!$B$3:$P$119
Name Excel_BuiltIn_Print_Area: UCCD1!$B$3:$O$48
Name Excel_BuiltIn_Print_Titles: '01F1_GTA_A'!$3:$5
Name Excel_BuiltIn_Print_Titles: '01F1_GTA_P'!$3:$5
Name Excel_BuiltIn_Print_Titles: '01F1_KGC_A'!$3:$5
Name Excel_BuiltIn_Print_Titles: '01F1_KGC_P'!$3:$5
Name Excel_BuiltIn_Print_Titles: '87B_AT'!$3:$5
Name Excel_BuiltIn_Print_Titles: '87B_MT1'!$3:$5
Name Excel_BuiltIn_Print_Titles: '87B_MT2'!$3:$5
Name Excel_BuiltIn_Print_Titles: BC1_P1!$3:$5
Name Excel_BuiltIn_Print_Titles: BC2_P1!$3:$5
Name Excel_BuiltIn_Print_Titles: BC3_P2!$3:$5
Name Excel_BuiltIn_Print_Titles: BC4_P2!$3:$5
Name Excel_BuiltIn_Print_Titles: Capa!$3:$4
Name Excel_BuiltIn_Print_Titles: Consistidos!$3:$5
Name Excel_BuiltIn_Print_Titles: CTR!$3:$5
Name Excel_BuiltIn_Print_Titles: GTD_11!$3:$5
Name Excel_BuiltIn_Print_Titles: GTD_12!$3:$5
Name Excel_BuiltIn_Print_Titles: GTD_13!$3:$5
Name Excel_BuiltIn_Print_Titles: GTD_14!$3:$5
Name Excel_BuiltIn_Print_Titles: GTD_15!$3:$5
Name Excel_BuiltIn_Print_Titles: GTD_21!$3:$5
Name Excel_BuiltIn_Print_Titles: GTD_22!$3:$5
Name Excel_BuiltIn_Print_Titles: GTD_23!$3:$5

Sheet Capa
A1: #VALUE! | C1: SUBESTAÇÃO RGE GRAVATAÍ 4 (SE_GTD)
C2: Lista de Pontos Supervisionados
J3: COS
B6: Rede
B7: IP Adress: | C7: 10.34.13.2
B8: Mascara: | C8: 255255255224
B9: Gateway: | C9: 10.34.13.1
B10: Endereço: | C10: 13
B11: Protocolo N3: | C11: DNP3
B12: Protocolo N2: | C12: Siemens
B13: Protocolo Relés: | C13: IEC-61850
B15: 1. Rede Link
B16: IED | C16: Painel | D16: Módulo | E16: Descrição | F16: Protocolo | G16: IP
B17: SICAM PAS | C17: PSSD | D17: CTR | E17: CONCENTRADORA / DISTRIBUIÇÃO | F17: IEC-61850/DNP3/Modbus | G17: 10.34.13.2
B18: SIEMENS RS900 | C18: PSSD | D18: SW3 | E18: SWITCH | F18: TCP/IP | G18: 10.34.13.3
G19: 10.34.13.4
G20: 10.34.13.5
B21: LANDIS + GYR | C21: PMT1 | D21: 37M1 | E21: MEDIÇÃO PERDAS TR1AT | F21: TCP/IP | G21: 0.0.0.0
B22: LANDIS + GYR | C22: PMT1 | D22: 37M2 | E22: MEDIÇÃO PERDAS TR1MT | F22: TCP/IP | G22: 0.0.0.0
B23: LANDIS + GYR | C23: PMT1 | D23: 37M3 | E23: MEDIÇÃO PERDAS GTD11 (AL11) | F23: TCP/IP | G23: 0.0.0.0
B24: LANDIS + GYR | C24: PMT1 | D24: 37M4 | E24: MEDIÇÃO PERDAS GTD12 (AL12) | F24: TCP/IP | G24: 0.0.0.0
B25: LANDIS + GYR | C25: PMT1 | D25: 37M5 | E25: MEDIÇÃO PERDAS GTD13 (AL13) | F25: TCP/IP | G25: 0.0.0.0
B26: LANDIS + GYR | C26: PMT1 | D26: 37M6 | E26: MEDIÇÃO PERDAS GTD14 (AL14) | F26: TCP/IP | G26: 0.0.0.0
B27: LANDIS + GYR | C27: PMT1 | D27: 37M7 | E27: MEDIÇÃO PERDAS GTD15 (AL15) | F27: TCP/IP | G27: 0.0.0.0
B28: LANDIS + GYR | C28: PMT1 | D28: 37M8 | E28: MEDIÇÃO PERDAS TRF MT1 | F28: TCP/IP | G28: 0.0.0.0
B29: LANDIS + GYR | C29: PMT1 | D29: 37M9 | E29: MEDIÇÃO PERDAS FUT | F29: TCP/IP | G29: 0.0.0.0
B30: LANDIS + GYR | C30: PMT1 | D30: 37M10 | E30: MEDIÇÃO PERDAS FUT | F30: TCP/IP | G30: 0.0.0.0
B31: LANDIS + GYR | C31: PMT1 | D31: 37M11 | E31: MEDIÇÃO PERDAS FUT | F31: TCP/IP | G31: 0.0.0.0
B32: LANDIS + GYR | C32: PMT1 | D32: 37M12 | E32: MEDIÇÃO PERDAS FUT | F32: TCP/IP | G32: 0.0.0.0
... B48: RS900 | C48: PMT2 | D48: SW2 | E48: SWITCH PMT2 | F48: TCP/IP | G48: 0.0.0.0
B52: 2. Rede Local | C52: GTW: 10.39.13.1 | D52: MSK: 255.255.255.192
B53: IED | C53: Painel | D53: Módulo | E53: Descrição | F53: Protocolo | G53: IP
B54: CTR | C54: PSSD | D54: SIEMENS SICAM PAS | E54: CONCENTRADORA / AQUISIÇÃO | F54: IEC-61850/DNP3/Modbus | G54: IP:10.39.13.2
B55: SOL | C55: PSSD | D55: SICAM SCC | E55: OPERAÇÃO, MONITORAMENTO E ANÁLISE LOCAL | F55: IEC-61850 | G55: IP:10.39.13.3
B56: UCCD | C56: PSSD | D56: SIEMENS SICAM A800/UAC | E56: UNIDADE TERMINAL | F56: IEC-61850 | G56: IP:10.39.13.4
B57: GE REASON RT430 | C57: PSSD | D57: GPS | E57: SINCRONIZADOR TEMPORAL | F57: TCP/IP | G57: IP:10.39.13.5
B58: SIEMENS RSG2100 | C58: PSSD | D58: SW T1 | E58: SWITCH | F58: TCP/IP | G58: IP:10.39.13.6
B59: SIEMENS RSG2100 | C59: PSSD | D59: SW T2 | E59: SWITCH | F59: TCP/IP | G59: IP:10.39.13.7
B60: SMAL | C60: PSSD | D60: Maquina Engenharia | E60: OPERAÇÃO, MONITORAMENTO E ANÁLISE LOCAL | F60: TCP/IP | G60: IP:10.39.13.8 | H60: ?
B61: 01F1 | C61: PPL1 | D61: LT_GTA_P | E61: RELÉ DE PROTEÇÃO 7SA86 | F61: IEC-61850 | G61: IP:10.39.13.9
...

Sheet CTR
A1: #VALUE! | C1: SUBESTAÇÃO RGE GRAVATAÍ 4 (SE_GTD)
C2: Lista de Pontos Supervisionados
C3: Falhas de Comunicação (Origem SICAM PAS) | G3: Concentradora: SICAM PAS | M3: COS
C4: Protocolo: DNP3 | G4: Protocolo: DNP3 IP:10.34.13.2 End:13
A5: IED | B5: Módulo | C5: Descrição do ponto | D5: Variável | E5: Endereço Variável | F5: Variação: | G5: Tipo | H5: Origem | I5: Lógica | J5: Endereço DNP3 | K5: N2 | L5: N3 | M5: NIVEL3
A6: Digitais
A7: 01F1 | B7: LT_GTA | C7: Falha Comunicação IED 01F1 - (Linha GTA - PPL1) | F7: 1 Atuado | G7: Digital Simples | H7: UCCD1 | I7: Direto | J7: *
A8: 01F2 | B8: LT_GTA | C8: Falha Comunicação IED 01F2 - (Linha GTA - PPL1) | F8: 1 Atuado | G8: Digital Simples | H8: UCCD1 | I8: Direto | J8: * | M8: =VLOOKUP(Z8,[1]ETerra_D!$A$1:$D$30000,4,0) -> #N/A
A9: 02F1 | B9: LT_KGC | C9: Falha Comunicação IED 02F1 - (Linha KGC - PPL2) | F9: 1 Atuado | G9: Digital Simples | H9: UCCD1 | I9: Direto | J9: * | M9: =VLOOKUP(Z9,[1]ETerra_D!$A$1:$D$30000,4,0) -> #N/A
A10: 02F2 | B10: LT_KGC | C10: Falha Comunicação IED 02F2 - (Linha KGC - PPL2) | F10: 1 Atuado | G10: Digital Simples | H10: UCCD1 | I10: Direto | J10: * | M10: =VLOOKUP(Z10,[1]ETerra_D!$A$1:$D$30000,4,0) -> #N/A
A11: 05F1 | B11: TRF-3 | C11: Falha Comunicação IED 05F1 - (Transferência 69kV - PPT-AT) | F11: 1 Atuado | G11: Digital Simples | H11: UCCD1 | I11: Direto | J11: * | M11: =VLOOKUP(Z11,[1]ETerra_D!$A$1:$D$30000,4,0) -> #N/A
A12: 05F2 | B12: TRF-3 | C12: Falha Comunicação IED 05F2 - (Transferência 69kV - PPT-AT) | F12: 1 Atuado | G12: Digital Simples | H12: UCCD1 | I12: Direto | J12: * | M12: =VLOOKUP(Z12,[1]ETerra_D!$A$1:$D$30000,4,0) -> #N/A
A13: 34F1 | B13: 87B_AT | C13: Falha Comunicação IED 34F1 - (Diferencial de Barras 69kV - PPBAT) | F13: 1 Atuado | G13: Digital Simples | H13: UCCD1 | I13: Direto | J13: * | M13: =VLOOKUP(Z13,[1]ETerra_D!$A$1:$D$30000,4,0) -> #N/A
A14: 06F1 | B14: TR1 | C14: Falha Comunicação IED 06F1 - (Transformador 1 - PPT1) | F14: 1 Atuado | G14: Digital Simples | H14: UCCD1 | I14: Direto | J14: * | M14: =VLOOKUP(Z14,[1]ETerra_D!$A$1:$D$30000,4,0) -> #N/A
A15: 06F2 | B15: TR1 | C15: Falha Comunicação IED 06F2 - (Transformador 1 - PPT1) | F15: 1 Atuado | G15: Digital Simples | H15: UCCD1 | I15: Direto | J15: * | M15: =VLOOKUP(Z15,[1]ETerra_D!$A$1:$D$30000,4,0) -> #N/A
A16: 06F3 | B16: TR1 | C16: Falha Comunicação IED 06F3 - (Transformador 1 - TR1) | F16: 1 Atuado | G16: Digital Simples | H16: UCCD1 | I16: Direto | J16: *
A17: 07F1 | B17: TR2 | C17: Falha Comunicação IED 07F1 - (Transformador 2 - PPT2) | F17: 1 Atuado | G17: Digital Simples | H17: UCCD1 | I17: Direto | J17: * | M17: =VLOOKUP(Z17,[1]ETerra_D!$A$1:$D$30000,4,0) -> #N/A
A18: 07F2 | B18: TR2 | C18: Falha Comunicação IED 07F2 - (Transformador 2 - PPT2) | F18: 1 Atuado | G18: Digital Simples | H18: UCCD1 | I18: Direto | J18: * | M18: =VLOOKUP(Z18,[1]ETerra_D!$A$1:$D$30000,4,0) -> #N/A
A19: 07F3 | B19: TR2 | C19: Falha Comunicação IED 07F3 - (Transformador 2 - TR2) | F19: 1 Atuado | G19: Digital Simples | H19: UCCD1 | I19: Direto | J19: *
A20: 11F1 | B20: GTD11 | C20: Falha Comunicação IED 11F1 - (Alimentador 11 - Barra P1 - PAL8) | F20: 1 Atuado | G20: Digital Simples | H20: UCCD1 | I20: Direto | J20: * | M20: =VLOOKUP(Z20,[1]ETerra_D!$A$1:$D$30000,4,0) -> #N/A
A21: 12F1 | B21: GTD12 | C21: Falha Comunicação IED 12F1 - (Alimentador 12 - Barra P1 - PAL8) | F21: 1 Atuado | G21: Digital Simples | H21: UCCD1 | I21: Direto | J21: * | M21: =VLOOKUP(Z25,[1]ETerra_D!$A$1:$D$30000,4,0) -> #N/A
A22: 13F1 | B22: GTD13 | C22: Falha Comunicação IED 13F1 - (Alimentador 13 - Barra P1 - PAL8) | F22: 1 Atuado | G22: Digital Simples | H22: UCCD1 | I22: Direto | J22: * | M22: =VLOOKUP(Z21,[1]ETerra_D!$A$1:$D$30000,4,0) -> #N/A
A23: 14F1 | B23: GTD14 | C23: Falha Comunicação IED 14F1 - (Alimentador 14 - Barra P1 - PAL10) | F23: 1 Atuado | G23: Digital Simples | H23: UCCD1 | I23: Direto | J23: * | M23: =VLOOKUP(Z23,[1]ETerra_D!$A$1:$D$30000,4,0) -> #N/A
A24: 15F1 | B24: GTD15 | C24: Falha Comunicação IED 15F1 - (Alimentador 15 - Barra P1 - PAL10) | F24: 1 Atuado | G24: Digital Simples | H24: UCCD1 | I24: Direto | J24: * | M24: =VLOOKUP(Z24,[1]ETerra_D!$A$1:$D$30000,4,0) -> #N/A
A25: 16F1 | B25: TRF-1 | C25: Falha Comunicação IED 16F1 - (Transferência 1 - Barra P1 - PAL10) | F25: 1 Atuado | G25: Digital Simples | H25: UCCD1 | I25: Direto | J25: * | M25: =VLOOKUP(Z22,[1]ETerra_D!$A$1:$D$30000,4,0) -> #N/A
A26: 18F1 | B26: BC1 | C26: Falha Comunicação IED 18F1 - (Banco de Capacitores 1 - Barra P1 - PAL8) | F26: 1 Atuado | G26: Digital Simples | H26: UCCD1 | I26: Direto | J26: * | M26: =VLOOKUP(Z26,[1]ETerra_D!$A$1:$D$30000,4,0) -> #N/A
A27: 19F1 | B27: BC2 | C27: Falha Comunicação IED 19F1 - (Banco de Capacitores 2 - Barra P1 - PAL10) | F27: 1 Atuado | G27: Digital Simples | H27: UCCD1 | I27: Direto | J27: * | M27: =VLOOKUP(Z27,[1]ETerra_D!$A$1:$D$30000,4,0) -> #N/A
A28: 20F1 | B28: IB_23kV | C28: Falha Comunicação IED 20F1 - (Interbarras - Barra P1/P2 - PAL12) | F28: 1 Atuado | G28: Digital Simples | H28: UCCD1 | I28: Direto | J28: * | M28: =VLOOKUP(Z28,[1]ETerra_D!$A$1:$D$30000,4,0) -> #N/A
A29: 21F1 | B29: GTD21 | C29: Falha Comunicação IED 21F1 - (Alimentador 21 - Barra P2 - PAL14) | F29: 1 Atuado | G29: Digital Simples | H29: UCCD1 | I29: Direto | J29: *
A30: 22F1 | B30: GTD22 | C30: Falha Comunicação IED 22F1 - (Alimentador 22 - Barra P2 - PAL14) | F30: 1 Atuado | G30: Digital Simples | H30: UCCD1 | I30: Direto | J30: * | M30: =VLOOKUP(Z30,[1]ETerra_D!$A$1:$D$30000,4,0) -> #N/A
A31: 23F1 | B31: GTD23 | C31: Falha Comunicação IED 23F1 - (Alimentador 23 - Barra P2 - PAL15) | F31: 1 Atuado | G31: Digital Simples | H31: UCCD1 | I31: Direto | J31: * | M31: =VLOOKUP(Z31,[1]ETerra_D!$A$1:$D$30000,4,0) -> #N/A
A32: 24F1 | B32: GTD24 | C32: Falha Comunicação IED 24F1 - (Alimentador 24 - Barra P2 - PAL15) | F32: 1 Atuado | G32: Digital Simples | H32: UCCD1 | I32: Direto | J32: * | M32: =VLOOKUP(Z32,[1]ETerra_D!$A$1:$D$30000,4,0) -> #N/A
A33: 25F1 | B33: GTD25 | C33: Falha Comunicação IED 25F1 - (Alimentador 25 - Barra P2 - PAL15) | F33: 1 Atuado | G33: Digital Simples | H33: UCCD1 | I33: Direto | J33: *
A34: 27F1 | B34: TRF-2 | C34: Falha Comunicação IED 27F1 - (Transferência 2 - Barra P2 - PAL14) | F34: 1 Atuado | G34: Digital Simples | H34: UCCD1 | I34: Direto | J34: * | M34: =VLOOKUP(Z34,[1]ETerra_D!$A$1:$D$30000,4,0) -> #N/A
A35: 28F1 | B35: BC3 | C35: Falha Comunicação IED 28F1 - (Banco de Capacitores 3 - Barra P2 - PAL14) | F35: 1 Atuado | G35: Digital Simples | H35: UCCD1 | I35: Direto | J35: * | M35: =VLOOKUP(Z35,[1]ETerra_D!$A$1:$D$30000,4,0) -> #N/A
A36: 29F1 | B36: BC4 | C36: Falha Comunicação IED 29F1 - (Banco de Capacitores 4 - Barra P2 - PAL15) | F36: 1 Atuado | G36: Digital Simples | H36: UCCD1 | I36: Direto | J36: *
A37: 35F1 | B37: 87B_MT1 | C37: Falha Comunicação IED 35F1 - (Diferencial de Barras 23kV - PPBMT1) | F37: 1 Atuado | G37: Digital Simples | H37: UCCD1 | I37: Direto | J37: * | M37: =VLOOKUP(Z37,[1]ETerra_D!$A$1:$D$30000,4,0) -> #N/A
A38: 36F1 | B38: 87B_MT2 | C38: Falha Comunicação IED 36F1 - (Diferencial de Barras 23kV - PPBMT2) | F38: 1 Atuado | G38: Digital Simples | H38: UCCD1 | I38: Direto | J38: *
A39: 40F1 | B39: PSACA | C39: Falha Interna Relé 40F1 - Painel Serviço Auxiliar - (PSACA) | F39: 1 Atuado | G39: Digital Simples | H39: UCCD1 | I39: Direto | J39: *

Sheet UCCD1
A1: #VALUE! | C1: SUBESTAÇÃO RGE GRAVATAÍ 4 (SE_GTD)
C2: Lista de Pontos Supervisionados A8000
C3: Relé: Siemens A8000 IP: 192.168.0.11 | H3: Concentradora: SICAM PAS | N3: COS
C4: Protocolo: IEC 61850 Versão:2.1 | H4: Protocolo: DNP3 IP:10.34.13.2 End:13
A5: IED | B5: Módulo | C5: Descrição do ponto | D5: Entrada BI.nária | E5: Variável | F5: Endereço Variável | G5: Variação: | H5: Tipo | I5: Origem | J5: Lógica | K5: Endereço DNP3 | L5: N2 | M5: N3 | N5: NIVEL3
A6: Comandos
A7: UCCD1 | B7: 86FD-P | C7: Comando de reset do relé de bloqueio da Barra P 69kV | E7: OUT1D0_Reset_86FDP | F7: UTRCTRL/BO0GGIO0.SPCSO0.ctlVal | G7: On: Reset | H7: Comando S | J7: Direto | K7: 1270
A8: UCCD1 | B8: 86FD-P1 | C8: Comando de reset do relé de bloqueio da Barra P1 23kV | E8: OUT1D1_Reset_86FDP1 | F8: UTRCTRL/BO0GGIO1.SPCSO0.ctlVal | G8: On: Reset | H8: Comando S | J8: Direto | K8: 1271
A9: UCCD1 | B9: 86FD-P2 | C9: Comando de reset do relé de bloqueio da Barra P2 23kV | E9: OUT1D2_Reset_86FDP2 | F9: UTRCTRL/BO0GGIO2.SPCSO0.ctlVal | G9: On: Reset | H9: Comando S | J9: Direto | K9: 1272
A10: Digitais
A11: SW1 | B11: PMT1 | C11: Falha Interna Switch 1 - Painel de medição de perdas 1 - (PMT1) | D11: IN1D0 | E11: IN1D0_PMT1_Falha_SW1 | F11: UTRCTRL/BI0GGIO0.Ind0.stVal | G11: 1 Atuado | H11: Digital Simples | I11: UCCD1 | J11: Direto | K11: 1250 | N11: =VLOOKUP(AA11,[1]ETerra_D!$A$1:$D$30000,4,0) -> #N/A
A12: SW2 | B12: PMT1 | C12: Falha Interna Switch 2 - Painel de medição de perdas 1 - (PMT1) | D12: IN1D1 | E12: IN1D0_PMT1_Falha_SW1 | F12: UTRCTRL/BI0GGIO0.Ind1.stVal | G12: 1 Atuado | H12: Digital Simples | I12: UCCD1 | J12: Direto | K12: 1251 | N12: =VLOOKUP(AA12,[1]ETerra_D!$A$1:$D$30000,4,0) -> #N/A
A13: SW1 | B13: PMT2 | C13: Falha Interna Switch 1 - Painel de medição de perdas 2 - (PMT2) | D13: IN1D2 | E13: IN1D2_PMT2_Falha_SW1 | F13: UTRCTRL/BI0GGIO0.Ind2.stVal | G13: 1 Atuado | H13: Digital Simples | I13: UCCD1 | J13: Direto | K13: 1260 | N13: =VLOOKUP(AA13,[1]ETerra_D!$A$1:$D$30000,4,0) -> #N/A
A14: SW2 | B14: PMT2 | C14: Falha Interna Switch 2 - Painel de medição de perdas 2 - (PMT2) | D14: IN1D3 | E14: IN1D3_PMT2_Falha_SW2 | F14: UTRCTRL/BI0GGIO0.Ind3.stVal | G14: 1 Atuado | H14: Digital Simples | I14: UCCD1 | J14: Direto | K14: 1261 | N14: =VLOOKUP(AA14,[1]ETerra_D!$A$1:$D$30000,4,0) -> #N/A
A15: 01F1 | B15: LT_GTA | C15: Falha Interna Relé 01F1 - (Linha GTA - PPL1) | D15: IN1D4 | E15: IN1D4_PPL1_Falha_01F1 | F15: UTRCTRL/BI0GGIO0.Ind4.stVal | G15: 1 Atuado | H15: Digital Simples | I15: UCCD1 | J15: Direto | K15: *
A16: 01F2 | B16: LT_GTA | C16: Falha Interna Relé 01F2 - (Linha GTA - PPL1) | D16: IN1D5 | E16: IN1D5_PPL1_Falha_01F2 | F16: UTRCTRL/BI0GGIO0.Ind5.stVal | G16: 1 Atuado | H16: Digital Simples | I16: UCCD1 | J16: Direto | K16: * | N16: =VLOOKUP(AA16,[1]ETerra_D!$A$1:$D$30000,4,0) -> #N/A
A17: 02F1 | B17: LT_KGC | C17: Falha Interna Relé 02F1 - (Linha KGC - PPL2) | D17: IN1D6 | E17: IN1D6_PPL2_Falha_02F1 | F17: UTRCTRL/BI0GGIO0.Ind6.stVal | G17: 1 Atuado | H17: Digital Simples | I17: UCCD1 | J17: Direto | K17: * | N17: =VLOOKUP(AA17,[1]ETerra_D!$A$1:$D$30000,4,0) -> #N/A
A18: 02F2 | B18: LT_KGC | C18: Falha Interna Relé 02F2 - (Linha KGC - PPL2) | D18: IN1D7 | E18: IN1D7_PPL2_Falha_02F2 | F18: UTRCTRL/BI0GGIO0.Ind7.stVal | G18: 1 Atuado | H18: Digital Simples | I18: UCCD1 | J18: Direto | K18: * | N18: =VLOOKUP(AA18,[1]ETerra_D!$A$1:$D$30000,4,0) -> #N/A
A19: 05F1 | B19: TRF-3 | C19: Falha Interna Relé 05F1 - (Transferência 69kV - PPT-AT) | D19: IN1D10 | E19: IN1D10_PPTAT_Falha_05F1 | F19: UTRCTRL/BI0GGIO0.Ind10.stVal | G19: 1 Atuado | H19: Digital Simples | I19: UCCD1 | J19: Direto | K19: * | N19: =VLOOKUP(AA19,[1]ETerra_D!$A$1:$D$30000,4,0) -> #N/A
A20: 05F2 | B20: TRF-3 | C20: Falha Interna Relé 05F2 - (Transferência 69kV - PPT-AT) | D20: IN1D11 | E20: IN1D11_PPTAT_Falha_05F2 | F20: UTRCTRL/BI0GGIO0.Ind11.stVal | G20: 1 Atuado | H20: Digital Simples | I20: UCCD1 | J20: Direto | K20: * | N20: =VLOOKUP(AA20,[1]ETerra_D!$A$1:$D$30000,4,0) -> #N/A
A21: 34F1 | B21: 87B_AT | C21: Falha Interna Relé 34F1 - (Diferencial de Barras 69kV - PPBAT) | D21: IN1D12 | E21: IN1D12_PPBAT_Falha_34F1 | F21: UTRCTRL/BI0GGIO0.Ind12.stVal | G21: 1 Atuado | H21: Digital Simples | I21: UCCD1 | J21: Direto | K21: * | N21: =VLOOKUP(AA21,[1]ETerra_D!$A$1:$D$30000,4,0) -> #N/A
A22: 06F1 | B22: TR1 | C22: Falha Interna Relé 06F1 - (Transformador 1 - PPT1) | D22: IN1D13 | E22: IN1D13_PPT1_Falha_06F1 | F22: UTRCTRL/BI0GGIO0.Ind13.stVal | G22: 1 Atuado | H22: Digital Simples | I22: UCCD1 | J22: Direto | K22: * | N22: =VLOOKUP(AA22,[1]ETerra_D!$A$1:$D$30000,4,0) -> #N/A
A23: 06F2 | B23: TR1 | C23: Falha Interna Relé 06F2 - (Transrfomador 1 - PPT1) | D23: IN1D14 | E23: IN1D14_PPT1_Falha_06F2 | F23: UTRCTRL/BI0GGIO0.Ind14.stVal | G23: 1 Atuado | H23: Digital Simples | I23: UCCD1 | J23: Direto | K23: * | N23: =VLOOKUP(AA23,[1]ETerra_D!$A$1:$D$30000,4,0) -> #N/A
A24: 07F1 | B24: TR2 | C24: Falha Interna Relé 07F1 - (Transrfomador 2 - PPT2) | D24: IN1D15 | E24: IN1D15_PPT2_Falha_07F1 | F24: UTRCTRL/BI0GGIO0.Ind15.stVal | G24: 1 Atuado | H24: Digital Simples | I24: UCCD1 | J24: Direto | K24: * | N24: =VLOOKUP(AA24,[1]ETerra_D!$A$1:$D$30000,4,0) -> #N/A
A25: 07F2 | B25: TR2 | C25: Falha Interna Relé 07F2 - (Transrfomador 2 - PPT2) | D25: IN1D16 | E25: IN1D16_PPT2_Falha_07F2 | F25: UTRCTRL/BI0GGIO0.Ind16.stVal | G25: 1 Atuado | H25: Digital Simples | I25: UCCD1 | J25: Direto | K25: * | N25: =VLOOKUP(AA25,[1]ETerra_D!$A$1:$D$30000,4,0) -> #N/A
A26: 35F1 | B26: 87B_MT1 | C26: Falha Interna Relé 35F1 - (Diferencial de Barras 23kV - PPBMT1) | D26: IN1D17 | E26: IN1D17_PPBMT1_Falha_35F1 | F26: UTRCTRL/BI0GGIO0.Ind17.stVal | G26: 1 Atuado | H26: Digital Simples | I26: UCCD1 | J26: Direto | K26: * | N26: =VLOOKUP(AA26,[1]ETerra_D!$A$1:$D$30000,4,0) -> #N/A
A27: 36F1 | B27: 87B_MT2 | C27: Falha Interna Relé 36F1 - (Diferencial de Barras 23kV - PPBMT2) | D27: IN2D0 | E27: IN2D0_PPBMT2_Falha_36F1 | F27: UTRCTRL/BI1GGIO1.Ind0.stVal | G27: 1 Atuado | H27: Digital Simples | I27: UCCD1 | J27: Direto | K27: *
A28: 11F1 | B28: GTD11 | C28: Falha Interna Relé 11F1 - (Alimentador 11 - Barra P1 - PAL8) | D28: IN2D2 | E28: IN2D2_PAL8_Falha_11F1 | F28: UTRCTRL/BI1GGIO1.Ind2.stVal | G28: 1 Atuado | H28: Digital Simples | I28: UCCD1 | J28: Direto | K28: * | N28: =VLOOKUP(AA28,[1]ETerra_D!$A$1:$D$30000,4,0) -> #N/A
A29: 12F1 | B29: GTD12 | C29: Falha Interna Relé 12F1 - (Alimentador 12 - Barra P1 - PAL8) | D29: IN2D3 | E29: IN2D3_PAL8_Falha_12F1 | F29: UTRCTRL/BI1GGIO1.Ind3.stVal | G29: 1 Atuado | H29: Digital Simples | I29: UCCD1 | J29: Direto | K29: * | N29: =VLOOKUP(AA33,[1]ETerra_D!$A$1:$D$30000,4,0) -> #N/A
A30: 13F1 | B30: GTD13 | C30: Falha Interna Relé 13F1 - (Alimentador 13 - Barra P1 - PAL8) | D30: IN2D4 | E30: IN2D4_PAL8_Falha_13F1 | F30: UTRCTRL/BI1GGIO1.Ind4.stVal | G30: 1 Atuado | H30: Digital Simples | I30: UCCD1 | J30: Direto | K30: * | N30: =VLOOKUP(AA29,[1]ETerra_D!$A$1:$D$30000,4,0) -> #N/A
A31: 14F1 | B31: GTD14 | C31: Falha Interna Relé 14F1 - (Alimentador 14 - Barra P1 - PAL10) | D31: IN2D6 | E31: IN2D6_PAL10_Falha_14F1 | F31: UTRCTRL/BI1GGIO1.Ind6.stVal | G31: 1 Atuado | H31: Digital Simples | I31: UCCD1 | J31: Direto | K31: * | N31: =VLOOKUP(AA31,[1]ETerra_D!$A$1:$D$30000,4,0) -> #N/A
A32: 15F1 | B32: GTD15 | C32: Falha Interna Relé 15F1 - (Alimentador 15 - Barra P1 - PAL10) | D32: IN2D7 | E32: IN2D7_PAL10_Falha_15F1 | F32: UTRCTRL/BI1GGIO1.Ind7.stVal | G32: 1 Atuado | H32: Digital Simples | I32: UCCD1 | J32: Direto | K32: * | N32: =VLOOKUP(AA32,[1]ETerra_D!$A$1:$D$30000,4,0) -> #N/A
A33: 16F1 | B33: TRF-1 | C33: Falha Interna Relé 16F1 - (Transferência 1 - Barra P1 - PAL10) | D33: IN2D5 | E33: IN2D5_PAL10_Falha_16F1 | F33: UTRCTRL/BI1GGIO1.Ind5.stVal | G33: 1 Atuado | H33: Digital Simples | I33: UCCD1 | J33: Direto | K33: * | N33: =VLOOKUP(AA30,[1]ETerra_D!$A$1:$D$30000,4,0) -> #N/A
A34: 18F1 | B34: BC1 | C34: Falha Interna Relé 18F1 - (Banco de Capacitores 1 - Barra P1 - PAL8) | D34: IN2D1 | E34: IN2D1_PAL8_Falha_18F1 | F34: UTRCTRL/BI1GGIO1.Ind1.stVal | G34: 1 Atuado | H34: Digital Simples | I34: UCCD1 | J34: Direto | K34: * | N34: =VLOOKUP(AA34,[1]ETerra_D!$A$1:$D$30000,4,0) -> #N/A
A35: 19F1 | B35: BC2 | C35: Falha Interna Relé 19F1 - (Banco de Capacitores 2 - Barra P1 - PAL10) | D35: IN2D10 | E35: IN2D10_PAL10_Falha_19F1 | F35: UTRCTRL/BI1GGIO1.Ind10.stVal | G35: 1 Atuado | H35: Digital Simples | I35: UCCD1 | J35: Direto | K35: * | N35: =VLOOKUP(AA35,[1]ETerra_D!$A$1:$D$30000,4,0) -> #N/A
A36: 20F1 | B36: IB_23kV | C36: Falha Interna Relé 20F1 - (Interbarras - Barra P1/P2 - PAL12) | D36: IN2D11 | E36: IN2D11_PAL12_Falha_20F1 | F36: UTRCTRL/BI1GGIO1.Ind11.stVal | G36: 1 Atuado | H36: Digital Simples | I36: UCCD1 | J36: Direto | K36: * | N36: =VLOOKUP(AA36,[1]ETerra_D!$A$1:$D$30000,4,0) -> #N/A
A37: 21F1 | B37: GTD21 | C37: Falha Interna Relé 21F1 - (Alimentador 21 - Barra P2 - PAL14) | D37: IN2D13 | E37: IN2D13_PAL14_Falha_21F1 | F37: UTRCTRL/BI1GGIO1.Ind13.stVal | G37: 1 Atuado | H37: Digital Simples | I37: UCCD1 | J37: Direto | K37: *
A38: 22F1 | B38: GTD22 | C38: Falha Interna Relé 22F1 - (Alimentador 22 - Barra P2 - PAL14) | D38: IN2D14 | E38: IN2D14_PAL14_Falha_22F1 | F38: UTRCTRL/BI1GGIO1.Ind14.stVal | G38: 1 Atuado | H38: Digital Simples | I38: UCCD1 | J38: Direto | K38: * | N38: =VLOOKUP(AA38,[1]ETerra_D!$A$1:$D$30000,4,0) -> #N/A
A39: 23F1 | B39: GTD23 | C39: Falha Interna Relé 23F1 - (Alimentador 23 - Barra P2 - PAL15) | D39: IN2D16 | E39: IN2D16_PAL15_Falha_23F1 | F39: UTRCTRL/BI1GGIO1.Ind16.stVal | G39: 1 Atuado | H39: Digital Simples | I39: UCCD1 | J39: Direto | K39: * | N39: =VLOOKUP(AA39,[1]ETerra_D!$A$1:$D$30000,4,0) -> #N/A
A40: 24F1 | B40: GTD24 | C40: Falha Interna Relé 24F1 - (Alimentador 24 - Barra P2 - PAL15) | D40: IN2D17 | E40: IN2D17_PAL15_Falha_24F1 | F40: UTRCTRL/BI1GGIO1.Ind17.stVal | G40: 1 Atuado | H40: Digital Simples | I40: UCCD1 | J40: Direto | K40: * | N40: =VLOOKUP(AA40,[1]ETerra_D!$A$1:$D$30000,4,0) -> #N/A
...

Sheet Consistidos
A1: #VALUE! | C1: SUBESTAÇÃO RGE GRAVATAÍ 4 (SE_GTD)
C2: Lista de Pontos Consistidos para Barras P/P1/P2
F3: Concentradora: SICAM PAS | K3: COS
C4: Protocolo: IEC 61850 Versão:2.1 | F4: Protocolo: DNP3 IP:10.34.13.2 End:13
A5: IED | B5: Módulo | C5: Descrição do ponto | D5: Variável | E5: Endereço Variável | F5: Tipo | G5: Lógica | H5: Endereço DNP3 | I5: N2 | J5: N3 | K5: NIVEL3
A6: Digitais Barra P 69kV
A7: 01F1 | B7: LT_GTA | C7: 87FD-P Atuado | D7: BI.4.10 86FDP Atuado | E7: GTA_01F1/Application/USER1/BI410 | G7: Consistido | H7: 1200 | K7: =VLOOKUP(X7,[1]ETerra_D!$A$1:$D$30000,4,0) -> #N/A
A8: 34F1 | B8: 87B-AT | C8: 86FD-P Atuado | D8: ='87B_AT'!F18 -> BI.2.2 86FDP Atuado | E8: ='87B_AT'!G18 -> Barra_87B_AT/ApplicationBusBarProt/USER1/BI202 | K8: =VLOOKUP(X8,[1]ETerra_D!$A$1:$D$30000,4,0) -> #N/A
A9: Digitais Barra P1 23kV
A10: 06F2 | B10: TR1_MT | C10: 86FD-P1 Atuado | D10: BI.6.37 86FD-P1 Atuado | E10: TR1_06F2/Application/USER1/BI637 | G10: Consistido | H10: 1201 | K10: =VLOOKUP(X10,[1]ETerra_D!$A$1:$D$30000,4,0) -> #N/A
A11: 35F1 | B11: 87B-MT1 | C11: 86FD-P1 Atuado | D11: ='87B_MT1'!F18 -> BI.2.2 86FDP1 Atuado | E11: ='87B_MT1'!G18 -> Barra_87B_MT1/ApplicationBusBarProt/USER1/BI202
A12: Digitais Barra P2 23kV
A13: 07F2 | B13: TR2-MT | C13: 86FD-P2 Atuado | D13: BI.6.37 86FD-P2 Atuado | E13: TR2_07F2/Application/USER1/BI637 | G13: Consistido | H13: 1202 | K13: =VLOOKUP(X13,[1]ETerra_D!$A$1:$D$30000,4,0) -> #N/A
A14: 26F1 | B14: 87B-MT2 | C14: 86FD-P2 Atuado | D14: ='87B_MT2'!F18 -> BI.2.2 86FDP2 Atuado | E14: ='87B_MT2'!G18 -> Barra_87B_MT2/ApplicationBusBarProt/USER1/BI202 | K14: =VLOOKUP(X14,[1]ETerra_D!$A$1:$D$30000,4,0) -> #N/A
A15: Analógicos Barra P 69kV
A16: 07F1 | B16: B69P | C16: Tensão Barra P Fases AB | D16: Vpp:AB | E16: TR2_07F1/PTS1_OperationalValues/RPRE_MMXU1/PPV/phsAB | F16: Analógico | G16: Consistido | H16: 1200 | K16: =VLOOKUP(X16,[1]ETerra_D!$A$1:$D$30000,4,0) -> #N/A
A17: 06F1 | B17: B69P | C17: Tensão Barra P Fases AB | D17: Vpp:AB | E17: TR1_06F1/PTS1_OperationalValues/RPRE_MMXU1/PPV/phsAB | F17: Analógico | K17: =VLOOKUP(X17,[1]ETerra_D!$A$1:$D$30000,4,0) -> #N/A
A18: Analógicos Barra P1 23kV
A19: 06F2 | B19: P1_23kV | C19: Tensão Barra P1 Fases AB | D19: Vpp:AB | E19: TR1_06F2/PTS2_OperationalValues/RPRE_MMXU1/PPV/phsAB | F19: Analógico | G19: Consistido | H19: 1201 | K19: =VLOOKUP(X19,[1]ETerra_D!$A$1:$D$30000,4,0) -> #N/A
A20: 16F1 | B20: B23P1 | C20: Tensão Barra P1 Fases AB | D20: Vpp:AB | E20: TRF1/VI3p1_OperationalValues/RPRE_MMXU1/PPV/phsAB | F20: Analógico | K20: =VLOOKUP(X20,[1]ETerra_D!$A$1:$D$30000,4,0) -> #N/A
A21: Analógicos Barra P2 23kV
A22: 07F2 | B22: P2_23kV | C22: Tensão Barra P2 Fases AB | D22: Vpp:AB | E22: TR2_07F2/PTS2_OperationalValues/RPRE_MMXU1/PPV/phsAB | F22: Analógico | G22: Consistido | H22: 1202 | K22: =VLOOKUP(X22,[1]ETerra_D!$A$1:$D$30000,4,0) -> #N/A
A23: 27F1 | B23: B23P2 | C23: Tensão Barra P2 Fases AB | D23: Vpp:AB | E23: TRF2/VI3p1_OperationalValues/RPRE_MMXU1/PPV/phsAB | F23: Analógico
K24: =VLOOKUP(X24,[1]ETerra_D!$A$1:$D$30000,4,0) -> #N/A
K25: =VLOOKUP(X25,[1]ETerra_D!$A$1:$D$30000,4,0) -> #N/A
K26: =VLOOKUP(X28,[1]ETerra_D!$A$1:$D$30000,4,0) -> #N/A
K27: =VLOOKUP(X26,[1]ETerra_D!$A$1:$D$30000,4,0) -> #N/A
K28: =VLOOKUP(X27,[1]ETerra_D!$A$1:$D$30000,4,0) -> #N/A
K29: =VLOOKUP(X29,[1]ETerra_D!$A$1:$D$30000,4,0) -> #N/A
K30: =VLOOKUP(X30,[1]ETerra_D!$A$1:$D$30000,4,0) -> #N/A
K31: =VLOOKUP(X31,[1]ETerra_D!$A$1:$D$30000,4,0) -> #N/A
K32: =VLOOKUP(X32,[1]ETerra_D!$A$1:$D$30000,4,0) -> #N/A
K33: =VLOOKUP(X33,[1]ETerra_D!$A$1:$D$30000,4,0) -> #N/A
K35: =VLOOKUP(X35,[1]ETerra_D!$A$1:$D$30000,4,0) -> #N/A
K36: =VLOOKUP(X36,[1]ETerra_D!$A$1:$D$30000,4,0) -> #N/A
K37: =VLOOKUP(X37,[1]ETerra_D!$A$1:$D$30000,4,0) -> #N/A
K38: =VLOOKUP(X38,[1]ETerra_D!$A$1:$D$30000,4,0) -> #N/A
K41: =VLOOKUP(X41,[1]ETerra_D!$A$1:$D$30000,4,0) -> #N/A
K42: =VLOOKUP(X42,[1]ETerra_D!$A$1:$D$30000,4,0) -> #N/A
K43: =VLOOKUP(X43,[1]ETerra_D!$A$1:$D$30000,4,0) -> #N/A
...

Sheet 01F1_GTA_P
A1: #VALUE! | C1: SUBESTAÇÃO RGE GRAVATAÍ 4 (SE_GTD) | K1: Consistido: Consistir IED Principal e Alternado (DNP em Vermelho) Direto: Aquisição direta do IED CMD. Direto: Comando Direct (Enviar para Principal e Alternado
C2: Lista de Pontos Supervisionados LT_GTA Unidade Principal
C3: Relé: Siemens 7SA86 Shorcode: P1A639088 | G3: =Capa!G61 -> IP:10.39.13.9 | I3: Concentradora: SICAM PAS | O3: COS
C4: Protocolo: IEC 61850 Versão:2.1 FW: V9.8 FW Comm: V9.8 | I4: Protocolo: DNP3 IP:10.34.13.2 End:13
A5: IED | B5: Módulo | C5: Descrição do ponto | D5: Entrada BI.nária | E5: Saída BI.nária | F5: Variável | G5: Endereço Variável | H5: Variação: | I5: Tipo | J5: Origem | K5: Lógica | L5: Endereço DNP3 | M5: N2 | N5: N3 | O5: NIVEL3
A6: Analógicas
A7: 01F1 | B7: LT_GTA | C7: Corrente Fase A | D7: 1IA | F7: Iph:A | G7: GTA_01F1/CB1_Fundamental/FPRE_MMXU1/A/phsA | I7: Analógico | J7: 1F1/1F2 | K7: Consistido | L7: 0 | O7: =VLOOKUP(AB7,[1]ETerra_A!$A$1:$D$30000,3,0) -> #N/A
A8: 01F1 | B8: LT_GTA | C8: Corrente Fase B | D8: 1IB | F8: Iph:B | G8: GTA_01F1/CB1_Fundamental/FPRE_MMXU1/A/phsB | I8: Analógico | J8: 1F1/1F2 | K8: Consistido | L8: 1 | O8: =VLOOKUP(AB8,[1]ETerra_A!$A$1:$D$30000,3,0) -> #N/A
A9: 01F1 | B9: LT_GTA | C9: Corrente Fase C | D9: 1IC | F9: Iph:C | G9: GTA_01F1/CB1_Fundamental/FPRE_MMXU1/A/phsC | I9: Analógico | J9: 1F1/1F2 | K9: Consistido | L9: 2 | O9: =VLOOKUP(AB9,[1]ETerra_A!$A$1:$D$30000,3,0) -> #N/A
A10: 01F1 | B10: B69P | C10: Tensão Barra Fases AB | D10: 1V1 | F10: Vpp:AB | G10: GTA_01F1/CB1_Fundamental/FPRE_MMXU1/PPV/phsAB | I10: Analógico | J10: 1F1/1F2 | K10: Consistido | L10: 3 | O10: =VLOOKUP(AB10,[1]ETerra_A!$A$1:$D$30000,3,0) -> #N/A
A11: 01F1 | B11: B69P | C11: Tensão Barra Fases BC | D11: 1V2 | F11: Vpp:BC | G11: GTA_01F1/CB1_Fundamental/FPRE_MMXU1/PPV/phsBC | I11: Analógico | J11: 1F1/1F2 | K11: Consistido | L11: 4 | O11: =VLOOKUP(AB11,[1]ETerra_A!$A$1:$D$30000,3,0) -> #N/A
A12: 01F1 | B12: B69P | C12: Tensão Barra Fases CA | D12: 1V3 | F12: Vpp:CA | G12: GTA_01F1/CB1_Fundamental/FPRE_MMXU1/PPV/phsCA | I12: Analógico | J12: 1F1/1F2 | K12: Consistido | L12: 5 | O12: =VLOOKUP(AB12,[1]ETerra_A!$A$1:$D$30000,3,0) -> #N/A
A13: 01F1 | B13: LT_GTA | C13: Tensão Linha (Fase B) | D13: 1V4 | F13: V2 | G13: GTA_01F1/CB1_25Synchronization/GENRSYN1/V2Clc | I13: Analógico | J13: 1F1/1F2 | K13: Consistido | L13: 6 | O13: =VLOOKUP(AB13,[1]ETerra_A!$A$1:$D$30000,3,0) -> #N/A
A14: 01F1 | B14: LT_GTA | C14: Potência Ativa | F14: P tot | G14: GTA_01F1/Ln1_OperationalValues/PPRE_MMXU1/TotW | I14: Analógico | J14: 1F1/1F2 | K14: Consistido | L14: 7 | O14: =VLOOKUP(AB14,[1]ETerra_A!$A$1:$D$30000,3,0) -> #N/A
A15: 01F1 | B15: LT_GTA | C15: Potência Reativa | F15: Q tot | G15: GTA_01F1/Ln1_OperationalValues/PPRE_MMXU1/TotVAr | I15: Analógico | J15: 1F1/1F2 | K15: Consistido | L15: 8 | O15: =VLOOKUP(AB15,[1]ETerra_A!$A$1:$D$30000,3,0) -> #N/A
A16: 01F1 | B16: LT_GTA | C16: Distancia da Última Falta | F16: VD.091 Distância da Falta | G16: GTA_01F1/Application/USER3/VA001 | I16: Analógico | J16: 1F1 | K16: Direto | L16: 9 | O16: =VLOOKUP(AB16,[1]ETerra_A!$A$1:$D$30000,3,0) -> #N/A
A17: Comandos
A18: 01F1 | B18: LT_GTA | C18: Disj. 52-1 (01Q0) - Desligar / Ligar | E18: 1.3/1.1 | F18: Comando DJ/Pos | G18: GTA_01F1/CB1/CSWI1/Pos | H18: ON: Ligar / OFF: Desligar | I18: Comando D | J18: 1F1/1F2 | K18: CMD Direto | L18: 0 | O18: =VLOOKUP(AB18,[1]ETerra_C!$A$1:$D$30000,2,0) -> #N/A
A19: 01F1 | B19: LT_GTA | C19: Secc. 89-2 (01Q1 Barra) - Abrir / Fechar | E19: 3.2/3.3 | F19: Comando 89 Barra | G19: GTA_01F1/Dc1/CSWI1/Pos | H19: ON: Fechar / OFF: Abrir | I19: Comando D | J19: 1F1/1F2 | K19: CMD Direto | L19: 1 | O19: =VLOOKUP(AB19,[1]ETerra_C!$A$1:$D$30000,2,0) -> #N/A
A20: 01F1 | B20: LT_GTA | C20: Secc. 89-4 (01Q2 Linha) - Abrir / Fechar | E20: 4.2/4.3 | F20: Comando 89 Linha | G20: GTA_01F1/Dc2/CSWI1/Pos | H20: ON: Fechar / OFF: Abrir | I20: Comando D | J20: 1F1/1F2 | K20: CMD Direto | L20: 2 | O20: =VLOOKUP(AB20,[1]ETerra_C!$A$1:$D$30000,2,0) -> #N/A
A21: 01F1 | B21: LT_GTA | C21: Secc. 89-6 (01Q3 Contorno) - Abrir / Fechar | E21: 3.5/3.6 | F21: Comando 89 Contorno | G21: GTA_01F1/Dc3/CSWI1/Pos | H21: ON: Fechar / OFF: Abrir | I21: Comando D | J21: 1F1/1F2 | K21: CMD Direto | L21: 3 | O21: =VLOOKUP(AB21,[1]ETerra_C!$A$1:$D$30000,2,0) -> #N/A
A22: 01F1 | B22: LT_GTA | C22: Religamento Automático (79) - Excluir / Incluir | F22: CMD RMT.01 79 Excluír/Incluír | G22: GTA_01F1/Application/USER7/CMD001 | H22: ON: Incluí / OFF: Excluí | I22: Comando D | J22: 1F1/1F2 | K22: CMD Direto | L22: 4 | O22: =VLOOKUP(AB22,[1]ETerra_C!$A$1:$D$30000,2,0) -> #N/A
A23: 01F1 | B23: LT_GTA | C23: Grupo de Ajustes 2 - Excluir / Incluir | F23: CMD RMT.02 Troca de Grupo | G23: GTA_01F1/Application/USER7/CMD002 | H23: ON: Incluí / OFF: Excluí | I23: Comando D | J23: 1F1/1F2 | K23: CMD Direto | L23: 5 | O23: =VLOOKUP(AB23,[1]ETerra_C!$A$1:$D$30000,2,0) -> #N/A
A24: 01F1 | B24: LT_GTA | C24: Check de Sincronismo (25) - Bloquear / Desbloquear | F24: CMD RMT.03 25 Bloqueio/Desbloqueio | G24: GTA_01F1/Application/USER7/CMD003 | H24: ON: Incluí / OFF: Excluí | I24: Comando D | J24: 1F1/1F2 | K24: CMD Direto | L24: 6
A25: 01F1 | B25: LT_GTA | C25: Reserva para Aplicação Futura RGE | F25: CMD RMT.004 Reserva | G25: GTA_01F1/Application/USER7/CMD004 | H25: ON: Incluí / OFF: Excluí | I25: Comando D | J25: 1F1/1F2 | K25: CMD Direto | L25: 7
A26: 01F1 | B26: LT_GTA | C26: Reserva para Aplicação Futura RGE | F26: CMD RMT.005 Reserva | G26: GTA_01F1/Application/USER7/CMD005 | H26: ON: Incluí / OFF: Excluí | I26: Comando D | J26: 1F1/1F2 | K26: CMD Direto | L26: 8
A27: Digitais (Controle)
A28: Disjuntor 52-1 (01Q0)
A29: 01F1 | B29: LT_GTA | C29: Disj. 52-1 (01Q0) - Desligado | D29: 3.1 | F29: VD.001 DJ 52 Desligado Consistido | G29: GTA_01F1/Application/USER3/VD001 | H29: 1 Desligado | I29: Digital Simples | J29: 1F1/1F2 | K29: Consistido | L29: 1 | O29: =VLOOKUP(AB29,[1]ETerra_D!$A$1:$D$30000,4,0) -> #N/A
A30: 01F1 | B30: LT_GTA | C30: Disj. 52-1 (01Q0) - Ligado | D30: 3.2 | F30: VD.002 DJ 52 Ligado Consistido | G30: GTA_01F1/Application/USER3/VD002 | H30: 1 Ligado | I30: Digital Simples | J30: 1F1/1F2 | K30: Consistido | L30: 2 | O30: =VLOOKUP(AB30,[1]ETerra_D!$A$1:$D$30000,4,0) -> #N/A
A31: 01F1 | B31: LT_GTA | C31: Disj. 52-1 (01Q0) - Indefinido | F31: VD.003 DJ 52 Indefinido | G31: GTA_01F1/Application/USER3/VD003 | H31: 1 Alarme | I31: Digital Simples | J31: 1F1/1F2 | K31: Consistido | L31: - | M31: N2
A32: 01F1 | B32: LT_GTA | C32: Disj. 52-1 (01Q0) - Baixa Pressão SF6 - Alarme | D32: 3.3 | F32: BI.3.3 DJ 52 SF6 1º Estagio | G32: GTA_01F1/Application/USER1/BI303 | H32: 1 Alarme | I32: Digital Simples | J32: 1F1/1F2 | K32: Consistido | L32: 3 | O32: =VLOOKUP(AB32,[1]ETerra_D!$A$1:$D$30000,4,0) -> #N/A
A33: 01F1 | B33: LT_GTA | C33: Disj. 52-1 (01Q0) - Baixa Pressão SF6 - Bloqueio | D33: 3.4 | F33: BI.3.4 DJ 52 SF6 2º Estagio | G33: GTA_01F1/Application/USER1/BI304 | H33: 1 Alarme | I33: Digital Simples | J33: 1F1/1F2 | K33: Consistido | L33: 4 | O33: =VLOOKUP(AB33,[1]ETerra_D!$A$1:$D$30000,4,0) -> #N/A
A34: 01F1 | B34: LT_GTA | C34: Disj. 52-1 (01Q0) - Mola Descarregada ou FVCC CMD. Bob. Ab. 1 ou 2 | D34: 3.5 | F34: VD.036 52 Mola Descarregada Temporizada | G34: GTA_01F1/Application/USER3/VD036 | H34: 1 Alarme | I34: Digital Simples | J34: 1F1/1F2 | K34: Consistido | L34: 5 | O34: =VLOOKUP(AB34,[1]ETerra_D!$A$1:$D$30000,4,0) -> #N/A
A35: 01F1 | B35: LT_GTA | C35: Disj. 52-1 (01Q0) - Chave 43LR Pos. Remoto | D35: 3.6 | F35: BI.3.6 DJ 52 43LR Remoto | G35: GTA_01F1/Application/USER1/BI306 | H35: 1 Normal | I35: Digital Simples | J35: 1F1/1F2 | K35: Consistido | L35: 6 | O35: =VLOOKUP(AB35,[1]ETerra_D!$A$1:$D$30000,4,0) -> #N/A
A36: 01F1 | B36: LT_GTA | C36: Disj. 52-1 (01Q0) – Supervisão Bobina de Ligar | D36: 4.1 | F36: VD.035 52 Falha Bob. Ligar | G36: GTA_01F1/Application/USER3/VD035 | H36: 1 Alarme | I36: Digital Simples | J36: 1F1/1F2 | K36: Consistido | L36: 7 | O36: =VLOOKUP(AB36,[1]ETerra_D!$A$1:$D$30000,4,0) -> #N/A
A37: 01F1 | B37: LT_GTA | C37: Disj. 52-1 (01Q0) - Supervisão Bobina Desligar 1 | D37: 4.2 | F37: VD.033 52 Falha Bob. Aber. 1 | G37: GTA_01F1/Application/USER3/VD033 | H37: 1 Alarme | I37: Digital Simples | J37: 1F1/1F2 | K37: Consistido | L37: 8
A38: 01F1 | B38: LT_GTA | C38: Disj. 52-1 (01Q0) - Supervisão Bobina Desligar 2 | D38: 4.3 | F38: VD.034 52 Falha Bob. Abert. 2 | G38: GTA_01F1/Application/USER3/VD034 | H38: 1 Alarme | I38: Digital Simples | J38: 1F1/1F2 | K38: Consistido | L38: 9 | O38: =VLOOKUP(AB38,[1]ETerra_D!$A$1:$D$30000,4,0) -> #N/A
A39: 01F1 | B39: LT_GTA | C39: Disj. 52-1 (01Q0) - Intertravamento | E39: 1.2 | F39: VD.088 DJ 52 Intertravamento | G39: GTA_01F1/Application/USER3/VD088 | H39: 1 Libera | I39: Digital Simples | J39: 1F1/1F2 | K39: Consistido | L39: 10 | M39: N2
A40: 01F1 | B40: LT_GTA | C40: Disj. 52-1 (01Q0) - Falha Comando de Desligar | F40: VD.032 52 Falha Comando de Desligar | G40: GTA_01F1/Application/USER3/VD032 | H40: 1 Falha | I40: Digital Simples | J40: 1F1/1F2 | K40: Consistido | L40: 11 | M40: N2
...

Sheet 01F1_GTA_A
A1: #VALUE! | C1: SUBESTAÇÃO RGE GRAVATAÍ 4 (SE_GTD) | K1: Consistido: Consistir IED Principal e Alternado (DNP em Vermelho) Direto: Aquisição direta do IED CMD. Direto: Comando Direct (Enviar para Principal e Alternado
C2: Lista de Pontos Supervisionados LT_GTA Unidade Alternada
C3: Relé: Siemens 7SA86 Shorcode: P1A639088 | G3: =Capa!G62 -> IP:10.39.13.10 | I3: Concentradora: SICAM PAS | O3: COS
C4: Protocolo: IEC 61850 Versão:2.1 FW: V9.8 FW Comm: V9.8 | I4: Protocolo: DNP3 IP:10.34.13.2 End:13
A5: IED | B5: Módulo | C5: Descrição do ponto | D5: Entrada Binária | E5: Saída Binária | F5: Variável | G5: Endereço Variável | H5: Variação: | I5: Tipo | J5: Origem | K5: Lógica | L5: Endereço DNP3 | M5: N2 | N5: N3 | O5: NIVEL3
A6: Analógicas
A7: 01F2 | B7: LT_GTA | C7: Corrente Fase A | D7: 1IA | F7: Iph:A | G7: GTA_01F2/CB1_Fundamental/FPRE_MMXU1/A/phsA | I7: Analógico | J7: 1F1/1F2 | K7: Consistido | L7: * | O7: =VLOOKUP(AB7,[1]ETerra_A!$A$1:$D$30000,3,0) -> #N/A
A8: 01F2 | B8: LT_GTA | C8: Corrente Fase B | D8: 1IB | F8: Iph:B | G8: GTA_01F2/CB1_Fundamental/FPRE_MMXU1/A/phsB | I8: Analógico | J8: 1F1/1F2 | K8: Consistido | L8: * | O8: =VLOOKUP(AB8,[1]ETerra_A!$A$1:$D$30000,3,0) -> #N/A
A9: 01F2 | B9: LT_GTA | C9: Corrente Fase C | D9: 1IC | F9: Iph:C | G9: GTA_01F2/CB1_Fundamental/FPRE_MMXU1/A/phsC | I9: Analógico | J9: 1F1/1F2 | K9: Consistido | L9: * | O9: =VLOOKUP(AB9,[1]ETerra_A!$A$1:$D$30000,3,0) -> #N/A
A10: 01F2 | B10: B69P | C10: Tensão Barra Fases AB | D10: 1V1 | F10: Vpp:AB | G10: GTA_01F2/CB1_Fundamental/FPRE_MMXU1/PPV/phsAB | I10: Analógico | J10: 1F1/1F2 | K10: Consistido | L10: * | O10: =VLOOKUP(AB10,[1]ETerra_A!$A$1:$D$30000,3,0) -> #N/A
A11: 01F2 | B11: B69P | C11: Tensão Barra Fases BC | D11: 1V2 | F11: Vpp:BC | G11: GTA_01F2/CB1_Fundamental/FPRE_MMXU1/PPV/phsBC | I11: Analógico | J11: 1F1/1F2 | K11: Consistido | L11: * | O11: =VLOOKUP(AB11,[1]ETerra_A!$A$1:$D$30000,3,0) -> #N/A
A12: 01F2 | B12: B69P | C12: Tensão Barra Fases CA | D12: 1V3 | F12: Vpp:CA | G12: GTA_01F2/CB1_Fundamental/FPRE_MMXU1/PPV/phsCA | I12: Analógico | J12: 1F1/1F2 | K12: Consistido | L12: * | O12: =VLOOKUP(AB12,[1]ETerra_A!$A$1:$D$30000,3,0) -> #N/A
A13: 01F2 | B13: LT_GTA | C13: Tensão Linha (Fase B) | D13: 1V4 | F13: V2 | G13: GTA_01F2/CB1_25Synchronization/GENRSYN1/V2Clc | I13: Analógico | J13: 1F1/1F2 | K13: Consistido | L13: * | O13: =VLOOKUP(AB13,[1]ETerra_A!$A$1:$D$30000,3,0) -> #N/A
A14: 01F2 | B14: LT_GTA | C14: Potência Ativa | F14: P tot | G14: GTA_01F2/Ln1_OperationalValues/PPRE_MMXU1/TotW | I14: Analógico | J14: 1F1/1F2 | K14: Consistido | L14: * | O14: =VLOOKUP(AB14,[1]ETerra_A!$A$1:$D$30000,3,0) -> #N/A
A15: 01F2 | B15: LT_GTA | C15: Potência Reativa | F15: Q tot | G15: GTA_01F2/Ln1_OperationalValues/PPRE_MMXU1/TotVAr | I15: Analógico | J15: 1F1/1F2 | K15: Consistido | L15: * | O15: =VLOOKUP(AB15,[1]ETerra_A!$A$1:$D$30000,3,0) -> #N/A
A16: 01F2 | B16: LT_GTA | C16: Distancia da Última Falta | F16: VD..091 Distância da Falta | G16: GTA_01F2/Application/USER3/VA001 | I16: Analógico | J16: 1F2 | K16: Direto | L16: 10 | O16: =VLOOKUP(AB16,[1]ETerra_A!$A$1:$D$30000,3,0) -> #N/A
A17: Comandos
A18: 01F2 | B18: LT_GTA | C18: Disj. 52-1 (01Q0) - Desligar / Ligar | E18: 1.3/1.1 | F18: Comando DJ/Pos | G18: GTA_01F2/CB1/CSWI1/Pos | H18: ON: Ligar / OFF: Desligar | I18: Comando D | J18: 1F1/1F2 | K18: CMD Direto | L18: * | O18: =VLOOKUP(AB18,[1]ETerra_C!$A$1:$D$30000,2,0) -> #N/A
A19: 01F2 | B19: LT_GTA | C19: Secc. 89-2 (01Q1 Barra) - Abrir / Fechar | E19: 3.2/3.3 | F19: Comando 89 Barra | G19: GTA_01F2/Dc1/CSWI1/Pos | H19: ON: Fechar / OFF: Abrir | I19: Comando D | J19: 1F1/1F2 | K19: CMD Direto | L19: * | O19: =VLOOKUP(AB19,[1]ETerra_C!$A$1:$D$30000,2,0) -> #N/A
A20: 01F2 | B20: LT_GTA | C20: Secc. 89-4 (01Q2 Linha) - Abrir / Fechar | E20: 4.2/4.3 | F20: Comando 89 Linha | G20: GTA_01F2/Dc2/CSWI1/Pos | H20: ON: Fechar / OFF: Abrir | I20: Comando D | J20: 1F1/1F2 | K20: CMD Direto | L20: * | O20: =VLOOKUP(AB20,[1]ETerra_C!$A$1:$D$30000,2,0) -> #N/A
A21: 01F2 | B21: LT_GTA | C21: Secc. 89-6 (01Q3 Contorno) - Abrir / Fechar | E21: 3.5/3.6 | F21: Comando 89 Contorno | G21: GTA_01F2/Dc3/CSWI1/Pos | H21: ON: Fechar / OFF: Abrir | I21: Comando D | J21: 1F1/1F2 | K21: CMD Direto | L21: * | O21: =VLOOKUP(AB21,[1]ETerra_C!$A$1:$D$30000,2,0) -> #N/A
A22: 01F2 | B22: LT_GTA | C22: Religamento Automático (79) - Excluir / Incluir | F22: CMD RMT.01 79 Excluír/Incluír | G22: GTA_01F2/Application/USER7/CMD001 | H22: ON: Incluí / OFF: Excluí | I22: Comando D | J22: 1F1/1F2 | K22: CMD Direto | L22: * | O22: =VLOOKUP(AB22,[1]ETerra_C!$A$1:$D$30000,2,0) -> #N/A
A23: 01F2 | B23: LT_GTA | C23: Grupo de Ajustes 2 - Excluir / Incluir | F23: CMD RMT.02 Troca de Grupo | G23: GTA_01F2/Application/USER7/CMD002 | H23: ON: Incluí / OFF: Excluí | I23: Comando D | J23: 1F1/1F2 | K23: CMD Direto | L23: * | O23: =VLOOKUP(AB23,[1]ETerra_C!$A$1:$D$30000,2,0) -> #N/A
A24: 01F2 | B24: LT_GTA | C24: Check de Sincronismo (25) - Bloquear / Desbloquear | F24: CMD RMT.03 25 Bloqueio/Desbloqueio | G24: GTA_01F2/Application/USER7/CMD003 | H24: ON: Incluí / OFF: Excluí | I24: Comando D | J24: 1F1/1F2 | K24: CMD Direto | L24: *
A25: 01F2 | B25: LT_GTA | C25: Reserva para Aplicação Futura RGE | F25: CMD RMT.004 Reserva | G25: GTA_01F2/Application/USER7/CMD004 | H25: ON: Incluí / OFF: Excluí | I25: Comando D | J25: 1F1/1F2 | K25: CMD Direto | L25: *
A26: 01F2 | B26: LT_GTA | C26: Reserva para Aplicação Futura RGE | F26: CMD RMT.005 Reserva | G26: GTA_01F2/Application/USER7/CMD005 | H26: ON: Incluí / OFF: Excluí | I26: Comando D | J26: 1F1/1F2 | K26: CMD Direto | L26: *
A27: Digitais (Controle)
A28: Disjuntor 52-1 (01Q0)
A29: 01F2 | B29: LT_GTA | C29: Disj. 52-1 (01Q0) - Desligado | D29: 3.1 | F29: VD.001 DJ 52 Desligado Consistido | G29: GTA_01F2/Application/USER3/VD001 | H29: 1 Desligado | I29: Digital Simples | J29: 1F1/1F2 | K29: Consistido | L29: * | O29: =VLOOKUP(AB29,[1]ETerra_D!$A$1:$D$30000,4,0) -> #N/A
A30: 01F2 | B30: LT_GTA | C30: Disj. 52-1 (01Q0) - Ligado | D30: 3.2 | F30: VD.002 DJ 52 Ligado Consistido | G30: GTA_01F2/Application/USER3/VD002 | H30: 1 Ligado | I30: Digital Simples | J30: 1F1/1F2 | K30: Consistido | L30: * | O30: =VLOOKUP(AB30,[1]ETerra_D!$A$1:$D$30000,4,0) -> #N/A
A31: 01F2 | B31: LT_GTA | C31: Disj. 52-1 (01Q0) - Indefinido | F31: VD.003 DJ 52 Indefinido | G31: GTA_01F2/Application/USER3/VD003 | H31: 1 Alarme | I31: Digital Simples | J31: 1F1/1F2 | K31: Consistido | L31: * | M31: N2
A32: 01F2 | B32: LT_GTA | C32: Disj. 52-1 (01Q0) - Baixa Pressão SF6 - Alarme | D32: 3.3 | F32: BI.3.3 DJ 52 SF6 1º Estagio | G32: GTA_01F2/Application/USER1/BI303 | H32: 1 Alarme | I32: Digital Simples | J32: 1F1/1F2 | K32: Consistido | L32: * | O32: =VLOOKUP(AB32,[1]ETerra_D!$A$1:$D$30000,4,0) -> #N/A
A33: 01F2 | B33: LT_GTA | C33: Disj. 52-1 (01Q0) - Baixa Pressão SF6 - Bloqueio | D33: 3.4 | F33: BI.3.4 DJ 52 SF6 2º Estagio | G33: GTA_01F2/Application/USER1/BI304 | H33: 1 Alarme | I33: Digital Simples | J33: 1F1/1F2 | K33: Consistido | L33: * | O33: =VLOOKUP(AB33,[1]ETerra_D!$A$1:$D$30000,4,0) -> #N/A
A34: 01F2 | B34: LT_GTA | C34: Disj. 52-1 (01Q0) - Mola Descarregada ou FVCC CMD. Bob. Ab. 1 ou 2 | D34: 3.5 | F34: VD.036 52 Mola Descarregada Temporizada | G34: GTA_01F2/Application/USER3/VD036 | H34: 1 Alarme | I34: Digital Simples | J34: 1F1/1F2 | K34: Consistido | L34: * | O34: =VLOOKUP(AB34,[1]ETerra_D!$A$1:$D$30000,4,0) -> #N/A
A35: 01F2 | B35: LT_GTA | C35: Disj. 52-1 (01Q0) - Chave 43LR Pos. Remoto | D35: 3.6 | F35: BI.3.6 DJ 52 43LR Remoto | G35: GTA_01F2/Application/USER1/BI306 | H35: 1 Normal | I35: Digital Simples | J35: 1F1/1F2 | K35: Consistido | L35: * | O35: =VLOOKUP(AB35,[1]ETerra_D!$A$1:$D$30000,4,0) -> #N/A
A36: 01F2 | B36: LT_GTA | C36: Disj. 52-1 (01Q0) – Supervisão Bobina de Ligar | D36: 4.1 | F36: VD.035 52 Falha Bob. Ligar | G36: GTA_01F2/Application/USER3/VD035 | H36: 1 Alarme | I36: Digital Simples | J36: 1F1/1F2 | K36: Consistido | L36: * | O36: =VLOOKUP(AB36,[1]ETerra_D!$A$1:$D$30000,4,0) -> #N/A
A37: 01F2 | B37: LT_GTA | C37: Disj. 52-1 (01Q0) - Supervisão Bobina Desligar 1 | D37: 4.2 | F37: VD.033 52 Falha Bob. Aber. 1 | G37: GTA_01F2/Application/USER3/VD033 | H37: 1 Alarme | I37: Digital Simples | J37: 1F1/1F2 | K37: Consistido | L37: *
A38: 01F2 | B38: LT_GTA | C38: Disj. 52-1 (01Q0) - Supervisão Bobina Desligar 2 | D38: 4.3 | F38: VD.034 52 Falha Bob. Abert. 2 | G38: GTA_01F2/Application/USER3/VD034 | H38: 1 Alarme | I38: Digital Simples | J38: 1F1/1F2 | K38: Consistido | L38: * | O38: =VLOOKUP(AB38,[1]ETerra_D!$A$1:$D$30000,4,0) -> #N/A
A39: 01F2 | B39: LT_GTA | C39: Disj. 52-1 (01Q0) - Intertravamento | E39: 1.2 | F39: VD.088 DJ 52 Intertravamento | G39: GTA_01F2/Application/USER3/VD088 | H39: 1 Libera | I39: Digital Simples | J39: 1F1/1F2 | K39: Consistido | L39: * | M39: N2
A40: 01F2 | B40: LT_GTA | C40: Disj. 52-1 (01Q0) - Falha Comando de Desligar | F40: VD.032 52 Falha Comando de Desligar | G40: GTA_01F2/Application/USER3/VD032 | H40: 1 Falha | I40: Digital Simples | J40: 1F1/1F2 | K40: Consistido | L40: * | M40: N2
...

Sheet 01F1_KGC_P
A1: #VALUE! | C1: SUBESTAÇÃO RGE GRAVATAÍ 4 (SE_GTD) | K1: Consistido: Consistir IED Principal e Alternado (DNP em Vermelho) Direto: Aquisição direta do IED Cmd Direto: Comando Direct (Enviar para Principal e Alternado
C2: Lista de Pontos Supervisionados LT_KGC Unidade Principal
C3: Relé: Siemens 7SA86 Shorcode: P1A639088 | G3: =Capa!G63 -> IP:10.39.13.11 | I3: Concentradora: SICAM PAS
C4: Protocolo: IEC 61850 Versão:2.1 FW: V9.8 FW Comm: V9.8 | I4: Protocolo: DNP3 IP:10.34.13.2 End:13
A5: IED | B5: Módulo | C5: Descrição do ponto | D5: Entrada Binária | E5: Saída Binária | F5: Variável | G5: Endereço Variável | H5: Variação: | I5: Tipo | J5: Origem | K5: Lógica | L5: Endereço DNP3 | M5: N2 | N5: N3
A6: Analógicas
A7: 02F1 | B7: LT_KGC | C7: Corrente Fase A | D7: 1IA | F7: Iph:A | G7: KGC_02F1/CB1_Fundamental/FPRE_MMXU1/A/phsA | I7: Analógico | J7: 2F1/2F2 | K7: Consistido | L7: 200
A8: 02F1 | B8: LT_KGC | C8: Corrente Fase B | D8: 1IB | F8: Iph:B | G8: KGC_02F1/CB1_Fundamental/FPRE_MMXU1/A/phsB | I8: Analógico | J8: 2F1/2F2 | K8: Consistido | L8: 201
A9: 02F1 | B9: LT_KGC | C9: Corrente Fase C | D9: 1IC | F9: Iph:C | G9: KGC_02F1/CB1_Fundamental/FPRE_MMXU1/A/phsC | I9: Analógico | J9: 2F1/2F2 | K9: Consistido | L9: 202
A10: 02F1 | B10: B69P | C10: Tensão Barra Fases AB | D10: 1V1 | F10: Vpp:AB | G10: KGC_02F1/CB1_Fundamental/FPRE_MMXU1/PPV/phsAB | I10: Analógico | J10: 2F1/2F2 | K10: Consistido | L10: 203
A11: 02F1 | B11: B69P | C11: Tensão Barra Fases BC | D11: 1V2 | F11: Vpp:BC | G11: KGC_02F1/CB1_Fundamental/FPRE_MMXU1/PPV/phsBC | I11: Analógico | J11: 2F1/2F2 | K11: Consistido | L11: 204
A12: 02F1 | B12: B69P | C12: Tensão Barra Fases CA | D12: 1V3 | F12: Vpp:CA | G12: KGC_02F1/CB1_Fundamental/FPRE_MMXU1/PPV/phsCA | I12: Analógico | J12: 2F1/2F2 | K12: Consistido | L12: 205
A13: 02F1 | B13: LT_KGC | C13: Tensão Linha (Fase B) | D13: 1V4 | F13: V2 | G13: KGC_02F1/CB1_25Synchronization/GENRSYN1/V2Clc | I13: Analógico | J13: 2F1/2F2 | K13: Consistido | L13: 206
A14: 02F1 | B14: LT_KGC | C14: Potência Ativa | F14: P tot | G14: KGC_02F1/Ln1_OperationalValues/PPRE_MMXU1/TotW | I14: Analógico | J14: 2F1/2F2 | K14: Consistido | L14: 207
A15: 02F1 | B15: LT_KGC | C15: Potência Reativa | F15: Q tot | G15: KGC_02F1/Ln1_OperationalValues/PPRE_MMXU1/TotVAr | I15: Analógico | J15: 2F1/2F2 | K15: Consistido | L15: 208
A16: 02F1 | B16: LT_KGC | C16: Distancia da Última Falta | F16: VD..091 Distância da Falta | G16: KGC_02F1/Application/USER3/VA001 | I16: Analógico | J16: 2F1 | K16: Direto | L16: 209
A17: Comandos
A18: 02F1 | B18: LT_KGC | C18: Disj. 52-3 (02Q0) - Desligar / Ligar | E18: 1.3/1.1 | F18: Comando DJ/Pos | G18: KGC_02F1/CB1/CSWI1/Pos | H18: ON: Ligar / OFF: Desligar | I18: Comando D | J18: 2F1/2F2 | K18: Cmd Direto | L18: 200
A19: 02F1 | B19: LT_KGC | C19: Secc. 89-14 (02Q1 Barra) - Abrir / Fechar | E19: 3.2/3.3 | F19: Comando 89 Barra | G19: KGC_02F1/Dc1/CSWI1/Pos | H19: ON: Fechar / OFF: Abrir | I19: Comando D | J19: 2F1/2F2 | K19: Cmd Direto | L19: 201
A20: 02F1 | B20: LT_KGC | C20: Secc. 89-16 (02Q2 Linha) - Abrir / Fechar | E20: 4.2/4.3 | F20: Comando 89 Linha | G20: KGC_02F1/Dc2/CSWI1/Pos | H20: ON: Fechar / OFF: Abrir | I20: Comando D | J20: 2F1/2F2 | K20: Cmd Direto | L20: 202
A21: 02F1 | B21: LT_KGC | C21: Secc. 89-18 (02Q3 Contorno) - Abrir / Fechar | E21: 3.5/3.6 | F21: Comando 89 Contorno | G21: KGC_02F1/Dc3/CSWI1/Pos | H21: ON: Fechar / OFF: Abrir | I21: Comando D | J21: 2F1/2F2 | K21: Cmd Direto | L21: 203
A22: 02F1 | B22: LT_KGC | C22: Religamento Automático (79) - Excluir / Incluir | F22: CMD RMT.01 79 Excluír/Incluír | G22: KGC_02F1/Application/USER7/CMD001 | H22: ON: Incluí / OFF: Excluí | I22: Comando D | J22: 2F1/2F2 | K22: Cmd Direto | L22: 204
A23: 02F1 | B23: LT_KGC | C23: Grupo de Ajustes 2 - Excluir / Incluir | F23: CMD RMT.02 Troca de Grupo | G23: KGC_02F1/Application/USER7/CMD002 | H23: ON: Incluí / OFF: Excluí | I23: Comando D | J23: 2F1/2F2 | K23: Cmd Direto | L23: 205
A24: 02F1 | B24: LT_KGC | C24: Check de Sincronismo (25) - Bloquear / Desbloquear | F24: CMD RMT.03 25 Bloqueio/Desbloqueio | G24: KGC_02F1/Application/USER7/CMD003 | H24: ON: Incluí / OFF: Excluí | I24: Comando D | J24: 2F1/2F2 | K24: Cmd Direto | L24: 206
A25: 02F1 | B25: LT_KGC | C25: Reserva para Aplicação Futura RGE | F25: CMD RMT.004 Reserva | G25: KGC_02F1/Application/USER7/CMD004 | H25: ON: Incluí / OFF: Excluí | I25: Comando D | J25: 2F1/2F3 | K25: Cmd Direto | L25: 207
A26: 02F1 | B26: LT_KGC | C26: Reserva para Aplicação Futura RGE | F26: CMD RMT.005 Reserva | G26: KGC_02F1/Application/USER7/CMD005 | H26: ON: Incluí / OFF: Excluí | I26: Comando D | J26: 2F1/2F4 | K26: Cmd Direto | L26: 208
A27: Digitais (Controle)
A28: Disjuntor 52-3 (02Q0)
A29: 02F1 | B29: LT_KGC | C29: Disj. 52-3 (02Q0) - Desligado | D29: 3.1 | F29: VD.001 DJ 52 Desligado Consistido | G29: KGC_02F1/Application/USER3/VD001 | H29: 1 Desligado | I29: Digital Simples | J29: 2F1/2F2 | K29: Consistido | L29: 200
A30: 02F1 | B30: LT_KGC | C30: Disj. 52-3 (02Q0) - Ligado | D30: 3.2 | F30: VD.002 DJ 52 Ligado Consistido | G30: KGC_02F1/Application/USER3/VD002 | H30: 1 Ligado | I30: Digital Simples | J30: 2F1/2F2 | K30: Consistido | L30: 201
A31: 02F1 | B31: LT_KGC | C31: Disj. 52-3 (02Q0) - Indefinido | F31: VD.003 DJ 52 Indefinido | G31: KGC_02F1/Application/USER3/VD003 | H31: 1 Alarme | I31: Digital Simples | J31: 2F1/2F2 | K31: Consistido | L31: 202 | M31: N2
A32: 02F1 | B32: LT_KGC | C32: Disj. 52-3 (02Q0) - Baixa Pressão SF6 - Alarme | D32: 3.3 | F32: BI.3.3 DJ 52 SF6 1º Estagio | G32: KGC_02F1/Application/USER1/BI303 | H32: 1 Alarme | I32: Digital Simples | J32: 2F1/2F2 | K32: Consistido | L32: 203
A33: 02F1 | B33: LT_KGC | C33: Disj. 52-3 (02Q0) - Baixa Pressão SF6 - Bloqueio | D33: 3.4 | F33: BI.3.4 DJ 52 SF6 2º Estagio | G33: KGC_02F1/Application/USER1/BI304 | H33: 1 Alarme | I33: Digital Simples | J33: 2F1/2F2 | K33: Consistido | L33: 204
A34: 02F1 | B34: LT_KGC | C34: Disj. 52-3 (02Q0) - Mola Descarregada ou FVCC CMD Bob. Ab. 1 ou 2 | D34: 3.5 | F34: VD.036 52 Mola Descarregada Temporizada | G34: KGC_02F1/Application/USER3/VD036 | H34: 1 Alarme | I34: Digital Simples | J34: 2F1/2F2 | K34: Consistido | L34: 205
A35: 02F1 | B35: LT_KGC | C35: Disj. 52-3 (02Q0) - Chave 43LR Pos. Remoto | D35: 3.6 | F35: BI.3.6 DJ 52 43LR Remoto | G35: KGC_02F1/Application/USER1/BI306 | H35: 1 Normal | I35: Digital Simples | J35: 2F1/2F2 | K35: Consistido | L35: 206
A36: 02F1 | B36: LT_KGC | C36: Disj. 52-3 (02Q0) – Supervisão Bobina de Ligar | D36: 4.1 | F36: VD.035 52 Falha Bob. Ligar | G36: KGC_02F1/Application/USER3/VD035 | H36: 1 Alarme | I36: Digital Simples | J36: 2F1/2F2 | K36: Consistido | L36: 207
A37: 02F1 | B37: LT_KGC | C37: Disj. 52-3 (02Q0) - Supervisão Bobina Desligar 1 | D37: 4.2 | F37: VD.033 52 Falha Bob. Aber. 1 | G37: KGC_02F1/Application/USER3/VD033 | H37: 1 Alarme | I37: Digital Simples | J37: 2F1/2F2 | K37: Consistido | L37: 208
A38: 02F1 | B38: LT_KGC | C38: Disj. 52-3 (02Q0) - Supervisão Bobina Desligar 2 | D38: 4.3 | F38: VD.034 52 Falha Bob. Abert. 2 | G38: KGC_02F1/Application/USER3/VD034 | H38: 1 Alarme | I38: Digital Simples | J38: 2F1/2F2 | K38: Consistido | L38: 209
A39: 02F1 | B39: LT_KGC | C39: Disj. 52-3 (02Q0) - Intertravamento | E39: 1.2 | F39: VD.088 DJ 52 Intertravamento | G39: KGC_02F1/Application/USER3/VD088 | H39: 1 Libera | I39: Digital Simples | J39: 1F1/1F2 | K39: Consistido | L39: 210 | M39: N2
A40: 02F1 | B40: LT_KGC | C40: Disj. 52-3 (02Q0) - Falha Comando de Desligar | F40: VD.032 52 Falha Comando de Desligar | G40: KGC_02F1/Application/USER3/VD032 | H40: 1 Falha | I40: Digital Simples | J40: 2F1/2F2 | K40: Consistido | L40: 211 | M40: N2
...

Sheet 01F1_KGC_A
A1: #VALUE! | C1: SUBESTAÇÃO RGE GRAVATAÍ 4 (SE_GTD) | K1: Consistido: Consistir IED Principal e Alternado (DNP em Vermelho) Direto: Aquisição direta do IED Cmd Direto: Comando Direct (Enviar para Principal e Alternado
C2: Lista de Pontos Supervisionados LT_KGC Unidade Alternado
C3: Relé: Siemens 7SA86 Shorcode: P1A639088 | G3: =Capa!G64 -> IP:10.39.13.12 | I3: Concentradora: SICAM PAS | O3: COS
C4: Protocolo: IEC 61850 Versão:2.1 FW: V9.8 FW Comm: V9.8 | I4: Protocolo: DNP3 IP:10.34.13.2 End:13
A5: IED | B5: Módulo | C5: Descrição do ponto | D5: Entrada Binária | E5: Saída Binária | F5: Variável | G5: Endereço Variável | H5: Variação: | I5: Tipo | J5: Origem | K5: Lógica | L5: Endereço DNP3 | M5: N2 | N5: N3 | O5: NIVEL3
A6: Analógicas
A7: 02F2 | B7: LT_KGC | C7: Corrente Fase A | D7: 1IA | F7: Iph:A | G7: KGC_02F2/CB1_Fundamental/FPRE_MMXU1/A/phsA | I7: Analógico | J7: 2F1/2F2 | K7: Consistido | L7: * | O7: =VLOOKUP(AB7,[1]ETerra_A!$A$1:$D$30000,3,0) -> #N/A
A8: 02F2 | B8: LT_KGC | C8: Corrente Fase B | D8: 1IB | F8: Iph:B | G8: KGC_02F2/CB1_Fundamental/FPRE_MMXU1/A/phsB | I8: Analógico | J8: 2F1/2F2 | K8: Consistido | L8: * | O8: =VLOOKUP(AB8,[1]ETerra_A!$A$1:$D$30000,3,0) -> #N/A
A9: 02F2 | B9: LT_KGC | C9: Corrente Fase C | D9: 1IC | F9: Iph:C | G9: KGC_02F2/CB1_Fundamental/FPRE_MMXU1/A/phsC | I9: Analógico | J9: 2F1/2F2 | K9: Consistido | L9: * | O9: =VLOOKUP(AB9,[1]ETerra_A!$A$1:$D$30000,3,0) -> #N/A
A10: 02F2 | B10: B69P | C10: Tensão Barra Fases AB | D10: 1V1 | F10: Vpp:AB | G10: KGC_02F2/CB1_Fundamental/FPRE_MMXU1/PPV/phsAB | I10: Analógico | J10: 2F1/2F2 | K10: Consistido | L10: * | O10: =VLOOKUP(AB10,[1]ETerra_A!$A$1:$D$30000,3,0) -> #N/A
A11: 02F2 | B11: B69P | C11: Tensão Barra Fases BC | D11: 1V2 | F11: Vpp:BC | G11: KGC_02F2/CB1_Fundamental/FPRE_MMXU1/PPV/phsBC | I11: Analógico | J11: 2F1/2F2 | K11: Consistido | L11: * | O11: =VLOOKUP(AB11,[1]ETerra_A!$A$1:$D$30000,3,0) -> #N/A
A12: 02F2 | B12: B69P | C12: Tensão Barra Fases CA | D12: 1V3 | F12: Vpp:CA | G12: KGC_02F2/CB1_Fundamental/FPRE_MMXU1/PPV/phsCA | I12: Analógico | J12: 2F1/2F2 | K12: Consistido | L12: * | O12: =VLOOKUP(AB12,[1]ETerra_A!$A$1:$D$30000,3,0) -> #N/A
A13: 02F2 | B13: LT_KGC | C13: Tensão Linha (Fase B) | D13: 1V4 | F13: V2 | G13: KGC_02F2/CB1_25Synchronization/GENRSYN1/V2Clc | I13: Analógico | J13: 2F1/2F2 | K13: Consistido | L13: * | O13: =VLOOKUP(AB13,[1]ETerra_A!$A$1:$D$30000,3,0) -> #N/A
A14: 02F2 | B14: LT_KGC | C14: Potência Ativa | F14: P tot | G14: KGC_02F2/Ln1_OperationalValues/PPRE_MMXU1/TotW | I14: Analógico | J14: 2F1/2F2 | K14: Consistido | L14: * | O14: =VLOOKUP(AB14,[1]ETerra_A!$A$1:$D$30000,3,0) -> #N/A
A15: 02F2 | B15: LT_KGC | C15: Potência Reativa | F15: Q tot | G15: KGC_02F2/Ln1_OperationalValues/PPRE_MMXU1/TotVAr | I15: Analógico | J15: 2F1/2F2 | K15: Consistido | L15: * | O15: =VLOOKUP(AB15,[1]ETerra_A!$A$1:$D$30000,3,0) -> #N/A
A16: 02F2 | B16: LT_KGC | C16: Distancia da Última Falta | F16: VD..091 Distância da Falta | G16: KGC_02F2/Application/USER3/VA001 | I16: Analógico | J16: 2F2 | K16: Direto | L16: 209 | O16: =VLOOKUP(AB16,[1]ETerra_A!$A$1:$D$30000,3,0) -> #N/A
A17: Comandos
A18: 02F2 | B18: LT_KGC | C18: Disj. 52-3 (02Q0) - Desligar / Ligar | E18: 1.3/1.1 | F18: Comando DJ/Pos | G18: KGC_02F2/CB1/CSWI1/Pos | H18: ON: Ligar / OFF: Desligar | I18: Comando D | J18: 2F1/2F2 | K18: Cmd Direto | L18: * | O18: =VLOOKUP(AB18,[1]ETerra_C!$A$1:$D$30000,2,0) -> #N/A
A19: 02F2 | B19: LT_KGC | C19: Secc. 89-14 (02Q1 Barra) - Abrir / Fechar | E19: 3.2/3.3 | F19: Comando 89 Barra | G19: KGC_02F2/Dc1/CSWI1/Pos | H19: ON: Fechar / OFF: Abrir | I19: Comando D | J19: 2F1/2F2 | K19: Cmd Direto | L19: * | O19: =VLOOKUP(AB19,[1]ETerra_C!$A$1:$D$30000,2,0) -> #N/A
A20: 02F2 | B20: LT_KGC | C20: Secc. 89-16 (02Q2 Linha) - Abrir / Fechar | E20: 4.2/4.3 | F20: Comando 89 Linha | G20: KGC_02F2/Dc2/CSWI1/Pos | H20: ON: Fechar / OFF: Abrir | I20: Comando D | J20: 2F1/2F2 | K20: Cmd Direto | L20: * | O20: =VLOOKUP(AB20,[1]ETerra_C!$A$1:$D$30000,2,0) -> #N/A
A21: 02F2 | B21: LT_KGC | C21: Secc. 89-18 (02Q3 Contorno) - Abrir / Fechar | E21: 3.5/3.6 | F21: Comando 89 Contorno | G21: KGC_02F2/Dc3/CSWI1/Pos | H21: ON: Fechar / OFF: Abrir | I21: Comando D | J21: 2F1/2F2 | K21: Cmd Direto | L21: * | O21: =VLOOKUP(AB21,[1]ETerra_C!$A$1:$D$30000,2,0) -> #N/A
A22: 02F2 | B22: LT_KGC | C22: Religamento Automático (79) - Excluir / Incluir | F22: CMD RMT.01 79 Excluír/Incluír | G22: KGC_02F2/Application/USER7/CMD001 | H22: ON: Incluí / OFF: Excluí | I22: Comando D | J22: 2F1/2F2 | K22: Cmd Direto | L22: * | O22: =VLOOKUP(AB22,[1]ETerra_C!$A$1:$D$30000,2,0) -> #N/A
A23: 02F2 | B23: LT_KGC | C23: Grupo de Ajustes 2 - Excluir / Incluir | F23: CMD.02 Troca de Grupo | G23: KGC_02F2/Application/USER7/CMD002 | H23: ON: Incluí / OFF: Excluí | I23: Comando D | J23: 2F1/2F2 | K23: Cmd Direto | L23: * | O23: =VLOOKUP(AB23,[1]ETerra_C!$A$1:$D$30000,2,0) -> #N/A
A24: 02F2 | B24: LT_KGC | C24: Check de Sincronismo (25) - Bloquear / Desbloquear | F24: CMD.03 25 Bloqueio/Desbloqueio | G24: KGC_02F2/Application/USER7/CMD003 | H24: ON: Incluí / OFF: Excluí | I24: Comando D | J24: 2F1/2F2 | K24: Cmd Direto | L24: *
A25: 02F2 | B25: LT_KGC | C25: Reserva para Aplicação Futura RGE | F25: CMD RMT.004 Reserva | G25: KGC_02F2/Application/USER7/CMD004 | H25: ON: Incluí / OFF: Excluí | I25: Comando D | J25: 2F1/2F2 | K25: Cmd Direto | L25: *
A26: 02F2 | B26: LT_KGC | C26: Reserva para Aplicação Futura RGE | F26: CMD RMT.005 Reserva | G26: KGC_02F2/Application/USER7/CMD005 | H26: ON: Incluí / OFF: Excluí | I26: Comando D | J26: 2F1/2F2 | K26: Cmd Direto | L26: *
A27: Digitais (Controle)
A28: Disjuntor 52-3 (02Q0)
A29: 02F2 | B29: LT_KGC | C29: Disj. 52-3 (02Q0) - Desligado | D29: 3.1 | F29: VD.001 DJ 52 Desligado Consistido | G29: KGC_02F2/Application/USER3/VD001 | H29: 1 Desligado | I29: Digital Simples | J29: 2F1/2F2 | K29: Consistido | L29: * | O29: =VLOOKUP(AB29,[1]ETerra_D!$A$1:$D$30000,4,0) -> #N/A
A30: 02F2 | B30: LT_KGC | C30: Disj. 52-3 (02Q0) - Ligado | D30: 3.2 | F30: VD.002 DJ 52 Ligado Consistido | G30: KGC_02F2/Application/USER3/VD002 | H30: 1 Ligado | I30: Digital Simples | J30: 2F1/2F2 | K30: Consistido | L30: * | O30: =VLOOKUP(AB30,[1]ETerra_D!$A$1:$D$30000,4,0) -> #N/A
A31: 02F2 | B31: LT_KGC | C31: Disj. 52-3 (02Q0) - Indefinido | F31: VD.003 DJ 52 Indefinido | G31: KGC_02F2/Application/USER3/VD003 | H31: 1 Alarme | I31: Digital Simples | J31: 2F1/2F2 | K31: Consistido | L31: * | M31: N2
