Workbook

Sheet Informações
B2: Nome SE | C2: IMIGRANTE
B3: Sigla SE | C3: IMA
B4: Tipo | C4: UTR
B5: Protocolo | C5: DNP3
B6: AOR | C6: =C3 -> IMA
B7: Mnemônico RTU | C7: =_xlfn.TEXTJOIN("_",FALSE,C4,C3,"1") -> UTR_IMA_1
B8: Fabricante da UTR | C8: SIEMENS_SICAM
B9: Adress Source | C9: X
B10: Adress Destination | C10: X
B11: IP Canal Principal | C11: 10.34.16.2 | D11: Porta TCP | E11: 20000
B12: IP Canal Starlink (8) | C12: 10.68.22.2 | D12: Porta TCP | E12: 20000
B13: IP Canal Starlink (9) | D13: Porta TCP | E13: XXXX
B15: Analógicos | C15: Como padrão, analógicos devem ser configurados como float. Caso não seja possível, deve ser utilizada escala conforme coluna L presente nas abas da lista de ponto ou informada qual escala deverá ser configurada.
B16: Estampa de tempo | C16: A estampa de tempo deve ser enviada em todos os pontos digitais
B17: Modo de Comando | C17: Como padrão, o modo de comando deve ser configurado como Direto. Caso haja alguma divergência, deve ser sinalizado.
B19: OBSERVAÇÃO
C26: PONTOS ADICIONADOS
C27: PONTOS ALTERADOS
C28: PONTOS EXCLUIDOS
C29: INDEX SUBISTITUIDOS - CORREÇÃO DOS ESTADOS DOS EQUIPAMENTOS (CONSISTIDOS)

Sheet LT 1 (FUTURO)
A1: MÓDULO - LINHA DE TRANSMISSÃO - LT 69KV (FUTURO) - 01F1/01F2
A2: EQUIPAMENTO | B2: NÚMERO OPERATIVO / MNEMNICO
A3: MÓDULO | B3: 1
A4: DJ | B4: 52-1
A5: SECC | B5: 89-4
A6: SECF | B6: 89-2
A7: SECT | B7: 89-6
A8: SECG | B8: 29-1
A10: Utilizado? | B10: SUBESTAÇÃO | C10: MÓDULO | D10: EQUIPAMENTO | E10: TIPO | F10: DESCRIÇÃO DO PONTO | G10: SIGLA SINAL | H10: NOME | I10: Tipo | J10: Nível Lógico 0 | K10: Nível Lógico 1 | L10: Escala | M10: Control Code / Qualificador | N10: INDEX DNP3
A11: NÃO | B11: =Informações!$C$3 -> IMA | C11: LT | D11: TC | E11: A | F11: =VLOOKUP(G11,[1]Analog!$A:$B,2,FALSE) -> CORRENTE FASE A | G11: IA | H11: {=_xlfn.IFS(OR(D11="TC",D11="TP",D11="LT"),CONCATENATE(B11,"_",C11,$B$3,"_",C11,$B$3,"_",G11),D11="SECC",CONCATENATE(B11,"_",C11,$B$3,"_",$B$5,"_",G11),D11="SECF",CONCATENATE(B11,"_",C11,$B$3,"_",$B$6,"_",G11),D11="SECT",CONCATENATE(B11,"_",C11,$B$3,"_",$B$7,"_",G11),D11="SECG",CONCATENATE(B11,"_",C11,$B$3,"_",$B$8,"_",G11),D11="DJ",CONCATENATE(B11,"_",C11,$B$3,"_",$B$4,"_",G11),D11="DJ_P",CONCATENATE(B11,"_",C11,$B$3,"_",$B$4,"_P","_",G11),D11="DJ_A",CONCATENATE(B11,"_",C11,$B$3,"_",$B$4,"_A","_",G11),D11="LT_P",CONCATENATE(B11,"_",C11,$B$3,"_",C11,$B$3,"_P","_",G11),D11="LT_A",CONCATENATE(B11,"_",C11,$B$3,"_",C11,$B$3,"_A","_",G11))} -> IMA_LT1_LT1_IA | I11: Ponto Simples | J11: - | K11: - | L11: 1 | M11: -
A12: NÃO | B12: =Informações!$C$3 -> IMA | C12: LT | D12: TC | E12: A | F12: =VLOOKUP(G12,[1]Analog!$A:$B,2,FALSE) -> CORRENTE FASE B | G12: IB | H12: {=_xlfn.IFS(OR(D12="TC",D12="TP",D12="LT"),CONCATENATE(B12,"_",C12,$B$3,"_",C12,$B$3,"_",G12),D12="SECC",CONCATENATE(B12,"_",C12,$B$3,"_",$B$5,"_",G12),D12="SECF",CONCATENATE(B12,"_",C12,$B$3,"_",$B$6,"_",G12),D12="SECT",CONCATENATE(B12,"_",C12,$B$3,"_",$B$7,"_",G12),D12="SECG",CONCATENATE(B12,"_",C12,$B$3,"_",$B$8,"_",G12),D12="DJ",CONCATENATE(B12,"_",C12,$B$3,"_",$B$4,"_",G12),D12="DJ_P",CONCATENATE(B12,"_",C12,$B$3,"_",$B$4,"_P","_",G12),D12="DJ_A",CONCATENATE(B12,"_",C12,$B$3,"_",$B$4,"_A","_",G12),D12="LT_P",CONCATENATE(B12,"_",C12,$B$3,"_",C12,$B$3,"_P","_",G12),D12="LT_A",CONCATENATE(B12,"_",C12,$B$3,"_",C12,$B$3,"_A","_",G12))} -> IMA_LT1_LT1_IB | I12: Ponto Simples | J12: - | K12: - | L12: 1 | M12: -
A13: NÃO | B13: =Informações!$C$3 -> IMA | C13: LT | D13: TC | E13: A | F13: =VLOOKUP(G13,[1]Analog!$A:$B,2,FALSE) -> CORRENTE FASE C | G13: IC | H13: {=_xlfn.IFS(OR(D13="TC",D13="TP",D13="LT"),CONCATENATE(B13,"_",C13,$B$3,"_",C13,$B$3,"_",G13),D13="SECC",CONCATENATE(B13,"_",C13,$B$3,"_",$B$5,"_",G13),D13="SECF",CONCATENATE(B13,"_",C13,$B$3,"_",$B$6,"_",G13),D13="SECT",CONCATENATE(B13,"_",C13,$B$3,"_",$B$7,"_",G13),D13="SECG",CONCATENATE(B13,"_",C13,$B$3,"_",$B$8,"_",G13),D13="DJ",CONCATENATE(B13,"_",C13,$B$3,"_",$B$4,"_",G13),D13="DJ_P",CONCATENATE(B13,"_",C13,$B$3,"_",$B$4,"_P","_",G13),D13="DJ_A",CONCATENATE(B13,"_",C13,$B$3,"_",$B$4,"_A","_",G13),D13="LT_P",CONCATENATE(B13,"_",C13,$B$3,"_",C13,$B$3,"_P","_",G13),D13="LT_A",CONCATENATE(B13,"_",C13,$B$3,"_",C13,$B$3,"_A","_",G13))} -> IMA_LT1_LT1_IC | I13: Ponto Simples | J13: - | K13: - | L13: 1 | M13: -
A14: NÃO | B14: =Informações!$C$3 -> IMA | C14: LT | D14: TP | E14: A | F14: =VLOOKUP(G14,[1]Analog!$A:$B,2,FALSE) -> TENSAO BARRA FASE A | G14: VA_B | H14: {=_xlfn.IFS(OR(D14="TC",D14="TP",D14="LT"),CONCATENATE(B14,"_",C14,$B$3,"_",C14,$B$3,"_",G14),D14="SECC",CONCATENATE(B14,"_",C14,$B$3,"_",$B$5,"_",G14),D14="SECF",CONCATENATE(B14,"_",C14,$B$3,"_",$B$6,"_",G14),D14="SECT",CONCATENATE(B14,"_",C14,$B$3,"_",$B$7,"_",G14),D14="SECG",CONCATENATE(B14,"_",C14,$B$3,"_",$B$8,"_",G14),D14="DJ",CONCATENATE(B14,"_",C14,$B$3,"_",$B$4,"_",G14),D14="DJ_P",CONCATENATE(B14,"_",C14,$B$3,"_",$B$4,"_P","_",G14),D14="DJ_A",CONCATENATE(B14,"_",C14,$B$3,"_",$B$4,"_A","_",G14),D14="LT_P",CONCATENATE(B14,"_",C14,$B$3,"_",C14,$B$3,"_P","_",G14),D14="LT_A",CONCATENATE(B14,"_",C14,$B$3,"_",C14,$B$3,"_A","_",G14))} -> IMA_LT1_LT1_VA_B | I14: Ponto Simples | J14: - | K14: - | L14: 0.01 | M14: -
A15: NÃO | B15: =Informações!$C$3 -> IMA | C15: LT | D15: TP | E15: A | F15: =VLOOKUP(G15,[1]Analog!$A:$B,2,FALSE) -> TENSAO BARRA FASE B | G15: VB_B | H15: {=_xlfn.IFS(OR(D15="TC",D15="TP",D15="LT"),CONCATENATE(B15,"_",C15,$B$3,"_",C15,$B$3,"_",G15),D15="SECC",CONCATENATE(B15,"_",C15,$B$3,"_",$B$5,"_",G15),D15="SECF",CONCATENATE(B15,"_",C15,$B$3,"_",$B$6,"_",G15),D15="SECT",CONCATENATE(B15,"_",C15,$B$3,"_",$B$7,"_",G15),D15="SECG",CONCATENATE(B15,"_",C15,$B$3,"_",$B$8,"_",G15),D15="DJ",CONCATENATE(B15,"_",C15,$B$3,"_",$B$4,"_",G15),D15="DJ_P",CONCATENATE(B15,"_",C15,$B$3,"_",$B$4,"_P","_",G15),D15="DJ_A",CONCATENATE(B15,"_",C15,$B$3,"_",$B$4,"_A","_",G15),D15="LT_P",CONCATENATE(B15,"_",C15,$B$3,"_",C15,$B$3,"_P","_",G15),D15="LT_A",CONCATENATE(B15,"_",C15,$B$3,"_",C15,$B$3,"_A","_",G15))} -> IMA_LT1_LT1_VB_B | I15: Ponto Simples | J15: - | K15: - | L15: 0.01 | M15: -
A16: NÃO | B16: =Informações!$C$3 -> IMA | C16: LT | D16: TP | E16: A | F16: =VLOOKUP(G16,[1]Analog!$A:$B,2,FALSE) -> TENSAO BARRA FASE C | G16: VC_B | H16: {=_xlfn.IFS(OR(D16="TC",D16="TP",D16="LT"),CONCATENATE(B16,"_",C16,$B$3,"_",C16,$B$3,"_",G16),D16="SECC",CONCATENATE(B16,"_",C16,$B$3,"_",$B$5,"_",G16),D16="SECF",CONCATENATE(B16,"_",C16,$B$3,"_",$B$6,"_",G16),D16="SECT",CONCATENATE(B16,"_",C16,$B$3,"_",$B$7,"_",G16),D16="SECG",CONCATENATE(B16,"_",C16,$B$3,"_",$B$8,"_",G16),D16="DJ",CONCATENATE(B16,"_",C16,$B$3,"_",$B$4,"_",G16),D16="DJ_P",CONCATENATE(B16,"_",C16,$B$3,"_",$B$4,"_P","_",G16),D16="DJ_A",CONCATENATE(B16,"_",C16,$B$3,"_",$B$4,"_A","_",G16),D16="LT_P",CONCATENATE(B16,"_",C16,$B$3,"_",C16,$B$3,"_P","_",G16),D16="LT_A",CONCATENATE(B16,"_",C16,$B$3,"_",C16,$B$3,"_A","_",G16))} -> IMA_LT1_LT1_VC_B | I16: Ponto Simples | J16: - | K16: - | L16: 0.01 | M16: -
A17: NÃO | B17: =Informações!$C$3 -> IMA | C17: LT | D17: TP | E17: A | F17: =VLOOKUP(G17,[1]Analog!$A:$B,2,FALSE) -> TENSAO LINHA FASE A | G17: VA_L | H17: {=_xlfn.IFS(OR(D17="TC",D17="TP",D17="LT"),CONCATENATE(B17,"_",C17,$B$3,"_",C17,$B$3,"_",G17),D17="SECC",CONCATENATE(B17,"_",C17,$B$3,"_",$B$5,"_",G17),D17="SECF",CONCATENATE(B17,"_",C17,$B$3,"_",$B$6,"_",G17),D17="SECT",CONCATENATE(B17,"_",C17,$B$3,"_",$B$7,"_",G17),D17="SECG",CONCATENATE(B17,"_",C17,$B$3,"_",$B$8,"_",G17),D17="DJ",CONCATENATE(B17,"_",C17,$B$3,"_",$B$4,"_",G17),D17="DJ_P",CONCATENATE(B17,"_",C17,$B$3,"_",$B$4,"_P","_",G17),D17="DJ_A",CONCATENATE(B17,"_",C17,$B$3,"_",$B$4,"_A","_",G17),D17="LT_P",CONCATENATE(B17,"_",C17,$B$3,"_",C17,$B$3,"_P","_",G17),D17="LT_A",CONCATENATE(B17,"_",C17,$B$3,"_",C17,$B$3,"_A","_",G17))} -> IMA_LT1_LT1_VA_L | I17: Ponto Simples | J17: - | K17: - | L17: 0.01 | M17: -
A18: NÃO | B18: =Informações!$C$3 -> IMA | C18: LT | D18: TP | E18: A | F18: =VLOOKUP(G18,[1]Analog!$A:$B,2,FALSE) -> TENSAO LINHA FASE B | G18: VB_L | H18: {=_xlfn.IFS(OR(D18="TC",D18="TP",D18="LT"),CONCATENATE(B18,"_",C18,$B$3,"_",C18,$B$3,"_",G18),D18="SECC",CONCATENATE(B18,"_",C18,$B$3,"_",$B$5,"_",G18),D18="SECF",CONCATENATE(B18,"_",C18,$B$3,"_",$B$6,"_",G18),D18="SECT",CONCATENATE(B18,"_",C18,$B$3,"_",$B$7,"_",G18),D18="SECG",CONCATENATE(B18,"_",C18,$B$3,"_",$B$8,"_",G18),D18="DJ",CONCATENATE(B18,"_",C18,$B$3,"_",$B$4,"_",G18),D18="DJ_P",CONCATENATE(B18,"_",C18,$B$3,"_",$B$4,"_P","_",G18),D18="DJ_A",CONCATENATE(B18,"_",C18,$B$3,"_",$B$4,"_A","_",G18),D18="LT_P",CONCATENATE(B18,"_",C18,$B$3,"_",C18,$B$3,"_P","_",G18),D18="LT_A",CONCATENATE(B18,"_",C18,$B$3,"_",C18,$B$3,"_A","_",G18))} -> IMA_LT1_LT1_VB_L | I18: Ponto Simples | J18: - | K18: - | L18: 0.01 | M18: -
A19: NÃO | B19: =Informações!$C$3 -> IMA | C19: LT | D19: TP | E19: A | F19: =VLOOKUP(G19,[1]Analog!$A:$B,2,FALSE) -> TENSAO LINHA FASE C | G19: VC_L | H19: {=_xlfn.IFS(OR(D19="TC",D19="TP",D19="LT"),CONCATENATE(B19,"_",C19,$B$3,"_",C19,$B$3,"_",G19),D19="SECC",CONCATENATE(B19,"_",C19,$B$3,"_",$B$5,"_",G19),D19="SECF",CONCATENATE(B19,"_",C19,$B$3,"_",$B$6,"_",G19),D19="SECT",CONCATENATE(B19,"_",C19,$B$3,"_",$B$7,"_",G19),D19="SECG",CONCATENATE(B19,"_",C19,$B$3,"_",$B$8,"_",G19),D19="DJ",CONCATENATE(B19,"_",C19,$B$3,"_",$B$4,"_",G19),D19="DJ_P",CONCATENATE(B19,"_",C19,$B$3,"_",$B$4,"_P","_",G19),D19="DJ_A",CONCATENATE(B19,"_",C19,$B$3,"_",$B$4,"_A","_",G19),D19="LT_P",CONCATENATE(B19,"_",C19,$B$3,"_",C19,$B$3,"_P","_",G19),D19="LT_A",CONCATENATE(B19,"_",C19,$B$3,"_",C19,$B$3,"_A","_",G19))} -> IMA_LT1_LT1_VC_L | I19: Ponto Simples | J19: - | K19: - | L19: 0.01 | M19: -
A20: NÃO | B20: =Informações!$C$3 -> IMA | C20: LT | D20: TC | E20: A | F20: =VLOOKUP(G20,[1]Analog!$A:$B,2,FALSE) -> POTENCIA ATIVA | G20: P | H20: {=_xlfn.IFS(OR(D20="TC",D20="TP",D20="LT"),CONCATENATE(B20,"_",C20,$B$3,"_",C20,$B$3,"_",G20),D20="SECC",CONCATENATE(B20,"_",C20,$B$3,"_",$B$5,"_",G20),D20="SECF",CONCATENATE(B20,"_",C20,$B$3,"_",$B$6,"_",G20),D20="SECT",CONCATENATE(B20,"_",C20,$B$3,"_",$B$7,"_",G20),D20="SECG",CONCATENATE(B20,"_",C20,$B$3,"_",$B$8,"_",G20),D20="DJ",CONCATENATE(B20,"_",C20,$B$3,"_",$B$4,"_",G20),D20="DJ_P",CONCATENATE(B20,"_",C20,$B$3,"_",$B$4,"_P","_",G20),D20="DJ_A",CONCATENATE(B20,"_",C20,$B$3,"_",$B$4,"_A","_",G20),D20="LT_P",CONCATENATE(B20,"_",C20,$B$3,"_",C20,$B$3,"_P","_",G20),D20="LT_A",CONCATENATE(B20,"_",C20,$B$3,"_",C20,$B$3,"_A","_",G20))} -> IMA_LT1_LT1_P | I20: Ponto Simples | J20: - | K20: - | L20: 10 | M20: -
A21: NÃO | B21: =Informações!$C$3 -> IMA | C21: LT | D21: TC | E21: A | F21: =VLOOKUP(G21,[1]Analog!$A:$B,2,FALSE) -> POTENCIA REATIVA | G21: Q | H21: {=_xlfn.IFS(OR(D21="TC",D21="TP",D21="LT"),CONCATENATE(B21,"_",C21,$B$3,"_",C21,$B$3,"_",G21),D21="SECC",CONCATENATE(B21,"_",C21,$B$3,"_",$B$5,"_",G21),D21="SECF",CONCATENATE(B21,"_",C21,$B$3,"_",$B$6,"_",G21),D21="SECT",CONCATENATE(B21,"_",C21,$B$3,"_",$B$7,"_",G21),D21="SECG",CONCATENATE(B21,"_",C21,$B$3,"_",$B$8,"_",G21),D21="DJ",CONCATENATE(B21,"_",C21,$B$3,"_",$B$4,"_",G21),D21="DJ_P",CONCATENATE(B21,"_",C21,$B$3,"_",$B$4,"_P","_",G21),D21="DJ_A",CONCATENATE(B21,"_",C21,$B$3,"_",$B$4,"_A","_",G21),D21="LT_P",CONCATENATE(B21,"_",C21,$B$3,"_",C21,$B$3,"_P","_",G21),D21="LT_A",CONCATENATE(B21,"_",C21,$B$3,"_",C21,$B$3,"_A","_",G21))} -> IMA_LT1_LT1_Q | I21: Ponto Simples | J21: - | K21: - | L21: 10 | M21: -
A22: NÃO | B22: =Informações!$C$3 -> IMA | C22: LT | D22: LT | E22: A | F22: =VLOOKUP(G22,[1]Analog!$A:$B,2,FALSE) -> DISTANCIA DEFEITO | G22: KMDF | H22: {=_xlfn.IFS(OR(D22="TC",D22="TP",D22="LT"),CONCATENATE(B22,"_",C22,$B$3,"_",C22,$B$3,"_",G22),D22="SECC",CONCATENATE(B22,"_",C22,$B$3,"_",$B$5,"_",G22),D22="SECF",CONCATENATE(B22,"_",C22,$B$3,"_",$B$6,"_",G22),D22="SECT",CONCATENATE(B22,"_",C22,$B$3,"_",$B$7,"_",G22),D22="SECG",CONCATENATE(B22,"_",C22,$B$3,"_",$B$8,"_",G22),D22="DJ",CONCATENATE(B22,"_",C22,$B$3,"_",$B$4,"_",G22),D22="DJ_P",CONCATENATE(B22,"_",C22,$B$3,"_",$B$4,"_P","_",G22),D22="DJ_A",CONCATENATE(B22,"_",C22,$B$3,"_",$B$4,"_A","_",G22),D22="LT_P",CONCATENATE(B22,"_",C22,$B$3,"_",C22,$B$3,"_P","_",G22),D22="LT_A",CONCATENATE(B22,"_",C22,$B$3,"_",C22,$B$3,"_A","_",G22))} -> IMA_LT1_LT1_KMDF | I22: Ponto Simples | J22: - | K22: - | L22: 0.01 | M22: -
... A25: NÃO | B25: =Informações!$C$3 -> IMA | C25: LT | D25: TC | E25: A | F25: =VLOOKUP(G25,[1]Analog!$A:$B,2,FALSE) -> CORRENTE CURTO CIRCUITO FASE C | G25: ICCC | H25: {=_xlfn.IFS(OR(D25="TC",D25="TP",D25="LT"),CONCATENATE(B25,"_",C25,$B$3,"_",C25,$B$3,"_",G25),D25="SECC",CONCATENATE(B25,"_",C25,$B$3,"_",$B$5,"_",G25),D25="SECF",CONCATENATE(B25,"_",C25,$B$3,"_",$B$6,"_",G25),D25="SECT",CONCATENATE(B25,"_",C25,$B$3,"_",$B$7,"_",G25),D25="SECG",CONCATENATE(B25,"_",C25,$B$3,"_",$B$8,"_",G25),D25="DJ",CONCATENATE(B25,"_",C25,$B$3,"_",$B$4,"_",G25),D25="DJ_P",CONCATENATE(B25,"_",C25,$B$3,"_",$B$4,"_P","_",G25),D25="DJ_A",CONCATENATE(B25,"_",C25,$B$3,"_",$B$4,"_A","_",G25),D25="LT_P",CONCATENATE(B25,"_",C25,$B$3,"_",C25,$B$3,"_P","_",G25),D25="LT_A",CONCATENATE(B25,"_",C25,$B$3,"_",C25,$B$3,"_A","_",G25))} -> IMA_LT1_LT1_ICCC | I25: Ponto Simples | J25: - | K25: - | L25: 1 | M25: -
A26: NÃO | B26: =Informações!$C$3 -> IMA | C26: LT | D26: SECC | E26: C | F26: =VLOOKUP(G26,[1]Discrete!$A:$B,2,FALSE) -> SECCIONADORA CARGA | G26: SECC | H26: {=_xlfn.IFS(OR(D26="TC",D26="TP",D26="LT"),CONCATENATE(B26,"_",C26,$B$3,"_",C26,$B$3,"_",G26),D26="SECC",CONCATENATE(B26,"_",C26,$B$3,"_",$B$5,"_",G26),D26="SECF",CONCATENATE(B26,"_",C26,$B$3,"_",$B$6,"_",G26),D26="SECT",CONCATENATE(B26,"_",C26,$B$3,"_",$B$7,"_",G26),D26="SECG",CONCATENATE(B26,"_",C26,$B$3,"_",$B$8,"_",G26),D26="DJ",CONCATENATE(B26,"_",C26,$B$3,"_",$B$4,"_",G26),D26="DJ_P",CONCATENATE(B26,"_",C26,$B$3,"_",$B$4,"_P","_",G26),D26="DJ_A",CONCATENATE(B26,"_",C26,$B$3,"_",$B$4,"_A","_",G26),D26="LT_P",CONCATENATE(B26,"_",C26,$B$3,"_",C26,$B$3,"_P","_",G26),D26="LT_A",CONCATENATE(B26,"_",C26,$B$3,"_",C26,$B$3,"_A","_",G26))} -> IMA_LT1_89-4_SECC | I26: - | J26: - | K26: - | L26: - | M26: 0 - Trip/Pulse-On // 1 - Close/Pulse-On
A27: NÃO | B27: =Informações!$C$3 -> IMA | C27: LT | D27: SECF | E27: C | F27: =VLOOKUP(G27,[1]Discrete!$A:$B,2,FALSE) -> SECCIONADORA FONTE | G27: SECF | H27: {=_xlfn.IFS(OR(D27="TC",D27="TP",D27="LT"),CONCATENATE(B27,"_",C27,$B$3,"_",C27,$B$3,"_",G27),D27="SECC",CONCATENATE(B27,"_",C27,$B$3,"_",$B$5,"_",G27),D27="SECF",CONCATENATE(B27,"_",C27,$B$3,"_",$B$6,"_",G27),D27="SECT",CONCATENATE(B27,"_",C27,$B$3,"_",$B$7,"_",G27),D27="SECG",CONCATENATE(B27,"_",C27,$B$3,"_",$B$8,"_",G27),D27="DJ",CONCATENATE(B27,"_",C27,$B$3,"_",$B$4,"_",G27),D27="DJ_P",CONCATENATE(B27,"_",C27,$B$3,"_",$B$4,"_P","_",G27),D27="DJ_A",CONCATENATE(B27,"_",C27,$B$3,"_",$B$4,"_A","_",G27),D27="LT_P",CONCATENATE(B27,"_",C27,$B$3,"_",C27,$B$3,"_P","_",G27),D27="LT_A",CONCATENATE(B27,"_",C27,$B$3,"_",C27,$B$3,"_A","_",G27))} -> IMA_LT1_89-2_SECF | I27: - | J27: - | K27: - | L27: - | M27: 0 - Trip/Pulse-On // 1 - Close/Pulse-On
A28: NÃO | B28: =Informações!$C$3 -> IMA | C28: LT | D28: SECT | E28: C | F28: =VLOOKUP(G28,[1]Discrete!$A:$B,2,FALSE) -> SECCIONADORA TRANSFERENCIA | G28: SECT | H28: {=_xlfn.IFS(OR(D28="TC",D28="TP",D28="LT"),CONCATENATE(B28,"_",C28,$B$3,"_",C28,$B$3,"_",G28),D28="SECC",CONCATENATE(B28,"_",C28,$B$3,"_",$B$5,"_",G28),D28="SECF",CONCATENATE(B28,"_",C28,$B$3,"_",$B$6,"_",G28),D28="SECT",CONCATENATE(B28,"_",C28,$B$3,"_",$B$7,"_",G28),D28="SECG",CONCATENATE(B28,"_",C28,$B$3,"_",$B$8,"_",G28),D28="DJ",CONCATENATE(B28,"_",C28,$B$3,"_",$B$4,"_",G28),D28="DJ_P",CONCATENATE(B28,"_",C28,$B$3,"_",$B$4,"_P","_",G28),D28="DJ_A",CONCATENATE(B28,"_",C28,$B$3,"_",$B$4,"_A","_",G28),D28="LT_P",CONCATENATE(B28,"_",C28,$B$3,"_",C28,$B$3,"_P","_",G28),D28="LT_A",CONCATENATE(B28,"_",C28,$B$3,"_",C28,$B$3,"_A","_",G28))} -> IMA_LT1_89-6_SECT | I28: - | J28: - | K28: - | L28: - | M28: 0 - Trip/Pulse-On // 1 - Close/Pulse-On
A29: NÃO | B29: =Informações!$C$3 -> IMA | C29: LT | D29: DJ | E29: C | F29: =VLOOKUP(G29,[1]Discrete!$A:$B,2,FALSE) -> DISJUNTOR NF | G29: DJF1 | H29: {=_xlfn.IFS(OR(D29="TC",D29="TP",D29="LT"),CONCATENATE(B29,"_",C29,$B$3,"_",C29,$B$3,"_",G29),D29="SECC",CONCATENATE(B29,"_",C29,$B$3,"_",$B$5,"_",G29),D29="SECF",CONCATENATE(B29,"_",C29,$B$3,"_",$B$6,"_",G29),D29="SECT",CONCATENATE(B29,"_",C29,$B$3,"_",$B$7,"_",G29),D29="SECG",CONCATENATE(B29,"_",C29,$B$3,"_",$B$8,"_",G29),D29="DJ",CONCATENATE(B29,"_",C29,$B$3,"_",$B$4,"_",G29),D29="DJ_P",CONCATENATE(B29,"_",C29,$B$3,"_",$B$4,"_P","_",G29),D29="DJ_A",CONCATENATE(B29,"_",C29,$B$3,"_",$B$4,"_A","_",G29),D29="LT_P",CONCATENATE(B29,"_",C29,$B$3,"_",C29,$B$3,"_P","_",G29),D29="LT_A",CONCATENATE(B29,"_",C29,$B$3,"_",C29,$B$3,"_A","_",G29))} -> IMA_LT1_52-1_DJF1 | I29: - | J29: - | K29: - | L29: - | M29: 0 - Trip/Pulse-On // 1 - Close/Pulse-On
A30: NÃO | B30: =Informações!$C$3 -> IMA | C30: LT | D30: DJ | E30: C | F30: =VLOOKUP(G30,[1]Discrete!$A:$B,2,FALSE) -> #N/A | G30: 79 | H30: {=_xlfn.IFS(OR(D30="TC",D30="TP",D30="LT"),CONCATENATE(B30,"_",C30,$B$3,"_",C30,$B$3,"_",G30),D30="SECC",CONCATENATE(B30,"_",C30,$B$3,"_",$B$5,"_",G30),D30="SECF",CONCATENATE(B30,"_",C30,$B$3,"_",$B$6,"_",G30),D30="SECT",CONCATENATE(B30,"_",C30,$B$3,"_",$B$7,"_",G30),D30="SECG",CONCATENATE(B30,"_",C30,$B$3,"_",$B$8,"_",G30),D30="DJ",CONCATENATE(B30,"_",C30,$B$3,"_",$B$4,"_",G30),D30="DJ_P",CONCATENATE(B30,"_",C30,$B$3,"_",$B$4,"_P","_",G30),D30="DJ_A",CONCATENATE(B30,"_",C30,$B$3,"_",$B$4,"_A","_",G30),D30="LT_P",CONCATENATE(B30,"_",C30,$B$3,"_",C30,$B$3,"_P","_",G30),D30="LT_A",CONCATENATE(B30,"_",C30,$B$3,"_",C30,$B$3,"_A","_",G30))} -> IMA_LT1_52-1_79 | I30: - | J30: - | K30: - | L30: - | M30: 0 - Close/Pulse-On // 1 - Trip/Pulse-On
A31: NÃO | B31: =Informações!$C$3 -> IMA | C31: LT | D31: DJ | E31: C | F31: =VLOOKUP(G31,[1]Discrete!$A:$B,2,FALSE) -> 51 - FUNCAO SOBRECORRENTE TEMPORIZADA NEUTRO | G31: 51N | H31: {=_xlfn.IFS(OR(D31="TC",D31="TP",D31="LT"),CONCATENATE(B31,"_",C31,$B$3,"_",C31,$B$3,"_",G31),D31="SECC",CONCATENATE(B31,"_",C31,$B$3,"_",$B$5,"_",G31),D31="SECF",CONCATENATE(B31,"_",C31,$B$3,"_",$B$6,"_",G31),D31="SECT",CONCATENATE(B31,"_",C31,$B$3,"_",$B$7,"_",G31),D31="SECG",CONCATENATE(B31,"_",C31,$B$3,"_",$B$8,"_",G31),D31="DJ",CONCATENATE(B31,"_",C31,$B$3,"_",$B$4,"_",G31),D31="DJ_P",CONCATENATE(B31,"_",C31,$B$3,"_",$B$4,"_P","_",G31),D31="DJ_A",CONCATENATE(B31,"_",C31,$B$3,"_",$B$4,"_A","_",G31),D31="LT_P",CONCATENATE(B31,"_",C31,$B$3,"_",C31,$B$3,"_P","_",G31),D31="LT_A",CONCATENATE(B31,"_",C31,$B$3,"_",C31,$B$3,"_A","_",G31))} -> IMA_LT1_52-1_51N | I31: - | J31: - | K31: - | L31: - | M31: 0 - Close/Pulse-On // 1 - Trip/Pulse-On
A32: NÃO | B32: =Informações!$C$3 -> IMA | C32: LT | D32: DJ | E32: C | F32: =VLOOKUP(G32,[1]Discrete!$A:$B,2,FALSE) -> #N/A | G32: 81 | H32: {=_xlfn.IFS(OR(D32="TC",D32="TP",D32="LT"),CONCATENATE(B32,"_",C32,$B$3,"_",C32,$B$3,"_",G32),D32="SECC",CONCATENATE(B32,"_",C32,$B$3,"_",$B$5,"_",G32),D32="SECF",CONCATENATE(B32,"_",C32,$B$3,"_",$B$6,"_",G32),D32="SECT",CONCATENATE(B32,"_",C32,$B$3,"_",$B$7,"_",G32),D32="SECG",CONCATENATE(B32,"_",C32,$B$3,"_",$B$8,"_",G32),D32="DJ",CONCATENATE(B32,"_",C32,$B$3,"_",$B$4,"_",G32),D32="DJ_P",CONCATENATE(B32,"_",C32,$B$3,"_",$B$4,"_P","_",G32),D32="DJ_A",CONCATENATE(B32,"_",C32,$B$3,"_",$B$4,"_A","_",G32),D32="LT_P",CONCATENATE(B32,"_",C32,$B$3,"_",C32,$B$3,"_P","_",G32),D32="LT_A",CONCATENATE(B32,"_",C32,$B$3,"_",C32,$B$3,"_A","_",G32))} -> IMA_LT1_52-1_81 | I32: - | J32: - | K32: - | L32: - | M32: 0 - Close/Pulse-On // 1 - Trip/Pulse-On
A33: NÃO | B33: =Informações!$C$3 -> IMA | C33: LT | D33: DJ | E33: C | F33: =VLOOKUP(G33,[1]Discrete!$A:$B,2,FALSE) -> GRUPO DE AJUSTE FUNCAO 81 | G33: 81AJST | H33: {=_xlfn.IFS(OR(D33="TC",D33="TP",D33="LT"),CONCATENATE(B33,"_",C33,$B$3,"_",C33,$B$3,"_",G33),D33="SECC",CONCATENATE(B33,"_",C33,$B$3,"_",$B$5,"_",G33),D33="SECF",CONCATENATE(B33,"_",C33,$B$3,"_",$B$6,"_",G33),D33="SECT",CONCATENATE(B33,"_",C33,$B$3,"_",$B$7,"_",G33),D33="SECG",CONCATENATE(B33,"_",C33,$B$3,"_",$B$8,"_",G33),D33="DJ",CONCATENATE(B33,"_",C33,$B$3,"_",$B$4,"_",G33),D33="DJ_P",CONCATENATE(B33,"_",C33,$B$3,"_",$B$4,"_P","_",G33),D33="DJ_A",CONCATENATE(B33,"_",C33,$B$3,"_",$B$4,"_A","_",G33),D33="LT_P",CONCATENATE(B33,"_",C33,$B$3,"_",C33,$B$3,"_P","_",G33),D33="LT_A",CONCATENATE(B33,"_",C33,$B$3,"_",C33,$B$3,"_A","_",G33))} -> IMA_LT1_52-1_81AJST | I33: - | J33: - | K33: - | L33: - | M33: 0 - Close/Pulse-On // 1 - Trip/Pulse-On
A34: NÃO | B34: =Informações!$C$3 -> IMA | C34: LT | D34: DJ | E34: C | F34: =VLOOKUP(G34,[1]Discrete!$A:$B,2,FALSE) -> 25 - FUNCAO SINCRONISMO | G34: 25IE | H34: {=_xlfn.IFS(OR(D34="TC",D34="TP",D34="LT"),CONCATENATE(B34,"_",C34,$B$3,"_",C34,$B$3,"_",G34),D34="SECC",CONCATENATE(B34,"_",C34,$B$3,"_",$B$5,"_",G34),D34="SECF",CONCATENATE(B34,"_",C34,$B$3,"_",$B$6,"_",G34),D34="SECT",CONCATENATE(B34,"_",C34,$B$3,"_",$B$7,"_",G34),D34="SECG",CONCATENATE(B34,"_",C34,$B$3,"_",$B$8,"_",G34),D34="DJ",CONCATENATE(B34,"_",C34,$B$3,"_",$B$4,"_",G34),D34="DJ_P",CONCATENATE(B34,"_",C34,$B$3,"_",$B$4,"_P","_",G34),D34="DJ_A",CONCATENATE(B34,"_",C34,$B$3,"_",$B$4,"_A","_",G34),D34="LT_P",CONCATENATE(B34,"_",C34,$B$3,"_",C34,$B$3,"_P","_",G34),D34="LT_A",CONCATENATE(B34,"_",C34,$B$3,"_",C34,$B$3,"_A","_",G34))} -> IMA_LT1_52-1_25IE | I34: - | J34: - | K34: - | L34: - | M34: 0 - Close/Pulse-On // 1 - Trip/Pulse-On
A35: NÃO | B35: =Informações!$C$3 -> IMA | C35: LT | D35: DJ | E35: C | F35: =VLOOKUP(G35,[1]Discrete!$A:$B,2,FALSE) -> #N/A | G35: 27 | H35: {=_xlfn.IFS(OR(D35="TC",D35="TP",D35="LT"),CONCATENATE(B35,"_",C35,$B$3,"_",C35,$B$3,"_",G35),D35="SECC",CONCATENATE(B35,"_",C35,$B$3,"_",$B$5,"_",G35),D35="SECF",CONCATENATE(B35,"_",C35,$B$3,"_",$B$6,"_",G35),D35="SECT",CONCATENATE(B35,"_",C35,$B$3,"_",$B$7,"_",G35),D35="SECG",CONCATENATE(B35,"_",C35,$B$3,"_",$B$8,"_",G35),D35="DJ",CONCATENATE(B35,"_",C35,$B$3,"_",$B$4,"_",G35),D35="DJ_P",CONCATENATE(B35,"_",C35,$B$3,"_",$B$4,"_P","_",G35),D35="DJ_A",CONCATENATE(B35,"_",C35,$B$3,"_",$B$4,"_A","_",G35),D35="LT_P",CONCATENATE(B35,"_",C35,$B$3,"_",C35,$B$3,"_P","_",G35),D35="LT_A",CONCATENATE(B35,"_",C35,$B$3,"_",C35,$B$3,"_A","_",G35))} -> IMA_LT1_52-1_27 | I35: - | J35: - | K35: - | L35: - | M35: 0 - Close/Pulse-On // 1 - Trip/Pulse-On
A36: NÃO | B36: =Informações!$C$3 -> IMA | C36: LT | D36: DJ | E36: C | F36: =VLOOKUP(G36,[1]Discrete!$A:$B,2,FALSE) -> #N/A | G36: 59 | H36: {=_xlfn.IFS(OR(D36="TC",D36="TP",D36="LT"),CONCATENATE(B36,"_",C36,$B$3,"_",C36,$B$3,"_",G36),D36="SECC",CONCATENATE(B36,"_",C36,$B$3,"_",$B$5,"_",G36),D36="SECF",CONCATENATE(B36,"_",C36,$B$3,"_",$B$6,"_",G36),D36="SECT",CONCATENATE(B36,"_",C36,$B$3,"_",$B$7,"_",G36),D36="SECG",CONCATENATE(B36,"_",C36,$B$3,"_",$B$8,"_",G36),D36="DJ",CONCATENATE(B36,"_",C36,$B$3,"_",$B$4,"_",G36),D36="DJ_P",CONCATENATE(B36,"_",C36,$B$3,"_",$B$4,"_P","_",G36),D36="DJ_A",CONCATENATE(B36,"_",C36,$B$3,"_",$B$4,"_A","_",G36),D36="LT_P",CONCATENATE(B36,"_",C36,$B$3,"_",C36,$B$3,"_P","_",G36),D36="LT_A",CONCATENATE(B36,"_",C36,$B$3,"_",C36,$B$3,"_A","_",G36))} -> IMA_LT1_52-1_59 | I36: - | J36: - | K36: - | L36: - | M36: 0 - Close/Pulse-On // 1 - Trip/Pulse-On
A37: NÃO | B37: =Informações!$C$3 -> IMA | C37: LT | D37: DJ | E37: C | F37: =VLOOKUP(G37,[1]Discrete!$A:$B,2,FALSE) -> AJUSTE PARA 81 E1 | G37: 81U1 | H37: {=_xlfn.IFS(OR(D37="TC",D37="TP",D37="LT"),CONCATENATE(B37,"_",C37,$B$3,"_",C37,$B$3,"_",G37),D37="SECC",CONCATENATE(B37,"_",C37,$B$3,"_",$B$5,"_",G37),D37="SECF",CONCATENATE(B37,"_",C37,$B$3,"_",$B$6,"_",G37),D37="SECT",CONCATENATE(B37,"_",C37,$B$3,"_",$B$7,"_",G37),D37="SECG",CONCATENATE(B37,"_",C37,$B$3,"_",$B$8,"_",G37),D37="DJ",CONCATENATE(B37,"_",C37,$B$3,"_",$B$4,"_",G37),D37="DJ_P",CONCATENATE(B37,"_",C37,$B$3,"_",$B$4,"_P","_",G37),D37="DJ_A",CONCATENATE(B37,"_",C37,$B$3,"_",$B$4,"_A","_",G37),D37="LT_P",CONCATENATE(B37,"_",C37,$B$3,"_",C37,$B$3,"_P","_",G37),D37="LT_A",CONCATENATE(B37,"_",C37,$B$3,"_",C37,$B$3,"_A","_",G37))} -> IMA_LT1_52-1_81U1 | I37: - | J37: - | K37: - | L37: - | M37: 0 - Close/Pulse-On // 1 - Trip/Pulse-On
A38: NÃO | B38: =Informações!$C$3 -> IMA | C38: LT | D38: DJ | E38: C | F38: =VLOOKUP(G38,[1]Discrete!$A:$B,2,FALSE) -> AJUSTE PARA 81 E2 | G38: 81U2 | H38: {=_xlfn.IFS(OR(D38="TC",D38="TP",D38="LT"),CONCATENATE(B38,"_",C38,$B$3,"_",C38,$B$3,"_",G38),D38="SECC",CONCATENATE(B38,"_",C38,$B$3,"_",$B$5,"_",G38),D38="SECF",CONCATENATE(B38,"_",C38,$B$3,"_",$B$6,"_",G38),D38="SECT",CONCATENATE(B38,"_",C38,$B$3,"_",$B$7,"_",G38),D38="SECG",CONCATENATE(B38,"_",C38,$B$3,"_",$B$8,"_",G38),D38="DJ",CONCATENATE(B38,"_",C38,$B$3,"_",$B$4,"_",G38),D38="DJ_P",CONCATENATE(B38,"_",C38,$B$3,"_",$B$4,"_P","_",G38),D38="DJ_A",CONCATENATE(B38,"_",C38,$B$3,"_",$B$4,"_A","_",G38),D38="LT_P",CONCATENATE(B38,"_",C38,$B$3,"_",C38,$B$3,"_P","_",G38),D38="LT_A",CONCATENATE(B38,"_",C38,$B$3,"_",C38,$B$3,"_A","_",G38))} -> IMA_LT1_52-1_81U2 | I38: - | J38: - | K38: - | L38: - | M38: 0 - Close/Pulse-On // 1 - Trip/Pulse-On
A39: NÃO | B39: =Informações!$C$3 -> IMA | C39: LT | D39: DJ | E39: C | F39: =VLOOKUP(G39,[1]Discrete!$A:$B,2,FALSE) -> AJUSTE PARA 81 E3 | G39: 81U3 | H39: {=_xlfn.IFS(OR(D39="TC",D39="TP",D39="LT"),CONCATENATE(B39,"_",C39,$B$3,"_",C39,$B$3,"_",G39),D39="SECC",CONCATENATE(B39,"_",C39,$B$3,"_",$B$5,"_",G39),D39="SECF",CONCATENATE(B39,"_",C39,$B$3,"_",$B$6,"_",G39),D39="SECT",CONCATENATE(B39,"_",C39,$B$3,"_",$B$7,"_",G39),D39="SECG",CONCATENATE(B39,"_",C39,$B$3,"_",$B$8,"_",G39),D39="DJ",CONCATENATE(B39,"_",C39,$B$3,"_",$B$4,"_",G39),D39="DJ_P",CONCATENATE(B39,"_",C39,$B$3,"_",$B$4,"_P","_",G39),D39="DJ_A",CONCATENATE(B39,"_",C39,$B$3,"_",$B$4,"_A","_",G39),D39="LT_P",CONCATENATE(B39,"_",C39,$B$3,"_",C39,$B$3,"_P","_",G39),D39="LT_A",CONCATENATE(B39,"_",C39,$B$3,"_",C39,$B$3,"_A","_",G39))} -> IMA_LT1_52-1_81U3 | I39: - | J39: - | K39: - | L39: - | M39: 0 - Close/Pulse-On // 1 - Trip/Pulse-On
A40: NÃO | B40: =Informações!$C$3 -> IMA | C40: LT | D40: DJ | E40: C | F40: =VLOOKUP(G40,[1]Discrete!$A:$B,2,FALSE) -> AJUSTE PARA 81 E4 | G40: 81U4 | H40: {=_xlfn.IFS(OR(D40="TC",D40="TP",D40="LT"),CONCATENATE(B40,"_",C40,$B$3,"_",C40,$B$3,"_",G40),D40="SECC",CONCATENATE(B40,"_",C40,$B$3,"_",$B$5,"_",G40),D40="SECF",CONCATENATE(B40,"_",C40,$B$3,"_",$B$6,"_",G40),D40="SECT",CONCATENATE(B40,"_",C40,$B$3,"_",$B$7,"_",G40),D40="SECG",CONCATENATE(B40,"_",C40,$B$3,"_",$B$8,"_",G40),D40="DJ",CONCATENATE(B40,"_",C40,$B$3,"_",$B$4,"_",G40),D40="DJ_P",CONCATENATE(B40,"_",C40,$B$3,"_",$B$4,"_P","_",G40),D40="DJ_A",CONCATENATE(B40,"_",C40,$B$3,"_",$B$4,"_A","_",G40),D40="LT_P",CONCATENATE(B40,"_",C40,$B$3,"_",C40,$B$3,"_P","_",G40),D40="LT_A",CONCATENATE(B40,"_",C40,$B$3,"_",C40,$B$3,"_A","_",G40))} -> IMA_LT1_52-1_81U4 | I40: - | J40: - | K40: - | L40: - | M40: 0 - Close/Pulse-On // 1 - Trip/Pulse-On
A41: NÃO | B41: =Informações!$C$3 -> IMA | C41: LT | D41: DJ | E41: C | F41: AJUSTE PARA 81 ESTAGIO 5 | G41: 81U5 | H41: {=_xlfn.IFS(OR(D41="TC",D41="TP",D41="LT"),CONCATENATE(B41,"_",C41,$B$3,"_",C41,$B$3,"_",G41),D41="SECC",CONCATENATE(B41,"_",C41,$B$3,"_",$B$5,"_",G41),D41="SECF",CONCATENATE(B41,"_",C41,$B$3,"_",$B$6,"_",G41),D41="SECT",CONCATENATE(B41,"_",C41,$B$3,"_",$B$7,"_",G41),D41="SECG",CONCATENATE(B41,"_",C41,$B$3,"_",$B$8,"_",G41),D41="DJ",CONCATENATE(B41,"_",C41,$B$3,"_",$B$4,"_",G41),D41="DJ_P",CONCATENATE(B41,"_",C41,$B$3,"_",$B$4,"_P","_",G41),D41="DJ_A",CONCATENATE(B41,"_",C41,$B$3,"_",$B$4,"_A","_",G41),D41="LT_P",CONCATENATE(B41,"_",C41,$B$3,"_",C41,$B$3,"_P","_",G41),D41="LT_A",CONCATENATE(B41,"_",C41,$B$3,"_",C41,$B$3,"_A","_",G41))} -> IMA_LT1_52-1_81U5 | I41: - | J41: - | K41: - | L41: - | M41: 0 - Close/Pulse-On // 1 - Trip/Pulse-On
A42: NÃO | B42: =Informações!$C$3 -> IMA | C42: LT | D42: SECC | E42: D | F42: =VLOOKUP(G42,[1]Discrete!$A:$B,2,FALSE) -> SECCIONADORA CARGA | G42: SECC | H42: {=_xlfn.IFS(OR(D42="TC",D42="TP",D42="LT"),CONCATENATE(B42,"_",C42,$B$3,"_",C42,$B$3,"_",G42),D42="SECC",CONCATENATE(B42,"_",C42,$B$3,"_",$B$5,"_",G42),D42="SECF",CONCATENATE(B42,"_",C42,$B$3,"_",$B$6,"_",G42),D42="SECT",CONCATENATE(B42,"_",C42,$B$3,"_",$B$7,"_",G42),D42="SECG",CONCATENATE(B42,"_",C42,$B$3,"_",$B$8,"_",G42),D42="DJ",CONCATENATE(B42,"_",C42,$B$3,"_",$B$4,"_",G42),D42="DJ_P",CONCATENATE(B42,"_",C42,$B$3,"_",$B$4,"_P","_",G42),D42="DJ_A",CONCATENATE(B42,"_",C42,$B$3,"_",$B$4,"_A","_",G42),D42="LT_P",CONCATENATE(B42,"_",C42,$B$3,"_",C42,$B$3,"_P","_",G42),D42="LT_A",CONCATENATE(B42,"_",C42,$B$3,"_",C42,$B$3,"_A","_",G42))} -> IMA_LT1_89-4_SECC | I42: Ponto Simples | J42: ABERTA | K42: FECHADA | L42: - | M42: -
A43: NÃO | B43: =Informações!$C$3 -> IMA | C43: LT | D43: SECC | E43: D | F43: =VLOOKUP(G43,[1]Discrete!$A:$B,2,FALSE) -> 43 - CHAVE LOCAL REMOTO | G43: 43LR | H43: {=_xlfn.IFS(OR(D43="TC",D43="TP",D43="LT"),CONCATENATE(B43,"_",C43,$B$3,"_",C43,$B$3,"_",G43),D43="SECC",CONCATENATE(B43,"_",C43,$B$3,"_",$B$5,"_",G43),D43="SECF",CONCATENATE(B43,"_",C43,$B$3,"_",$B$6,"_",G43),D43="SECT",CONCATENATE(B43,"_",C43,$B$3,"_",$B$7,"_",G43),D43="SECG",CONCATENATE(B43,"_",C43,$B$3,"_",$B$8,"_",G43),D43="DJ",CONCATENATE(B43,"_",C43,$B$3,"_",$B$4,"_",G43),D43="DJ_P",CONCATENATE(B43,"_",C43,$B$3,"_",$B$4,"_P","_",G43),D43="DJ_A",CONCATENATE(B43,"_",C43,$B$3,"_",$B$4,"_A","_",G43),D43="LT_P",CONCATENATE(B43,"_",C43,$B$3,"_",C43,$B$3,"_P","_",G43),D43="LT_A",CONCATENATE(B43,"_",C43,$B$3,"_",C43,$B$3,"_A","_",G43))} -> IMA_LT1_89-4_43LR | I43: Ponto Simples | J43: REMOTO | K43: LOCAL | L43: - | M43: -
...

Sheet LT 2 (FUTURO)
A1: MÓDULO - LINHA DE TRANSMISSÃO - LT 69KV (FUTURO) - 02F1/02F2
A2: EQUIPAMENTO | B2: NÚMERO OPERATIVO / MNEMNICO
A3: MÓDULO | B3: 2
A4: DJ | B4: 52-2
A5: SECC | B5: 89-10
A6: SECF | B6: 89-8
A7: SECT | B7: 89-12
A8: SECG | B8: 29-3
A10: Utilizado? | B10: SUBESTAÇÃO | C10: MÓDULO | D10: EQUIPAMENTO | E10: TIPO | F10: DESCRIÇÃO DO PONTO | G10: SIGLA SINAL | H10: NOME | I10: Tipo | J10: Nível Lógico 0 | K10: Nível Lógico 1 | L10: Escala | M10: Control Code / Qualificador | N10: INDEX DNP3
A11: NÃO | B11: =Informações!$C$3 -> IMA | C11: LT | D11: TC | E11: A | F11: =VLOOKUP(G11,[1]Analog!$A:$B,2,FALSE) -> CORRENTE FASE A | G11: IA | H11: {=_xlfn.IFS(OR(D11="TC",D11="TP",D11="LT"),CONCATENATE(B11,"_",C11,$B$3,"_",C11,$B$3,"_",G11),D11="SECC",CONCATENATE(B11,"_",C11,$B$3,"_",$B$5,"_",G11),D11="SECF",CONCATENATE(B11,"_",C11,$B$3,"_",$B$6,"_",G11),D11="SECT",CONCATENATE(B11,"_",C11,$B$3,"_",$B$7,"_",G11),D11="SECG",CONCATENATE(B11,"_",C11,$B$3,"_",$B$8,"_",G11),D11="DJ",CONCATENATE(B11,"_",C11,$B$3,"_",$B$4,"_",G11),D11="DJ_P",CONCATENATE(B11,"_",C11,$B$3,"_",$B$4,"_P","_",G11),D11="DJ_A",CONCATENATE(B11,"_",C11,$B$3,"_",$B$4,"_A","_",G11),D11="LT_P",CONCATENATE(B11,"_",C11,$B$3,"_",C11,$B$3,"_P","_",G11),D11="LT_A",CONCATENATE(B11,"_",C11,$B$3,"_",C11,$B$3,"_A","_",G11))} -> IMA_LT2_LT2_IA | I11: Ponto Simples | J11: - | K11: - | L11: 1 | M11: -
A12: NÃO | B12: =Informações!$C$3 -> IMA | C12: LT | D12: TC | E12: A | F12: =VLOOKUP(G12,[1]Analog!$A:$B,2,FALSE) -> CORRENTE FASE B | G12: IB | H12: {=_xlfn.IFS(OR(D12="TC",D12="TP",D12="LT"),CONCATENATE(B12,"_",C12,$B$3,"_",C12,$B$3,"_",G12),D12="SECC",CONCATENATE(B12,"_",C12,$B$3,"_",$B$5,"_",G12),D12="SECF",CONCATENATE(B12,"_",C12,$B$3,"_",$B$6,"_",G12),D12="SECT",CONCATENATE(B12,"_",C12,$B$3,"_",$B$7,"_",G12),D12="SECG",CONCATENATE(B12,"_",C12,$B$3,"_",$B$8,"_",G12),D12="DJ",CONCATENATE(B12,"_",C12,$B$3,"_",$B$4,"_",G12),D12="DJ_P",CONCATENATE(B12,"_",C12,$B$3,"_",$B$4,"_P","_",G12),D12="DJ_A",CONCATENATE(B12,"_",C12,$B$3,"_",$B$4,"_A","_",G12),D12="LT_P",CONCATENATE(B12,"_",C12,$B$3,"_",C12,$B$3,"_P","_",G12),D12="LT_A",CONCATENATE(B12,"_",C12,$B$3,"_",C12,$B$3,"_A","_",G12))} -> IMA_LT2_LT2_IB | I12: Ponto Simples | J12: - | K12: - | L12: 1 | M12: -
A13: NÃO | B13: =Informações!$C$3 -> IMA | C13: LT | D13: TC | E13: A | F13: =VLOOKUP(G13,[1]Analog!$A:$B,2,FALSE) -> CORRENTE FASE C | G13: IC | H13: {=_xlfn.IFS(OR(D13="TC",D13="TP",D13="LT"),CONCATENATE(B13,"_",C13,$B$3,"_",C13,$B$3,"_",G13),D13="SECC",CONCATENATE(B13,"_",C13,$B$3,"_",$B$5,"_",G13),D13="SECF",CONCATENATE(B13,"_",C13,$B$3,"_",$B$6,"_",G13),D13="SECT",CONCATENATE(B13,"_",C13,$B$3,"_",$B$7,"_",G13),D13="SECG",CONCATENATE(B13,"_",C13,$B$3,"_",$B$8,"_",G13),D13="DJ",CONCATENATE(B13,"_",C13,$B$3,"_",$B$4,"_",G13),D13="DJ_P",CONCATENATE(B13,"_",C13,$B$3,"_",$B$4,"_P","_",G13),D13="DJ_A",CONCATENATE(B13,"_",C13,$B$3,"_",$B$4,"_A","_",G13),D13="LT_P",CONCATENATE(B13,"_",C13,$B$3,"_",C13,$B$3,"_P","_",G13),D13="LT_A",CONCATENATE(B13,"_",C13,$B$3,"_",C13,$B$3,"_A","_",G13))} -> IMA_LT2_LT2_IC | I13: Ponto Simples | J13: - | K13: - | L13: 1 | M13: -
A14: NÃO | B14: =Informações!$C$3 -> IMA | C14: LT | D14: TP | E14: A | F14: =VLOOKUP(G14,[1]Analog!$A:$B,2,FALSE) -> TENSAO BARRA FASE A | G14: VA_B | H14: {=_xlfn.IFS(OR(D14="TC",D14="TP",D14="LT"),CONCATENATE(B14,"_",C14,$B$3,"_",C14,$B$3,"_",G14),D14="SECC",CONCATENATE(B14,"_",C14,$B$3,"_",$B$5,"_",G14),D14="SECF",CONCATENATE(B14,"_",C14,$B$3,"_",$B$6,"_",G14),D14="SECT",CONCATENATE(B14,"_",C14,$B$3,"_",$B$7,"_",G14),D14="SECG",CONCATENATE(B14,"_",C14,$B$3,"_",$B$8,"_",G14),D14="DJ",CONCATENATE(B14,"_",C14,$B$3,"_",$B$4,"_",G14),D14="DJ_P",CONCATENATE(B14,"_",C14,$B$3,"_",$B$4,"_P","_",G14),D14="DJ_A",CONCATENATE(B14,"_",C14,$B$3,"_",$B$4,"_A","_",G14),D14="LT_P",CONCATENATE(B14,"_",C14,$B$3,"_",C14,$B$3,"_P","_",G14),D14="LT_A",CONCATENATE(B14,"_",C14,$B$3,"_",C14,$B$3,"_A","_",G14))} -> IMA_LT2_LT2_VA_B | I14: Ponto Simples | J14: - | K14: - | L14: 0.01 | M14: -
A15: NÃO | B15: =Informações!$C$3 -> IMA | C15: LT | D15: TP | E15: A | F15: =VLOOKUP(G15,[1]Analog!$A:$B,2,FALSE) -> TENSAO BARRA FASE B | G15: VB_B | H15: {=_xlfn.IFS(OR(D15="TC",D15="TP",D15="LT"),CONCATENATE(B15,"_",C15,$B$3,"_",C15,$B$3,"_",G15),D15="SECC",CONCATENATE(B15,"_",C15,$B$3,"_",$B$5,"_",G15),D15="SECF",CONCATENATE(B15,"_",C15,$B$3,"_",$B$6,"_",G15),D15="SECT",CONCATENATE(B15,"_",C15,$B$3,"_",$B$7,"_",G15),D15="SECG",CONCATENATE(B15,"_",C15,$B$3,"_",$B$8,"_",G15),D15="DJ",CONCATENATE(B15,"_",C15,$B$3,"_",$B$4,"_",G15),D15="DJ_P",CONCATENATE(B15,"_",C15,$B$3,"_",$B$4,"_P","_",G15),D15="DJ_A",CONCATENATE(B15,"_",C15,$B$3,"_",$B$4,"_A","_",G15),D15="LT_P",CONCATENATE(B15,"_",C15,$B$3,"_",C15,$B$3,"_P","_",G15),D15="LT_A",CONCATENATE(B15,"_",C15,$B$3,"_",C15,$B$3,"_A","_",G15))} -> IMA_LT2_LT2_VB_B | I15: Ponto Simples | J15: - | K15: - | L15: 0.01 | M15: -
A16: NÃO | B16: =Informações!$C$3 -> IMA | C16: LT | D16: TP | E16: A | F16: =VLOOKUP(G16,[1]Analog!$A:$B,2,FALSE) -> TENSAO BARRA FASE C | G16: VC_B | H16: {=_xlfn.IFS(OR(D16="TC",D16="TP",D16="LT"),CONCATENATE(B16,"_",C16,$B$3,"_",C16,$B$3,"_",G16),D16="SECC",CONCATENATE(B16,"_",C16,$B$3,"_",$B$5,"_",G16),D16="SECF",CONCATENATE(B16,"_",C16,$B$3,"_",$B$6,"_",G16),D16="SECT",CONCATENATE(B16,"_",C16,$B$3,"_",$B$7,"_",G16),D16="SECG",CONCATENATE(B16,"_",C16,$B$3,"_",$B$8,"_",G16),D16="DJ",CONCATENATE(B16,"_",C16,$B$3,"_",$B$4,"_",G16),D16="DJ_P",CONCATENATE(B16,"_",C16,$B$3,"_",$B$4,"_P","_",G16),D16="DJ_A",CONCATENATE(B16,"_",C16,$B$3,"_",$B$4,"_A","_",G16),D16="LT_P",CONCATENATE(B16,"_",C16,$B$3,"_",C16,$B$3,"_P","_",G16),D16="LT_A",CONCATENATE(B16,"_",C16,$B$3,"_",C16,$B$3,"_A","_",G16))} -> IMA_LT2_LT2_VC_B | I16: Ponto Simples | J16: - | K16: - | L16: 0.01 | M16: -
A17: NÃO | B17: =Informações!$C$3 -> IMA | C17: LT | D17: TP | E17: A | F17: =VLOOKUP(G17,[1]Analog!$A:$B,2,FALSE) -> TENSAO LINHA FASE A | G17: VA_L | H17: {=_xlfn.IFS(OR(D17="TC",D17="TP",D17="LT"),CONCATENATE(B17,"_",C17,$B$3,"_",C17,$B$3,"_",G17),D17="SECC",CONCATENATE(B17,"_",C17,$B$3,"_",$B$5,"_",G17),D17="SECF",CONCATENATE(B17,"_",C17,$B$3,"_",$B$6,"_",G17),D17="SECT",CONCATENATE(B17,"_",C17,$B$3,"_",$B$7,"_",G17),D17="SECG",CONCATENATE(B17,"_",C17,$B$3,"_",$B$8,"_",G17),D17="DJ",CONCATENATE(B17,"_",C17,$B$3,"_",$B$4,"_",G17),D17="DJ_P",CONCATENATE(B17,"_",C17,$B$3,"_",$B$4,"_P","_",G17),D17="DJ_A",CONCATENATE(B17,"_",C17,$B$3,"_",$B$4,"_A","_",G17),D17="LT_P",CONCATENATE(B17,"_",C17,$B$3,"_",C17,$B$3,"_P","_",G17),D17="LT_A",CONCATENATE(B17,"_",C17,$B$3,"_",C17,$B$3,"_A","_",G17))} -> IMA_LT2_LT2_VA_L | I17: Ponto Simples | J17: - | K17: - | L17: 0.01 | M17: -
A18: NÃO | B18: =Informações!$C$3 -> IMA | C18: LT | D18: TP | E18: A | F18: =VLOOKUP(G18,[1]Analog!$A:$B,2,FALSE) -> TENSAO LINHA FASE B | G18: VB_L | H18: {=_xlfn.IFS(OR(D18="TC",D18="TP",D18="LT"),CONCATENATE(B18,"_",C18,$B$3,"_",C18,$B$3,"_",G18),D18="SECC",CONCATENATE(B18,"_",C18,$B$3,"_",$B$5,"_",G18),D18="SECF",CONCATENATE(B18,"_",C18,$B$3,"_",$B$6,"_",G18),D18="SECT",CONCATENATE(B18,"_",C18,$B$3,"_",$B$7,"_",G18),D18="SECG",CONCATENATE(B18,"_",C18,$B$3,"_",$B$8,"_",G18),D18="DJ",CONCATENATE(B18,"_",C18,$B$3,"_",$B$4,"_",G18),D18="DJ_P",CONCATENATE(B18,"_",C18,$B$3,"_",$B$4,"_P","_",G18),D18="DJ_A",CONCATENATE(B18,"_",C18,$B$3,"_",$B$4,"_A","_",G18),D18="LT_P",CONCATENATE(B18,"_",C18,$B$3,"_",C18,$B$3,"_P","_",G18),D18="LT_A",CONCATENATE(B18,"_",C18,$B$3,"_",C18,$B$3,"_A","_",G18))} -> IMA_LT2_LT2_VB_L | I18: Ponto Simples | J18: - | K18: - | L18: 0.01 | M18: -
A19: NÃO | B19: =Informações!$C$3 -> IMA | C19: LT | D19: TP | E19: A | F19: =VLOOKUP(G19,[1]Analog!$A:$B,2,FALSE) -> TENSAO LINHA FASE C | G19: VC_L | H19: {=_xlfn.IFS(OR(D19="TC",D19="TP",D19="LT"),CONCATENATE(B19,"_",C19,$B$3,"_",C19,$B$3,"_",G19),D19="SECC",CONCATENATE(B19,"_",C19,$B$3,"_",$B$5,"_",G19),D19="SECF",CONCATENATE(B19,"_",C19,$B$3,"_",$B$6,"_",G19),D19="SECT",CONCATENATE(B19,"_",C19,$B$3,"_",$B$7,"_",G19),D19="SECG",CONCATENATE(B19,"_",C19,$B$3,"_",$B$8,"_",G19),D19="DJ",CONCATENATE(B19,"_",C19,$B$3,"_",$B$4,"_",G19),D19="DJ_P",CONCATENATE(B19,"_",C19,$B$3,"_",$B$4,"_P","_",G19),D19="DJ_A",CONCATENATE(B19,"_",C19,$B$3,"_",$B$4,"_A","_",G19),D19="LT_P",CONCATENATE(B19,"_",C19,$B$3,"_",C19,$B$3,"_P","_",G19),D19="LT_A",CONCATENATE(B19,"_",C19,$B$3,"_",C19,$B$3,"_A","_",G19))} -> IMA_LT2_LT2_VC_L | I19: Ponto Simples | J19: - | K19: - | L19: 0.01 | M19: -
A20: NÃO | B20: =Informações!$C$3 -> IMA | C20: LT | D20: TC | E20: A | F20: =VLOOKUP(G20,[1]Analog!$A:$B,2,FALSE) -> POTENCIA ATIVA | G20: P | H20: {=_xlfn.IFS(OR(D20="TC",D20="TP",D20="LT"),CONCATENATE(B20,"_",C20,$B$3,"_",C20,$B$3,"_",G20),D20="SECC",CONCATENATE(B20,"_",C20,$B$3,"_",$B$5,"_",G20),D20="SECF",CONCATENATE(B20,"_",C20,$B$3,"_",$B$6,"_",G20),D20="SECT",CONCATENATE(B20,"_",C20,$B$3,"_",$B$7,"_",G20),D20="SECG",CONCATENATE(B20,"_",C20,$B$3,"_",$B$8,"_",G20),D20="DJ",CONCATENATE(B20,"_",C20,$B$3,"_",$B$4,"_",G20),D20="DJ_P",CONCATENATE(B20,"_",C20,$B$3,"_",$B$4,"_P","_",G20),D20="DJ_A",CONCATENATE(B20,"_",C20,$B$3,"_",$B$4,"_A","_",G20),D20="LT_P",CONCATENATE(B20,"_",C20,$B$3,"_",C20,$B$3,"_P","_",G20),D20="LT_A",CONCATENATE(B20,"_",C20,$B$3,"_",C20,$B$3,"_A","_",G20))} -> IMA_LT2_LT2_P | I20: Ponto Simples | J20: - | K20: - | L20: 10 | M20: -
A21: NÃO | B21: =Informações!$C$3 -> IMA | C21: LT | D21: TC | E21: A | F21: =VLOOKUP(G21,[1]Analog!$A:$B,2,FALSE) -> POTENCIA REATIVA | G21: Q | H21: {=_xlfn.IFS(OR(D21="TC",D21="TP",D21="LT"),CONCATENATE(B21,"_",C21,$B$3,"_",C21,$B$3,"_",G21),D21="SECC",CONCATENATE(B21,"_",C21,$B$3,"_",$B$5,"_",G21),D21="SECF",CONCATENATE(B21,"_",C21,$B$3,"_",$B$6,"_",G21),D21="SECT",CONCATENATE(B21,"_",C21,$B$3,"_",$B$7,"_",G21),D21="SECG",CONCATENATE(B21,"_",C21,$B$3,"_",$B$8,"_",G21),D21="DJ",CONCATENATE(B21,"_",C21,$B$3,"_",$B$4,"_",G21),D21="DJ_P",CONCATENATE(B21,"_",C21,$B$3,"_",$B$4,"_P","_",G21),D21="DJ_A",CONCATENATE(B21,"_",C21,$B$3,"_",$B$4,"_A","_",G21),D21="LT_P",CONCATENATE(B21,"_",C21,$B$3,"_",C21,$B$3,"_P","_",G21),D21="LT_A",CONCATENATE(B21,"_",C21,$B$3,"_",C21,$B$3,"_A","_",G21))} -> IMA_LT2_LT2_Q | I21: Ponto Simples | J21: - | K21: - | L21: 10 | M21: -
A22: NÃO | B22: =Informações!$C$3 -> IMA | C22: LT | D22: LT | E22: A | F22: =VLOOKUP(G22,[1]Analog!$A:$B,2,FALSE) -> DISTANCIA DEFEITO | G22: KMDF | H22: {=_xlfn.IFS(OR(D22="TC",D22="TP",D22="LT"),CONCATENATE(B22,"_",C22,$B$3,"_",C22,$B$3,"_",G22),D22="SECC",CONCATENATE(B22,"_",C22,$B$3,"_",$B$5,"_",G22),D22="SECF",CONCATENATE(B22,"_",C22,$B$3,"_",$B$6,"_",G22),D22="SECT",CONCATENATE(B22,"_",C22,$B$3,"_",$B$7,"_",G22),D22="SECG",CONCATENATE(B22,"_",C22,$B$3,"_",$B$8,"_",G22),D22="DJ",CONCATENATE(B22,"_",C22,$B$3,"_",$B$4,"_",G22),D22="DJ_P",CONCATENATE(B22,"_",C22,$B$3,"_",$B$4,"_P","_",G22),D22="DJ_A",CONCATENATE(B22,"_",C22,$B$3,"_",$B$4,"_A","_",G22),D22="LT_P",CONCATENATE(B22,"_",C22,$B$3,"_",C22,$B$3,"_P","_",G22),D22="LT_A",CONCATENATE(B22,"_",C22,$B$3,"_",C22,$B$3,"_A","_",G22))} -> IMA_LT2_LT2_KMDF | I22: Ponto Simples | J22: - | K22: - | L22: 0.01 | M22: -
... A25: NÃO | B25: =Informações!$C$3 -> IMA | C25: LT | D25: TC | E25: A | F25: =VLOOKUP(G25,[1]Analog!$A:$B,2,FALSE) -> CORRENTE CURTO CIRCUITO FASE C | G25: ICCC | H25: {=_xlfn.IFS(OR(D25="TC",D25="TP",D25="LT"),CONCATENATE(B25,"_",C25,$B$3,"_",C25,$B$3,"_",G25),D25="SECC",CONCATENATE(B25,"_",C25,$B$3,"_",$B$5,"_",G25),D25="SECF",CONCATENATE(B25,"_",C25,$B$3,"_",$B$6,"_",G25),D25="SECT",CONCATENATE(B25,"_",C25,$B$3,"_",$B$7,"_",G25),D25="SECG",CONCATENATE(B25,"_",C25,$B$3,"_",$B$8,"_",G25),D25="DJ",CONCATENATE(B25,"_",C25,$B$3,"_",$B$4,"_",G25),D25="DJ_P",CONCATENATE(B25,"_",C25,$B$3,"_",$B$4,"_P","_",G25),D25="DJ_A",CONCATENATE(B25,"_",C25,$B$3,"_",$B$4,"_A","_",G25),D25="LT_P",CONCATENATE(B25,"_",C25,$B$3,"_",C25,$B$3,"_P","_",G25),D25="LT_A",CONCATENATE(B25,"_",C25,$B$3,"_",C25,$B$3,"_A","_",G25))} -> IMA_LT2_LT2_ICCC | I25: Ponto Simples | J25: - | K25: - | L25: 1 | M25: -
A26: NÃO | B26: =Informações!$C$3 -> IMA | C26: LT | D26: SECC | E26: C | F26: =VLOOKUP(G26,[1]Discrete!$A:$B,2,FALSE) -> SECCIONADORA CARGA | G26: SECC | H26: {=_xlfn.IFS(OR(D26="TC",D26="TP",D26="LT"),CONCATENATE(B26,"_",C26,$B$3,"_",C26,$B$3,"_",G26),D26="SECC",CONCATENATE(B26,"_",C26,$B$3,"_",$B$5,"_",G26),D26="SECF",CONCATENATE(B26,"_",C26,$B$3,"_",$B$6,"_",G26),D26="SECT",CONCATENATE(B26,"_",C26,$B$3,"_",$B$7,"_",G26),D26="SECG",CONCATENATE(B26,"_",C26,$B$3,"_",$B$8,"_",G26),D26="DJ",CONCATENATE(B26,"_",C26,$B$3,"_",$B$4,"_",G26),D26="DJ_P",CONCATENATE(B26,"_",C26,$B$3,"_",$B$4,"_P","_",G26),D26="DJ_A",CONCATENATE(B26,"_",C26,$B$3,"_",$B$4,"_A","_",G26),D26="LT_P",CONCATENATE(B26,"_",C26,$B$3,"_",C26,$B$3,"_P","_",G26),D26="LT_A",CONCATENATE(B26,"_",C26,$B$3,"_",C26,$B$3,"_A","_",G26))} -> IMA_LT2_89-10_SECC | I26: - | J26: - | K26: - | L26: - | M26: 0 - Trip/Pulse-On // 1 - Close/Pulse-On
A27: NÃO | B27: =Informações!$C$3 -> IMA | C27: LT | D27: SECF | E27: C | F27: =VLOOKUP(G27,[1]Discrete!$A:$B,2,FALSE) -> SECCIONADORA FONTE | G27: SECF | H27: {=_xlfn.IFS(OR(D27="TC",D27="TP",D27="LT"),CONCATENATE(B27,"_",C27,$B$3,"_",C27,$B$3,"_",G27),D27="SECC",CONCATENATE(B27,"_",C27,$B$3,"_",$B$5,"_",G27),D27="SECF",CONCATENATE(B27,"_",C27,$B$3,"_",$B$6,"_",G27),D27="SECT",CONCATENATE(B27,"_",C27,$B$3,"_",$B$7,"_",G27),D27="SECG",CONCATENATE(B27,"_",C27,$B$3,"_",$B$8,"_",G27),D27="DJ",CONCATENATE(B27,"_",C27,$B$3,"_",$B$4,"_",G27),D27="DJ_P",CONCATENATE(B27,"_",C27,$B$3,"_",$B$4,"_P","_",G27),D27="DJ_A",CONCATENATE(B27,"_",C27,$B$3,"_",$B$4,"_A","_",G27),D27="LT_P",CONCATENATE(B27,"_",C27,$B$3,"_",C27,$B$3,"_P","_",G27),D27="LT_A",CONCATENATE(B27,"_",C27,$B$3,"_",C27,$B$3,"_A","_",G27))} -> IMA_LT2_89-8_SECF | I27: - | J27: - | K27: - | L27: - | M27: 0 - Trip/Pulse-On // 1 - Close/Pulse-On
A28: NÃO | B28: =Informações!$C$3 -> IMA | C28: LT | D28: SECT | E28: C | F28: =VLOOKUP(G28,[1]Discrete!$A:$B,2,FALSE) -> SECCIONADORA TRANSFERENCIA | G28: SECT | H28: {=_xlfn.IFS(OR(D28="TC",D28="TP",D28="LT"),CONCATENATE(B28,"_",C28,$B$3,"_",C28,$B$3,"_",G28),D28="SECC",CONCATENATE(B28,"_",C28,$B$3,"_",$B$5,"_",G28),D28="SECF",CONCATENATE(B28,"_",C28,$B$3,"_",$B$6,"_",G28),D28="SECT",CONCATENATE(B28,"_",C28,$B$3,"_",$B$7,"_",G28),D28="SECG",CONCATENATE(B28,"_",C28,$B$3,"_",$B$8,"_",G28),D28="DJ",CONCATENATE(B28,"_",C28,$B$3,"_",$B$4,"_",G28),D28="DJ_P",CONCATENATE(B28,"_",C28,$B$3,"_",$B$4,"_P","_",G28),D28="DJ_A",CONCATENATE(B28,"_",C28,$B$3,"_",$B$4,"_A","_",G28),D28="LT_P",CONCATENATE(B28,"_",C28,$B$3,"_",C28,$B$3,"_P","_",G28),D28="LT_A",CONCATENATE(B28,"_",C28,$B$3,"_",C28,$B$3,"_A","_",G28))} -> IMA_LT2_89-12_SECT | I28: - | J28: - | K28: - | L28: - | M28: 0 - Trip/Pulse-On // 1 - Close/Pulse-On
A29: NÃO | B29: =Informações!$C$3 -> IMA | C29: LT | D29: DJ | E29: C | F29: =VLOOKUP(G29,[1]Discrete!$A:$B,2,FALSE) -> DISJUNTOR NF | G29: DJF1 | H29: {=_xlfn.IFS(OR(D29="TC",D29="TP",D29="LT"),CONCATENATE(B29,"_",C29,$B$3,"_",C29,$B$3,"_",G29),D29="SECC",CONCATENATE(B29,"_",C29,$B$3,"_",$B$5,"_",G29),D29="SECF",CONCATENATE(B29,"_",C29,$B$3,"_",$B$6,"_",G29),D29="SECT",CONCATENATE(B29,"_",C29,$B$3,"_",$B$7,"_",G29),D29="SECG",CONCATENATE(B29,"_",C29,$B$3,"_",$B$8,"_",G29),D29="DJ",CONCATENATE(B29,"_",C29,$B$3,"_",$B$4,"_",G29),D29="DJ_P",CONCATENATE(B29,"_",C29,$B$3,"_",$B$4,"_P","_",G29),D29="DJ_A",CONCATENATE(B29,"_",C29,$B$3,"_",$B$4,"_A","_",G29),D29="LT_P",CONCATENATE(B29,"_",C29,$B$3,"_",C29,$B$3,"_P","_",G29),D29="LT_A",CONCATENATE(B29,"_",C29,$B$3,"_",C29,$B$3,"_A","_",G29))} -> IMA_LT2_52-2_DJF1 | I29: - | J29: - | K29: - | L29: - | M29: 0 - Trip/Pulse-On // 1 - Close/Pulse-On
A30: NÃO | B30: =Informações!$C$3 -> IMA | C30: LT | D30: DJ | E30: C | F30: =VLOOKUP(G30,[1]Discrete!$A:$B,2,FALSE) -> #N/A | G30: 79 | H30: {=_xlfn.IFS(OR(D30="TC",D30="TP",D30="LT"),CONCATENATE(B30,"_",C30,$B$3,"_",C30,$B$3,"_",G30),D30="SECC",CONCATENATE(B30,"_",C30,$B$3,"_",$B$5,"_",G30),D30="SECF",CONCATENATE(B30,"_",C30,$B$3,"_",$B$6,"_",G30),D30="SECT",CONCATENATE(B30,"_",C30,$B$3,"_",$B$7,"_",G30),D30="SECG",CONCATENATE(B30,"_",C30,$B$3,"_",$B$8,"_",G30),D30="DJ",CONCATENATE(B30,"_",C30,$B$3,"_",$B$4,"_",G30),D30="DJ_P",CONCATENATE(B30,"_",C30,$B$3,"_",$B$4,"_P","_",G30),D30="DJ_A",CONCATENATE(B30,"_",C30,$B$3,"_",$B$4,"_A","_",G30),D30="LT_P",CONCATENATE(B30,"_",C30,$B$3,"_",C30,$B$3,"_P","_",G30),D30="LT_A",CONCATENATE(B30,"_",C30,$B$3,"_",C30,$B$3,"_A","_",G30))} -> IMA_LT2_52-2_79 | I30: - | J30: - | K30: - | L30: - | M30: 0 - Close/Pulse-On // 1 - Trip/Pulse-On
A31: NÃO | B31: =Informações!$C$3 -> IMA | C31: LT | D31: DJ | E31: C | F31: =VLOOKUP(G31,[1]Discrete!$A:$B,2,FALSE) -> 51 - FUNCAO SOBRECORRENTE TEMPORIZADA NEUTRO | G31: 51N | H31: {=_xlfn.IFS(OR(D31="TC",D31="TP",D31="LT"),CONCATENATE(B31,"_",C31,$B$3,"_",C31,$B$3,"_",G31),D31="SECC",CONCATENATE(B31,"_",C31,$B$3,"_",$B$5,"_",G31),D31="SECF",CONCATENATE(B31,"_",C31,$B$3,"_",$B$6,"_",G31),D31="SECT",CONCATENATE(B31,"_",C31,$B$3,"_",$B$7,"_",G31),D31="SECG",CONCATENATE(B31,"_",C31,$B$3,"_",$B$8,"_",G31),D31="DJ",CONCATENATE(B31,"_",C31,$B$3,"_",$B$4,"_",G31),D31="DJ_P",CONCATENATE(B31,"_",C31,$B$3,"_",$B$4,"_P","_",G31),D31="DJ_A",CONCATENATE(B31,"_",C31,$B$3,"_",$B$4,"_A","_",G31),D31="LT_P",CONCATENATE(B31,"_",C31,$B$3,"_",C31,$B$3,"_P","_",G31),D31="LT_A",CONCATENATE(B31,"_",C31,$B$3,"_",C31,$B$3,"_A","_",G31))} -> IMA_LT2_52-2_51N | I31: - | J31: - | K31: - | L31: - | M31: 0 - Close/Pulse-On // 1 - Trip/Pulse-On
A32: NÃO | B32: =Informações!$C$3 -> IMA | C32: LT | D32: DJ | E32: C | F32: =VLOOKUP(G32,[1]Discrete!$A:$B,2,FALSE) -> #N/A | G32: 81 | H32: {=_xlfn.IFS(OR(D32="TC",D32="TP",D32="LT"),CONCATENATE(B32,"_",C32,$B$3,"_",C32,$B$3,"_",G32),D32="SECC",CONCATENATE(B32,"_",C32,$B$3,"_",$B$5,"_",G32),D32="SECF",CONCATENATE(B32,"_",C32,$B$3,"_",$B$6,"_",G32),D32="SECT",CONCATENATE(B32,"_",C32,$B$3,"_",$B$7,"_",G32),D32="SECG",CONCATENATE(B32,"_",C32,$B$3,"_",$B$8,"_",G32),D32="DJ",CONCATENATE(B32,"_",C32,$B$3,"_",$B$4,"_",G32),D32="DJ_P",CONCATENATE(B32,"_",C32,$B$3,"_",$B$4,"_P","_",G32),D32="DJ_A",CONCATENATE(B32,"_",C32,$B$3,"_",$B$4,"_A","_",G32),D32="LT_P",CONCATENATE(B32,"_",C32,$B$3,"_",C32,$B$3,"_P","_",G32),D32="LT_A",CONCATENATE(B32,"_",C32,$B$3,"_",C32,$B$3,"_A","_",G32))} -> IMA_LT2_52-2_81 | I32: - | J32: - | K32: - | L32: - | M32: 0 - Close/Pulse-On // 1 - Trip/Pulse-On
A33: NÃO | B33: =Informações!$C$3 -> IMA | C33: LT | D33: DJ | E33: C | F33: =VLOOKUP(G33,[1]Discrete!$A:$B,2,FALSE) -> GRUPO DE AJUSTE FUNCAO 81 | G33: 81AJST | H33: {=_xlfn.IFS(OR(D33="TC",D33="TP",D33="LT"),CONCATENATE(B33,"_",C33,$B$3,"_",C33,$B$3,"_",G33),D33="SECC",CONCATENATE(B33,"_",C33,$B$3,"_",$B$5,"_",G33),D33="SECF",CONCATENATE(B33,"_",C33,$B$3,"_",$B$6,"_",G33),D33="SECT",CONCATENATE(B33,"_",C33,$B$3,"_",$B$7,"_",G33),D33="SECG",CONCATENATE(B33,"_",C33,$B$3,"_",$B$8,"_",G33),D33="DJ",CONCATENATE(B33,"_",C33,$B$3,"_",$B$4,"_",G33),D33="DJ_P",CONCATENATE(B33,"_",C33,$B$3,"_",$B$4,"_P","_",G33),D33="DJ_A",CONCATENATE(B33,"_",C33,$B$3,"_",$B$4,"_A","_",G33),D33="LT_P",CONCATENATE(B33,"_",C33,$B$3,"_",C33,$B$3,"_P","_",G33),D33="LT_A",CONCATENATE(B33,"_",C33,$B$3,"_",C33,$B$3,"_A","_",G33))} -> IMA_LT2_52-2_81AJST | I33: - | J33: - | K33: - | L33: - | M33: 0 - Close/Pulse-On // 1 - Trip/Pulse-On
A34: NÃO | B34: =Informações!$C$3 -> IMA | C34: LT | D34: DJ | E34: C | F34: =VLOOKUP(G34,[1]Discrete!$A:$B,2,FALSE) -> 25 - FUNCAO SINCRONISMO | G34: 25IE | H34: {=_xlfn.IFS(OR(D34="TC",D34="TP",D34="LT"),CONCATENATE(B34,"_",C34,$B$3,"_",C34,$B$3,"_",G34),D34="SECC",CONCATENATE(B34,"_",C34,$B$3,"_",$B$5,"_",G34),D34="SECF",CONCATENATE(B34,"_",C34,$B$3,"_",$B$6,"_",G34),D34="SECT",CONCATENATE(B34,"_",C34,$B$3,"_",$B$7,"_",G34),D34="SECG",CONCATENATE(B34,"_",C34,$B$3,"_",$B$8,"_",G34),D34="DJ",CONCATENATE(B34,"_",C34,$B$3,"_",$B$4,"_",G34),D34="DJ_P",CONCATENATE(B34,"_",C34,$B$3,"_",$B$4,"_P","_",G34),D34="DJ_A",CONCATENATE(B34,"_",C34,$B$3,"_",$B$4,"_A","_",G34),D34="LT_P",CONCATENATE(B34,"_",C34,$B$3,"_",C34,$B$3,"_P","_",G34),D34="LT_A",CONCATENATE(B34,"_",C34,$B$3,"_",C34,$B$3,"_A","_",G34))} -> IMA_LT2_52-2_25IE | I34: - | J34: - | K34: - | L34: - | M34: 0 - Close/Pulse-On // 1 - Trip/Pulse-On
A35: NÃO | B35: =Informações!$C$3 -> IMA | C35: LT | D35: DJ | E35: C | F35: =VLOOKUP(G35,[1]Discrete!$A:$B,2,FALSE) -> #N/A | G35: 27 | H35: {=_xlfn.IFS(OR(D35="TC",D35="TP",D35="LT"),CONCATENATE(B35,"_",C35,$B$3,"_",C35,$B$3,"_",G35),D35="SECC",CONCATENATE(B35,"_",C35,$B$3,"_",$B$5,"_",G35),D35="SECF",CONCATENATE(B35,"_",C35,$B$3,"_",$B$6,"_",G35),D35="SECT",CONCATENATE(B35,"_",C35,$B$3,"_",$B$7,"_",G35),D35="SECG",CONCATENATE(B35,"_",C35,$B$3,"_",$B$8,"_",G35),D35="DJ",CONCATENATE(B35,"_",C35,$B$3,"_",$B$4,"_",G35),D35="DJ_P",CONCATENATE(B35,"_",C35,$B$3,"_",$B$4,"_P","_",G35),D35="DJ_A",CONCATENATE(B35,"_",C35,$B$3,"_",$B$4,"_A","_",G35),D35="LT_P",CONCATENATE(B35,"_",C35,$B$3,"_",C35,$B$3,"_P","_",G35),D35="LT_A",CONCATENATE(B35,"_",C35,$B$3,"_",C35,$B$3,"_A","_",G35))} -> IMA_LT2_52-2_27 | I35: - | J35: - | K35: - | L35: - | M35: 0 - Close/Pulse-On // 1 - Trip/Pulse-On
A36: NÃO | B36: =Informações!$C$3 -> IMA | C36: LT | D36: DJ | E36: C | F36: =VLOOKUP(G36,[1]Discrete!$A:$B,2,FALSE) -> #N/A | G36: 59 | H36: {=_xlfn.IFS(OR(D36="TC",D36="TP",D36="LT"),CONCATENATE(B36,"_",C36,$B$3,"_",C36,$B$3,"_",G36),D36="SECC",CONCATENATE(B36,"_",C36,$B$3,"_",$B$5,"_",G36),D36="SECF",CONCATENATE(B36,"_",C36,$B$3,"_",$B$6,"_",G36),D36="SECT",CONCATENATE(B36,"_",C36,$B$3,"_",$B$7,"_",G36),D36="SECG",CONCATENATE(B36,"_",C36,$B$3,"_",$B$8,"_",G36),D36="DJ",CONCATENATE(B36,"_",C36,$B$3,"_",$B$4,"_",G36),D36="DJ_P",CONCATENATE(B36,"_",C36,$B$3,"_",$B$4,"_P","_",G36),D36="DJ_A",CONCATENATE(B36,"_",C36,$B$3,"_",$B$4,"_A","_",G36),D36="LT_P",CONCATENATE(B36,"_",C36,$B$3,"_",C36,$B$3,"_P","_",G36),D36="LT_A",CONCATENATE(B36,"_",C36,$B$3,"_",C36,$B$3,"_A","_",G36))} -> IMA_LT2_52-2_59 | I36: - | J36: - | K36: - | L36: - | M36: 0 - Close/Pulse-On // 1 - Trip/Pulse-On
A37: NÃO | B37: =Informações!$C$3 -> IMA | C37: LT | D37: DJ | E37: C | F37: =VLOOKUP(G37,[1]Discrete!$A:$B,2,FALSE) -> AJUSTE PARA 81 E1 | G37: 81U1 | H37: {=_xlfn.IFS(OR(D37="TC",D37="TP",D37="LT"),CONCATENATE(B37,"_",C37,$B$3,"_",C37,$B$3,"_",G37),D37="SECC",CONCATENATE(B37,"_",C37,$B$3,"_",$B$5,"_",G37),D37="SECF",CONCATENATE(B37,"_",C37,$B$3,"_",$B$6,"_",G37),D37="SECT",CONCATENATE(B37,"_",C37,$B$3,"_",$B$7,"_",G37),D37="SECG",CONCATENATE(B37,"_",C37,$B$3,"_",$B$8,"_",G37),D37="DJ",CONCATENATE(B37,"_",C37,$B$3,"_",$B$4,"_",G37),D37="DJ_P",CONCATENATE(B37,"_",C37,$B$3,"_",$B$4,"_P","_",G37),D37="DJ_A",CONCATENATE(B37,"_",C37,$B$3,"_",$B$4,"_A","_",G37),D37="LT_P",CONCATENATE(B37,"_",C37,$B$3,"_",C37,$B$3,"_P","_",G37),D37="LT_A",CONCATENATE(B37,"_",C37,$B$3,"_",C37,$B$3,"_A","_",G37))} -> IMA_LT2_52-2_81U1 | I37: - | J37: - | K37: - | L37: - | M37: 0 - Close/Pulse-On // 1 - Trip/Pulse-On
A38: NÃO | B38: =Informações!$C$3 -> IMA | C38: LT | D38: DJ | E38: C | F38: =VLOOKUP(G38,[1]Discrete!$A:$B,2,FALSE) -> AJUSTE PARA 81 E2 | G38: 81U2 | H38: {=_xlfn.IFS(OR(D38="TC",D38="TP",D38="LT"),CONCATENATE(B38,"_",C38,$B$3,"_",C38,$B$3,"_",G38),D38="SECC",CONCATENATE(B38,"_",C38,$B$3,"_",$B$5,"_",G38),D38="SECF",CONCATENATE(B38,"_",C38,$B$3,"_",$B$6,"_",G38),D38="SECT",CONCATENATE(B38,"_",C38,$B$3,"_",$B$7,"_",G38),D38="SECG",CONCATENATE(B38,"_",C38,$B$3,"_",$B$8,"_",G38),D38="DJ",CONCATENATE(B38,"_",C38,$B$3,"_",$B$4,"_",G38),D38="DJ_P",CONCATENATE(B38,"_",C38,$B$3,"_",$B$4,"_P","_",G38),D38="DJ_A",CONCATENATE(B38,"_",C38,$B$3,"_",$B$4,"_A","_",G38),D38="LT_P",CONCATENATE(B38,"_",C38,$B$3,"_",C38,$B$3,"_P","_",G38),D38="LT_A",CONCATENATE(B38,"_",C38,$B$3,"_",C38,$B$3,"_A","_",G38))} -> IMA_LT2_52-2_81U2 | I38: - | J38: - | K38: - | L38: - | M38: 0 - Close/Pulse-On // 1 - Trip/Pulse-On
A39: NÃO | B39: =Informações!$C$3 -> IMA | C39: LT | D39: DJ | E39: C | F39: =VLOOKUP(G39,[1]Discrete!$A:$B,2,FALSE) -> AJUSTE PARA 81 E3 | G39: 81U3 | H39: {=_xlfn.IFS(OR(D39="TC",D39="TP",D39="LT"),CONCATENATE(B39,"_",C39,$B$3,"_",C39,$B$3,"_",G39),D39="SECC",CONCATENATE(B39,"_",C39,$B$3,"_",$B$5,"_",G39),D39="SECF",CONCATENATE(B39,"_",C39,$B$3,"_",$B$6,"_",G39),D39="SECT",CONCATENATE(B39,"_",C39,$B$3,"_",$B$7,"_",G39),D39="SECG",CONCATENATE(B39,"_",C39,$B$3,"_",$B$8,"_",G39),D39="DJ",CONCATENATE(B39,"_",C39,$B$3,"_",$B$4,"_",G39),D39="DJ_P",CONCATENATE(B39,"_",C39,$B$3,"_",$B$4,"_P","_",G39),D39="DJ_A",CONCATENATE(B39,"_",C39,$B$3,"_",$B$4,"_A","_",G39),D39="LT_P",CONCATENATE(B39,"_",C39,$B$3,"_",C39,$B$3,"_P","_",G39),D39="LT_A",CONCATENATE(B39,"_",C39,$B$3,"_",C39,$B$3,"_A","_",G39))} -> IMA_LT2_52-2_81U3 | I39: - | J39: - | K39: - | L39: - | M39: 0 - Close/Pulse-On // 1 - Trip/Pulse-On
A40: NÃO | B40: =Informações!$C$3 -> IMA | C40: LT | D40: DJ | E40: C | F40: =VLOOKUP(G40,[1]Discrete!$A:$B,2,FALSE) -> AJUSTE PARA 81 E4 | G40: 81U4 | H40: {=_xlfn.IFS(OR(D40="TC",D40="TP",D40="LT"),CONCATENATE(B40,"_",C40,$B$3,"_",C40,$B$3,"_",G40),D40="SECC",CONCATENATE(B40,"_",C40,$B$3,"_",$B$5,"_",G40),D40="SECF",CONCATENATE(B40,"_",C40,$B$3,"_",$B$6,"_",G40),D40="SECT",CONCATENATE(B40,"_",C40,$B$3,"_",$B$7,"_",G40),D40="SECG",CONCATENATE(B40,"_",C40,$B$3,"_",$B$8,"_",G40),D40="DJ",CONCATENATE(B40,"_",C40,$B$3,"_",$B$4,"_",G40),D40="DJ_P",CONCATENATE(B40,"_",C40,$B$3,"_",$B$4,"_P","_",G40),D40="DJ_A",CONCATENATE(B40,"_",C40,$B$3,"_",$B$4,"_A","_",G40),D40="LT_P",CONCATENATE(B40,"_",C40,$B$3,"_",C40,$B$3,"_P","_",G40),D40="LT_A",CONCATENATE(B40,"_",C40,$B$3,"_",C40,$B$3,"_A","_",G40))} -> IMA_LT2_52-2_81U4 | I40: - | J40: - | K40: - | L40: - | M40: 0 - Close/Pulse-On // 1 - Trip/Pulse-On
A41: NÃO | B41: =Informações!$C$3 -> IMA | C41: LT | D41: DJ | E41: C | F41: AJUSTE PARA 81 ESTAGIO 5 | G41: 81U5 | H41: {=_xlfn.IFS(OR(D41="TC",D41="TP",D41="LT"),CONCATENATE(B41,"_",C41,$B$3,"_",C41,$B$3,"_",G41),D41="SECC",CONCATENATE(B41,"_",C41,$B$3,"_",$B$5,"_",G41),D41="SECF",CONCATENATE(B41,"_",C41,$B$3,"_",$B$6,"_",G41),D41="SECT",CONCATENATE(B41,"_",C41,$B$3,"_",$B$7,"_",G41),D41="SECG",CONCATENATE(B41,"_",C41,$B$3,"_",$B$8,"_",G41),D41="DJ",CONCATENATE(B41,"_",C41,$B$3,"_",$B$4,"_",G41),D41="DJ_P",CONCATENATE(B41,"_",C41,$B$3,"_",$B$4,"_P","_",G41),D41="DJ_A",CONCATENATE(B41,"_",C41,$B$3,"_",$B$4,"_A","_",G41),D41="LT_P",CONCATENATE(B41,"_",C41,$B$3,"_",C41,$B$3,"_P","_",G41),D41="LT_A",CONCATENATE(B41,"_",C41,$B$3,"_",C41,$B$3,"_A","_",G41))} -> IMA_LT2_52-2_81U5 | I41: - | J41: - | K41: - | L41: - | M41: 0 - Close/Pulse-On // 1 - Trip/Pulse-On
A42: NÃO | B42: =Informações!$C$3 -> IMA | C42: LT | D42: SECC | E42: D | F42: =VLOOKUP(G42,[1]Discrete!$A:$B,2,FALSE) -> SECCIONADORA CARGA | G42: SECC | H42: {=_xlfn.IFS(OR(D42="TC",D42="TP",D42="LT"),CONCATENATE(B42,"_",C42,$B$3,"_",C42,$B$3,"_",G42),D42="SECC",CONCATENATE(B42,"_",C42,$B$3,"_",$B$5,"_",G42),D42="SECF",CONCATENATE(B42,"_",C42,$B$3,"_",$B$6,"_",G42),D42="SECT",CONCATENATE(B42,"_",C42,$B$3,"_",$B$7,"_",G42),D42="SECG",CONCATENATE(B42,"_",C42,$B$3,"_",$B$8,"_",G42),D42="DJ",CONCATENATE(B42,"_",C42,$B$3,"_",$B$4,"_",G42),D42="DJ_P",CONCATENATE(B42,"_",C42,$B$3,"_",$B$4,"_P","_",G42),D42="DJ_A",CONCATENATE(B42,"_",C42,$B$3,"_",$B$4,"_A","_",G42),D42="LT_P",CONCATENATE(B42,"_",C42,$B$3,"_",C42,$B$3,"_P","_",G42),D42="LT_A",CONCATENATE(B42,"_",C42,$B$3,"_",C42,$B$3,"_A","_",G42))} -> IMA_LT2_89-10_SECC | I42: Ponto Simples | J42: ABERTA | K42: FECHADA | L42: - | M42: -
A43: NÃO | B43: =Informações!$C$3 -> IMA | C43: LT | D43: SECC | E43: D | F43: =VLOOKUP(G43,[1]Discrete!$A:$B,2,FALSE) -> 43 - CHAVE LOCAL REMOTO | G43: 43LR | H43: {=_xlfn.IFS(OR(D43="TC",D43="TP",D43="LT"),CONCATENATE(B43,"_",C43,$B$3,"_",C43,$B$3,"_",G43),D43="SECC",CONCATENATE(B43,"_",C43,$B$3,"_",$B$5,"_",G43),D43="SECF",CONCATENATE(B43,"_",C43,$B$3,"_",$B$6,"_",G43),D43="SECT",CONCATENATE(B43,"_",C43,$B$3,"_",$B$7,"_",G43),D43="SECG",CONCATENATE(B43,"_",C43,$B$3,"_",$B$8,"_",G43),D43="DJ",CONCATENATE(B43,"_",C43,$B$3,"_",$B$4,"_",G43),D43="DJ_P",CONCATENATE(B43,"_",C43,$B$3,"_",$B$4,"_P","_",G43),D43="DJ_A",CONCATENATE(B43,"_",C43,$B$3,"_",$B$4,"_A","_",G43),D43="LT_P",CONCATENATE(B43,"_",C43,$B$3,"_",C43,$B$3,"_P","_",G43),D43="LT_A",CONCATENATE(B43,"_",C43,$B$3,"_",C43,$B$3,"_A","_",G43))} -> IMA_LT2_89-10_43LR | I43: Ponto Simples | J43: REMOTO | K43: LOCAL | L43: - | M43: -
...

Sheet RELACAO RELES
B2: MODULO | C2: FUNÇÃO | D2: NOME / DRECRIÇÃO | E2: MODELO RELÉ / PN | F2: BAY
B3: 01F1 | C3: Proteção de linha principal | D3: FUTURO | F3: 52-1
B4: 01F2 | C4: Proteção de linha alternada | D4: FUTURO
B5: 02F1 | C5: Proteção de linha principal | D5: FUTURO | F5: 52-2
B6: 02F2 | C6: Proteção de linha alternada | D6: FUTURO
B7: 03F1 | C7: Proteção de linha principal | D7: ARROIO DO MEIO | E7: SIEMENS - 7SA86 - P1A460224 | F7: 52-3
B8: 03F2 | C8: Proteção de linha alternada | D8: ARROIO DO MEIO | E8: SIEMENS - 7SA86 - P1A460224
B9: 04F1 | C9: Proteção de linha principal | D9: ENCANTADO | E9: SIEMENS - 7SA86 - P1A460224 | F9: 52-4
B10: 04F2 | C10: Proteção de linha alternada | D10: ENCANTADO | E10: SIEMENS - 7SA86 - P1A460224
B11: 05F1 | C11: Sobrecorrente Transf barra AT | D11: FUTURO | F11: 24-3
B12: 06F1 | C12: Proteção dif + proteção GAT | D12: TRANSFORMADOR 1 | E12: SIEMENS - 7UT85 - P1F1070286 | F12: 52-6
B13: 06F2 | C13: Proteção dif + proteção GBT | D13: TRANSFORMADOR 1 | E13: SIEMENS - 7UT85 - P1F1070286 | F13: 52-19
B14: 06F3 | C14: Proteção e regulação comutador | D14: TRANSFORMADOR 1 | E14: SEL - 2414 | F14: TR1
B15: 07F1 | C15: Proteção dif + proteção GAT | D15: TRANSFORMADOR 2 | E15: SIEMENS - 7UT85 - P1F1070286 | F15: 52-7
B16: 07F2 | C16: Proteção dif + proteção GBT | D16: TRANSFORMADOR 2 | E16: SIEMENS - 7UT85 - P1F1070286 | F16: 52-29
B17: 07F3 | C17: Proteção e regulação comutador | D17: TRANSFORMADOR 2 | E17: SEL - 2414 | F17: TR2
B18: 34F1 | C18: Diferencial de barras AT | D18: BARRA AT TR1/2 | E18: SIEMENS - 7SS85 - P1E772365 | F18: BARRA AT
B19: 35F1 | C19: Diferencial de barras BT TR1 | D19: BARRA BT TR1 | E19: SIEMENS - 7SS85 - P1E772365 | F19: BARRA 1 BT
B20: 36F1 | C20: Diferencial de barras BT TR2 | D20: BARRA BT TR2 | E20: SIEMENS - 7SS85 - P1E772365 | F20: BARRA 2 BT
B21: 11F1 | C21: Sobrecorrente Alim 11 | D21: ALIMENTADOR 11 | E21: SIEMENS - 7SJ82 - P1J39905 | F21: 52-11
B22: 12F1 | C22: Sobrecorrente Alim 12 | D22: ALIMENTADOR 12 | E22: SIEMENS - 7SJ82 - P1J39905 | F22: 52-12
B23: 13F1 | C23: Sobrecorrente Alim 13 | D23: ALIMENTADOR 13 | E23: SIEMENS - 7SJ82 - P1J39905 | F23: 52-13
B24: 14F1 | C24: Sobrecorrente Alim 14 | D24: FUTURO | F24: 52-14
B25: 15F1 | C25: Sobrecorrente Alim 15 | D25: FUTURO | F25: 52-15
B26: 16F1 | C26: Sobrecorrente Alim 16 | D26: FUTURO | F26: 52-16
B27: 19F1 | C27: Sobrecorrente Transf barra 1 MT | D27: TRANSFERENCIA | E27: SIEMENS - 7SJ82 - P1J39905 | F27: 24-1
