Workbook
Name AnalogName: OFFSET([1]AnalogName!$B$2,0,0,COUNTA([1]AnalogName!$B$2:$B$1048576),1)
Name AnalogSignalType: [2]Info!$L$28:$L$51
Name AOR: #REF!
Name AORgroup: #REF!
Name CauseOfTransmissionLength: #REF!
Name command: #REF!
Name CommandQualifier: #REF!
Name CommandTriggersFastScan: #REF!
Name commT: #REF!
Name datatype: #REF!
Name DataType_: #REF!
Name DeadbandType: #REF!
Name direction: #REF!
Name Direction_: #REF!
Name display: #REF!
Name DisplayUnit: #REF!
Name FalseTrue: #REF!
Name flowd: #REF!
Name FlowDirection: #REF!
Name measurement: #REF!
Name MeasurementType: #REF!
Name N: #REF!
Name phases: #REF!
Name Phases_: #REF!
Name protocol: #REF!
Name qualifier: #REF!
Name ratedata: #REF!
Name RateType: #REF!
Name RemotePointType: #REF!
Name RemoteSource: #REF!
Name RemoteUnitType: #REF!
Name role: #REF!
Name RTU: #REF!
Name rtype: #REF!
Name sbo: #REF!
Name SelectBeforeOperate: #REF!
Name servicerole: #REF!
Name ServiceRole_: #REF!
Name SignalsType: #REF!
Name signaltype: #REF!
Name source: #REF!
Name stype: #REF!
Name TF: #REF!
Name Time_Zone: #REF!
Name TimeSyncMode: #REF!
Name timezone: #REF!
Name transmission: #REF!
Name type: #REF!
Name typedata: #REF!
Name typeM: #REF!

Sheet DiscreteSignals
A1: SINAL | B1: DESCRIÇÃO NOVA | C1: SIGNAL TYPE | D1: TYPE SEVERIDADE | E1: DIRECTION | F1: MM | G1: FUNÇÃO | H1: VALOR | I1: CONTROL CODE | J1: SEVERIDADE | K1: Funcionamento | L1: LINHA | M1: BARRA | N1: TRANSFORMADOR | O1: ALIMENTADOR | P1: TRANSFERÊNCIA
A2: CMDE | B2: PROPRIEDADE DO COMANDO | C2: Custom | D2: ALARMES PREDIAIS/VF/GRUPO | E2: ReadWrite | F2: CMD_CEEE@CMD_RGE___CEEE@RGE___Custom___INV___admsINV_S_TC_SA | G2: =VLOOKUP(F2,'Message Mapping'!A:L,3,FALSE) | H2: =VLOOKUP(F2,'Message Mapping'!A:L,4,FALSE) | J2: =VLOOKUP(F2,'Message Mapping'!A:L,12,FALSE)
A3: CCIC | B3: CHAVE DE COMANDO ICCP | C3: Custom | D3: ALARMES PREDIAIS/VF/GRUPO | E3: ReadWrite | F3: CMD_RGE@null___RGE@CPFLT___Custom_S_TC_SS_CPFLT | G3: =VLOOKUP(F3,'Message Mapping'!A:L,3,FALSE) | H3: =VLOOKUP(F3,'Message Mapping'!A:L,4,FALSE) | J3: =VLOOKUP(F3,'Message Mapping'!A:L,12,FALSE) | K3: Chave Virtual para seleção de quem está com o controle dos equipamentos (intertrava comandos no SAGE)
A4: 20A | B4: 20 - ALARME VALVULA | C4: Custom | D4: PROT | E4: Read | F4: null@null___NORMAL@ATUADO___Custom_S_TS_SA | G4: =VLOOKUP(F4,'Message Mapping'!A:L,3,FALSE) | H4: =VLOOKUP(F4,'Message Mapping'!A:L,4,FALSE) | J4: =VLOOKUP(F4,'Message Mapping'!A:L,12,FALSE)
A5: 20CA | B5: 20 - ALARME VALVULA CDC | C5: Custom | D5: PROT | E5: Read | F5: null@null___NORMAL@ATUADO___Custom_S_TS_SA | G5: =VLOOKUP(F5,'Message Mapping'!A:L,3,FALSE) | H5: =VLOOKUP(F5,'Message Mapping'!A:L,4,FALSE) | J5: =VLOOKUP(F5,'Message Mapping'!A:L,12,FALSE)
A6: 20TA | B6: 20 - ALARME VALVULA TRAFO | C6: Custom | D6: PROT | E6: Read | F6: null@null___NORMAL@ATUADO___Custom_S_TS_SA | G6: =VLOOKUP(F6,'Message Mapping'!A:L,3,FALSE) | H6: =VLOOKUP(F6,'Message Mapping'!A:L,4,FALSE) | J6: =VLOOKUP(F6,'Message Mapping'!A:L,12,FALSE)
A7: 20T | B7: 20 - VALVULA TRANSFORMADOR | C7: RelayTrip | D7: PROT | E7: Read | F7: null@null___NORMAL@ATUADO___RelayTrip_S_TS_SA | G7: =VLOOKUP(F7,'Message Mapping'!A:L,3,FALSE) | H7: =VLOOKUP(F7,'Message Mapping'!A:L,4,FALSE) | J7: =VLOOKUP(F7,'Message Mapping'!A:L,12,FALSE)
A8: 20C | B8: 20 - VALVULA COMUTADOR | C8: RelayTrip | D8: PROT | E8: Read | F8: null@null___NORMAL@ATUADO___RelayTrip_S_TS_SA | G8: =VLOOKUP(F8,'Message Mapping'!A:L,3,FALSE) | H8: =VLOOKUP(F8,'Message Mapping'!A:L,4,FALSE) | J8: =VLOOKUP(F8,'Message Mapping'!A:L,12,FALSE)
A9: 20D | B9: 20 - TRIP VALVULA | C9: RelayTrip | D9: PROT | E9: Read | F9: null@null___NORMAL@ATUADO___RelayTrip_S_TS_SA | G9: =VLOOKUP(F9,'Message Mapping'!A:L,3,FALSE) | H9: =VLOOKUP(F9,'Message Mapping'!A:L,4,FALSE) | J9: =VLOOKUP(F9,'Message Mapping'!A:L,12,FALSE)
A10: 20CD | B10: 20 - TRIP VALVULA CDC | C10: RelayTrip | D10: PROT | E10: Read | F10: null@null___NORMAL@ATUADO___RelayTrip_S_TS_SA | G10: =VLOOKUP(F10,'Message Mapping'!A:L,3,FALSE) | H10: =VLOOKUP(F10,'Message Mapping'!A:L,4,FALSE) | J10: =VLOOKUP(F10,'Message Mapping'!A:L,12,FALSE)
A11: 20TD | B11: 20 - TRIP VALVULA TRAFO | C11: RelayTrip | D11: PROT | E11: Read | F11: null@null___NORMAL@ATUADO___RelayTrip_S_TS_SA | G11: =VLOOKUP(F11,'Message Mapping'!A:L,3,FALSE) | H11: =VLOOKUP(F11,'Message Mapping'!A:L,4,FALSE) | J11: =VLOOKUP(F11,'Message Mapping'!A:L,12,FALSE)
A12: 20T1 | B12: 20 - TRIP VALVULA TRAFO E1 | C12: RelayTrip | D12: PROT | E12: Read | F12: null@null___NORMAL@ATUADO___RelayTrip_S_TS_SA | G12: =VLOOKUP(F12,'Message Mapping'!A:L,3,FALSE) | H12: =VLOOKUP(F12,'Message Mapping'!A:L,4,FALSE) | J12: =VLOOKUP(F12,'Message Mapping'!A:L,12,FALSE)
A13: 20T2 | B13: 20 - TRIP VALVULA TRAFO E2 | C13: RelayTrip | D13: PROT | E13: Read | F13: null@null___NORMAL@ATUADO___RelayTrip_S_TS_SA | G13: =VLOOKUP(F13,'Message Mapping'!A:L,3,FALSE) | H13: =VLOOKUP(F13,'Message Mapping'!A:L,4,FALSE) | J13: =VLOOKUP(F13,'Message Mapping'!A:L,12,FALSE)
A14: 20TC | B14: 20 - TRIP VALVULA TRAFO OU CDC | C14: RelayTrip | D14: PROT | E14: Read | F14: null@null___NORMAL@ATUADO___RelayTrip_S_TS_SA | G14: =VLOOKUP(F14,'Message Mapping'!A:L,3,FALSE) | H14: =VLOOKUP(F14,'Message Mapping'!A:L,4,FALSE) | J14: =VLOOKUP(F14,'Message Mapping'!A:L,12,FALSE)
A15: INTR | B15: 20 63 87 - PROTECOES INTRINSECAS | C15: RelayTrip | D15: PROT | E15: Read | F15: null@null___NORMAL@ATUADO___RelayTrip_S_TS_SA | G15: =VLOOKUP(F15,'Message Mapping'!A:L,3,FALSE) | H15: =VLOOKUP(F15,'Message Mapping'!A:L,4,FALSE) | J15: =VLOOKUP(F15,'Message Mapping'!A:L,12,FALSE)
... A66: TOEA | B66: 26 49 - ALARME TEMPERATURA | C66: Custom | D66: PROT | E66: Read | F66: null@null___NORMAL@ATUADO___Custom_S_TS_SI | G66: =VLOOKUP(F66,'Message Mapping'!A:L,3,FALSE) | H66: =VLOOKUP(F66,'Message Mapping'!A:L,4,FALSE) | J66: =VLOOKUP(F66,'Message Mapping'!A:L,12,FALSE)
A67: 2649 | B67: 26 49 - FUNCAO TEMPERATURA | C67: Enabled | D67: FUNCÕES/43/PARALELISMO | E67: ReadWrite | F67: INCLUIR@EXCLUIR___INCLUIDO@EXCLUIDO___Enabled_S_TC_SS | G67: =VLOOKUP(F67,'Message Mapping'!A:L,3,FALSE) | H67: =VLOOKUP(F67,'Message Mapping'!A:L,4,FALSE) | J67: =VLOOKUP(F67,'Message Mapping'!A:L,12,FALSE) | K67: Usado para indicar que houve o trip do disjuntor do alimentador, devido atuação da proteção por temperatura dos transformadores. Para verificar quais alimentadores possuem a função ativada, deve-se verificar a folha de ajustes da proteção.
A68: 2649 | B68: 26 49 - FUNCAO TEMPERATURA | C68: Enabled | D68: FUNCÕES/43/PARALELISMO | E68: Read | F68: null@null___INCLUIDO@EXCLUIDO___Enabled_S_TS_SS | G68: =VLOOKUP(F68,'Message Mapping'!A:L,3,FALSE) | H68: =VLOOKUP(F68,'Message Mapping'!A:L,4,FALSE) | J68: =VLOOKUP(F68,'Message Mapping'!A:L,12,FALSE) | K68: Usado nos transformadores, pra indicar o trip por temperatura (óleo ou enrolamento).
A69: TOED | B69: 26 49 - TRIP TEMPERATURA | C69: RelayTrip | D69: PROT | E69: Read | F69: null@null___NORMAL@ATUADO___RelayTrip_S_TS_SA | G69: =VLOOKUP(F69,'Message Mapping'!A:L,3,FALSE) | H69: =VLOOKUP(F69,'Message Mapping'!A:L,4,FALSE) | J69: =VLOOKUP(F69,'Message Mapping'!A:L,12,FALSE)
A70: 27BL | B70: 27 - BLOQUEIO SUBTENSAO | C70: Custom | D70: PROT | E70: Read | F70: null@null___NORMAL@ATUADO___Custom_S_TS_SA | G70: =VLOOKUP(F70,'Message Mapping'!A:L,3,FALSE) | H70: =VLOOKUP(F70,'Message Mapping'!A:L,4,FALSE) | J70: =VLOOKUP(F70,'Message Mapping'!A:L,12,FALSE)
A71: 27 | B71: 27 - FUNCAO SUBTENSAO | C71: Enabled | D71: FUNCÕES/43/PARALELISMO | E71: ReadWrite | F71: INCLUIR@EXCLUIR___INCLUIDO@EXCLUIDO___Enabled_S_TC_SS | G71: =VLOOKUP(F71,'Message Mapping'!A:L,3,FALSE) | H71: =VLOOKUP(F71,'Message Mapping'!A:L,4,FALSE) | J71: =VLOOKUP(F71,'Message Mapping'!A:L,12,FALSE)
A72: 27 | B72: 27 - FUNCAO SUBTENSAO | C72: Enabled | D72: FUNCÕES/43/PARALELISMO | E72: Read | F72: null@null___INCLUIDO@EXCLUIDO___Enabled_S_TS_SS | G72: =VLOOKUP(F72,'Message Mapping'!A:L,3,FALSE) | H72: =VLOOKUP(F72,'Message Mapping'!A:L,4,FALSE) | J72: =VLOOKUP(F72,'Message Mapping'!A:L,12,FALSE)
A73: 27BR | B73: 27 - SUBTENSAO BARRA | C73: Custom | D73: PROT | E73: Read | F73: null@null___NORMAL@ATUADO___Custom_S_TS_SA | G73: =VLOOKUP(F73,'Message Mapping'!A:L,3,FALSE) | H73: =VLOOKUP(F73,'Message Mapping'!A:L,4,FALSE) | J73: =VLOOKUP(F73,'Message Mapping'!A:L,12,FALSE)
A74: 27CD | B74: 27 - BLOQUEIO SUBTENSAO CDC | C74: Custom | D74: PROT | E74: Read | F74: null@null___NORMAL@ATUADO___Custom_S_TS_SA | G74: =VLOOKUP(F74,'Message Mapping'!A:L,3,FALSE) | H74: =VLOOKUP(F74,'Message Mapping'!A:L,4,FALSE) | J74: =VLOOKUP(F74,'Message Mapping'!A:L,12,FALSE)
A75: 27E1 | B75: 27 - SUBTENSAO E1 | C75: Custom | D75: PROT | E75: Read | F75: null@null___NORMAL@ATUADO___Custom_S_TS_SA | G75: =VLOOKUP(F75,'Message Mapping'!A:L,3,FALSE) | H75: =VLOOKUP(F75,'Message Mapping'!A:L,4,FALSE) | J75: =VLOOKUP(F75,'Message Mapping'!A:L,12,FALSE)
A76: 27E2 | B76: 27 - SUBTENSAO E2 | C76: Custom | D76: PROT | E76: Read | F76: null@null___NORMAL@ATUADO___Custom_S_TS_SA | G76: =VLOOKUP(F76,'Message Mapping'!A:L,3,FALSE) | H76: =VLOOKUP(F76,'Message Mapping'!A:L,4,FALSE) | J76: =VLOOKUP(F76,'Message Mapping'!A:L,12,FALSE)
A77: 27AB | B77: 27 - SUBTENSAO FASE AB | C77: Custom | D77: PROT | E77: Read | F77: null@null___NORMAL@ATUADO___Custom_S_TS_SA | G77: =VLOOKUP(F77,'Message Mapping'!A:L,3,FALSE) | H77: =VLOOKUP(F77,'Message Mapping'!A:L,4,FALSE) | J77: =VLOOKUP(F77,'Message Mapping'!A:L,12,FALSE)
A78: 27AC | B78: 27 - SUBTENSAO FASE AC | C78: Custom | D78: PROT | E78: Read | F78: null@null___NORMAL@ATUADO___Custom_S_TS_SA | G78: =VLOOKUP(F78,'Message Mapping'!A:L,3,FALSE) | H78: =VLOOKUP(F78,'Message Mapping'!A:L,4,FALSE) | J78: =VLOOKUP(F78,'Message Mapping'!A:L,12,FALSE)
A79: 27BC | B79: 27 - SUBTENSAO FASE BC | C79: Custom | D79: PROT | E79: Read | F79: null@null___NORMAL@ATUADO___Custom_S_TS_SA | G79: =VLOOKUP(F79,'Message Mapping'!A:L,3,FALSE) | H79: =VLOOKUP(F79,'Message Mapping'!A:L,4,FALSE) | J79: =VLOOKUP(F79,'Message Mapping'!A:L,12,FALSE)
A80: 27LT | B80: 27 - SUBTENSAO LINHA | C80: Custom | D80: PROT | E80: Read | F80: null@null___NORMAL@ATUADO___Custom_S_TS_SA | G80: =VLOOKUP(F80,'Message Mapping'!A:L,3,FALSE) | H80: =VLOOKUP(F80,'Message Mapping'!A:L,4,FALSE) | J80: =VLOOKUP(F80,'Message Mapping'!A:L,12,FALSE)
... A244: 43TP | B244: 43 - TRANSFERENCIA DE PROTECAO | C244: Custom | D244: FUNCÕES/43/PARALELISMO | E244: ReadWrite | F244: INCLUIR@EXCLUIR___INCLUIDO@EXCLUIDO___Custom_S_TC_SS | G244: =VLOOKUP(F244,'Message Mapping'!A:L,3,FALSE) | H244: =VLOOKUP(F244,'Message Mapping'!A:L,4,FALSE) | J244: =VLOOKUP(F244,'Message Mapping'!A:L,12,FALSE)
A245: 86 | B245: 86 - BLOQUEIO | C245: Custom | D245: PROT | E245: Read | F245: null@REARMAR___NORMAL@ATUADO___Custom_S_TS_SA | G245: =VLOOKUP(F245,'Message Mapping'!A:L,3,FALSE) | H245: =VLOOKUP(F245,'Message Mapping'!A:L,4,FALSE) | J245: =VLOOKUP(F245,'Message Mapping'!A:L,12,FALSE) | K245: Utilizado em transformadores, indica o defeito no equipamento.
A246: 86 | B246: 86 - BLOQUEIO | C246: Custom | D246: PROT | E246: ReadWrite | F246: REARMAR@null___NORMAL@ATUADO___Custom_S_TC_SA | G246: =VLOOKUP(F246,'Message Mapping'!A:L,3,FALSE) | H246: =VLOOKUP(F246,'Message Mapping'!A:L,4,FALSE) | J246: =VLOOKUP(F246,'Message Mapping'!A:L,12,FALSE) | K246: Utilizado em transformadores, indica o defeito no equipamento.
A247: 86BF | B247: 86 - BLOQUEIO DEFEITO DISJUNTOR | C247: Custom | D247: PROT | E247: Read | F247: null@REARMAR___NORMAL@ATUADO___Custom_S_TS_SA | G247: =VLOOKUP(F247,'Message Mapping'!A:L,3,FALSE) | H247: =VLOOKUP(F247,'Message Mapping'!A:L,4,FALSE) | J247: =VLOOKUP(F247,'Message Mapping'!A:L,12,FALSE) | K247: Utilizado em LTs, Barras e DJs, indica defeito no disjuntor
A248: 86BF | B248: 86 - BLOQUEIO DEFEITO DISJUNTOR | C248: Custom | D248: PROT | E248: ReadWrite | F248: REARMAR@null___NORMAL@ATUADO___Custom_S_TC_SA | G248: =VLOOKUP(F248,'Message Mapping'!A:L,3,FALSE) | H248: =VLOOKUP(F248,'Message Mapping'!A:L,4,FALSE) | J248: =VLOOKUP(F248,'Message Mapping'!A:L,12,FALSE) | K248: Utilizado em LTs, Barras e DJs, indica defeito no disjuntor
A249: 86C | B249: 86 - BLOQUEIO CDC | C249: Custom | D249: PROT | E249: Read | F249: null@null___NORMAL@ATUADO___Custom_S_TS_SA | G249: =VLOOKUP(F249,'Message Mapping'!A:L,3,FALSE) | H249: =VLOOKUP(F249,'Message Mapping'!A:L,4,FALSE) | J249: =VLOOKUP(F249,'Message Mapping'!A:L,12,FALSE)
A250: 86FL | B250: 86 - FALHA CIRCUITO RELE | C250: Custom | D250: FALHAS FCOM/VCA/VCC | E250: Read | F250: null@null___NORMAL@FALHA___Custom_S_TS_SB | G250: =VLOOKUP(F250,'Message Mapping'!A:L,3,FALSE) | H250: =VLOOKUP(F250,'Message Mapping'!A:L,4,FALSE) | J250: =VLOOKUP(F250,'Message Mapping'!A:L,12,FALSE)
A251: 87BL | B251: 87 - DIFERENCIAL BLOQUEIO | C251: RelayTrip | D251: PROT | E251: Read | F251: null@null___NORMAL@ATUADO___RelayTrip_S_TS_SA | G251: =VLOOKUP(F251,'Message Mapping'!A:L,3,FALSE) | H251: =VLOOKUP(F251,'Message Mapping'!A:L,4,FALSE) | J251: =VLOOKUP(F251,'Message Mapping'!A:L,12,FALSE)
A252: 87A | B252: 87 - DIFERENCIAL FASE A | C252: RelayTrip | D252: PROT | E252: Read | F252: null@null___NORMAL@ATUADO___RelayTrip_S_TS_SA | G252: =VLOOKUP(F252,'Message Mapping'!A:L,3,FALSE) | H252: =VLOOKUP(F252,'Message Mapping'!A:L,4,FALSE) | J252: =VLOOKUP(F252,'Message Mapping'!A:L,12,FALSE)
A253: 87B | B253: 87 - DIFERENCIAL FASE B | C253: RelayTrip | D253: PROT | E253: Read | F253: null@null___NORMAL@ATUADO___RelayTrip_S_TS_SA | G253: =VLOOKUP(F253,'Message Mapping'!A:L,3,FALSE) | H253: =VLOOKUP(F253,'Message Mapping'!A:L,4,FALSE) | J253: =VLOOKUP(F253,'Message Mapping'!A:L,12,FALSE)
...

Sheet AnalogSignals
A1: SINAL | B1: DESCRIÇÃO NOVA | C1: SIGNAL TYPE | D1: TIPO DE MEDIÇÃO | E1: UNIDADE DE EXIBIÇÃO | F1: FASES | G1: LADO | H1: DIREÇÃO DO FLUXO | I1: FUNCIONAMENTO
A2: IN61 | B2: 61 - CORRENTE DE DESEQUILIBRO | C2: Valor Medido | D2: Corrente | E2: A | F2: N
A3: ANG | B3: ANGULO | C3: Valor Medido | D3: Ângulo de Tensão | E3: Grau | F3: L1 L2 L3
A4: OPER | B4: CONTAGEM DE OPERACOES | C4: Contagem de Operação | D4: Discreto | E4: - | F4: L1 L2 L3
A5: IOUT | B5: CORRENTE CARGA | C5: Valor Medido | D5: Corrente | E5: A | F5: L1 L2 L3
A6: IACC | B6: CORRENTE CURTO CIRCUITO FASE A | C6: Gravador de Falha | D6: Corrente | E6: A | F6: L1
A7: IBCC | B7: CORRENTE CURTO CIRCUITO FASE B | C7: Gravador de Falha | D7: Corrente | E7: A | F7: L2
A8: ICCC | B8: CORRENTE CURTO CIRCUITO FASE C | C8: Gravador de Falha | D8: Corrente | E8: A | F8: L3
A9: INCC | B9: CORRENTE CURTO CIRCUITO NEUTRO | C9: Gravador de Falha | D9: Corrente | E9: A | F9: N
A10: IA | B10: CORRENTE FASE A | C10: Valor Medido | D10: Corrente | E10: A | F10: L1
A11: IB | B11: CORRENTE FASE B | C11: Valor Medido | D11: Corrente | E11: A | F11: L2
A12: IC | B12: CORRENTE FASE C | C12: Valor Medido | D12: Corrente | E12: A | F12: L3
A13: IN | B13: CORRENTE NEUTRO | C13: Valor Medido | D13: Corrente | E13: A | F13: N
... A27: V | B27: TENSAO | C27: Valor Medido | D27: Tensão | E27: kV | F27: L1 L2 L3
A28: V | B28: TENSAO | C28: Valor Medido | D28: Tensão | E28: V | F28: L1 L2 L3 | I28: Serviço auxiliar
A29: VA_B | B29: TENSAO BARRA FASE A | C29: Valor Medido | D29: Tensão | E29: kV | F29: L1
A30: VB_B | B30: TENSAO BARRA FASE B | C30: Valor Medido | D30: Tensão | E30: kV | F30: L2
A31: VC_B | B31: TENSAO BARRA FASE C | C31: Valor Medido | D31: Tensão | E31: kV | F31: L3
A32: VBAT | B32: TENSAO BATERIAS | C32: Valor Medido | D32: Tensão | E32: V | F32: L1 L2 L3
A33: VCC | B33: TENSAO CORRENTE CONTINUA | C33: Valor Medido | D33: Tensão | E33: V | F33: L1 L2 L3
A34: VCC1 | B34: TENSAO CORRENTE CONTINUA 1 | C34: Valor Medido | D34: Tensão | E34: V | F34: L1 L2 L3
A35: VCC2 | B35: TENSAO CORRENTE CONTINUA 2 | C35: Valor Medido | D35: Tensão | E35: V | F35: L1 L2 L3
A36: VIN | B36: TENSAO DE ENTRADA | C36: Valor Medido | D36: Tensão | E36: V | F36: L1 L2 L3
A37: VABI | B37: TENSAO FASE AB - LADO FONTE | C37: Valor Medido | D37: Tensão | E37: kV | F37: L1 L2
A38: VBCI | B38: TENSAO FASE BC - LADO FONTE | C38: Valor Medido | D38: Tensão | E38: kV | F38: L2 L3
A39: VCAI | B39: TENSAO FASE CA - LADO FONTE | C39: Valor Medido | D39: Tensão | E39: kV | F39: L1 L3
A40: VREF | B40: TENSAO DE REFERENCIA | C40: Valor Medido | D40: Tensão | E40: V | F40: L1 L2 L3
... A42: VA | B42: TENSAO FASE A | C42: Valor Medido | D42: Tensão | E42: kV | F42: L1
A43: VA | B43: TENSAO FASE A | C43: Valor Medido | D43: Tensão | E43: V | F43: L1 | I43: Serviço auxiliar
A44: VB | B44: TENSAO FASE B | C44: Valor Medido | D44: Tensão | E44: kV | F44: L2
A45: VB | B45: TENSAO FASE B | C45: Valor Medido | D45: Tensão | E45: V | F45: L2 | I45: Serviço auxiliar
A46: VC | B46: TENSAO FASE C | C46: Valor Medido | D46: Tensão | E46: kV | F46: L3
A47: VC | B47: TENSAO FASE C | C47: Valor Medido | D47: Tensão | E47: V | F47: L3 | I47: Serviço auxiliar
A48: VAB | B48: TENSAO FASE AB | C48: Valor Medido | D48: Tensão | E48: kV | F48: L1 L2
A49: VAB | B49: TENSAO FASE AB | C49: Valor Medido | D49: Tensão | E49: V | F49: L1 L2 | I49: Serviço auxiliar
A50: VBC | B50: TENSAO FASE BC | C50: Valor Medido | D50: Tensão | E50: kV | F50: L2 L3
A51: VBC | B51: TENSAO FASE BC | C51: Valor Medido | D51: Tensão | E51: V | F51: L2 L3 | I51: Serviço auxiliar
A52: VCA | B52: TENSAO FASE CA | C52: Valor Medido | D52: Tensão | E52: kV | F52: L1 L3
A53: VCA | B53: TENSAO FASE CA | C53: Valor Medido | D53: Tensão | E53: V | F53: L1 L3 | I53: Serviço auxiliar
A54: VA_L | B54: TENSAO LINHA FASE A | C54: Valor Medido | D54: Tensão | E54: kV | F54: L1
...

Sheet DiscreteAnalog
A1: SINAL | B1: DESCRIÇÃO NOVA | C1: SIGNAL TYPE | D1: MEASUREMENT TYPE | E1: FASES | F1: DIRECTION | G1: NORMAL VALUE | H1: REMOTE POINT TYPE | I1: OUTPUT DATA TYPE | J1: DEVICE MAPPING REF | K1: APLICABILIDADE
A2: TAP | B2: POSICAO DO TAP | C2: TapPosition | D2: Discrete | E2: ABC | F2: Read | G2: 9 | H2: Analog | I2: Float | J2: COMTAP | K2: TRANSFORMADOR

Sheet DE->PARA
A1: SINAL | B1: DESCRIÇÃO NOVA
A2: 90 | B2: R90
A3: 20T87T | B3: 2087T
A4: 21_1 | B4: 21Z1
A5: 21_2 | B5: 21Z2
A6: 21_3 | B6: 21Z3
A7: 21_4 | B7: 21Z4
A8: 2646_T | B8: TOED
A9: 2649T | B9: TOED
A10: 27_1 | B10: 27E1
A11: 27_2 | B11: 27E2
A12: 27_B | B12: 27BR
A13: 27L | B13: 27LT
A14: 43CD | B14: RLCD
... A22: 63T | B22: 63TD
A23: 67EX | B23: 67
A24: 67T1 | B24: 67FT
A25: 67T2 | B25: 67FT
A26: 81_1 | B26: 81E1
A27: 81_2 | B27: 81E2
A28: 81_TRIP | B28: 81_T
A29: 86BFCC | B29: 86CC
A30: 86T | B30: 86
A31: 87RF | B31: 87EF
A32: 90PI | B32: MANUT
A33: ABRE | B33: TEXT
A34: AJ81U1 | B34: 81U1
A35: AJ81U2 | B35: 81U2
A36: AJ81U3 | B36: 81U3
A37: AJ81U4 | B37: 81U4
A38: AJ81U5 | B38: 81U5
A39: AUTC | B39: AUTO
A40: BAFU | B40: BATA
A41: BASD | B41: MANUT
A42: BB | B42: BBAF
... A49: CDCL | B49: RLCD
A50: CDCO_CTRL
A51: CDMA | B51: CDAM
A52: COMANDADO | B52: COMA
A53: DFT1 | B53: DRT1
...

Sheet Severidades
A1: DETALHADO | G1: RESUMIDO
A2: MM | B2: SEVERIDADE | C2: COLORAÇÃO SUMÁRIO | D2: USO | E2: TEXTO | G2: UTILIZAÇÃO | H2: SIGLA | I2: SEVERIDADE | J2: COLORAÇÃO SUMÁRIO
B3: 1 | C3: SEVERIDADE | D3: ALARME EMERGENCIAL MUST (105%) | E3: ALISUP EMER MUST | G3: DJ | H3: SE/ST/E2 | I3: 2 | J3: SEVERIDADE
D4: ALARME CONTRATADO MUST (100%) | E4: ALISUP CONTR MUST | G4: DEFEITOS | H4: SI | I4: 3 | J4: SEVERIDADE
A5: SE/ST/E2 | B5: 2 | C5: SEVERIDADE | D5: ESTADO DJs (exceto BC) - EVENTO | E5: ALESTC | G5: PROT | H5: SA/DA/A1 | I5: 4 | J5: SEVERIDADE
A6: SI | B6: 3 | C6: SEVERIDADE | D6: DRET, DR, Alarmes limites VCC, Bobinas e circuitos de abertura e fechamento | E6: ALESTS | G6: ALARMES PREDIAIS/VF/GRUPO | H6: SV/SP/DV/DP | I6: 5 | J6: SEVERIDADE
A7: SA/DA/A1 | B7: 4 | C7: SEVERIDADE | D7: TRIP: PROTEÇÕES: 86, 50, 51, 26, 49, 27, 87, 20, 63, ... | E7: ALESTS/ALESTC | G7: DJ BC/SEC | H7: SC/SO | I7: 6 | J7: SEVERIDADE
A8: SV/SP/DV/DP | B8: 5 | C8: SEVERIDADE | D8: ALARMES PREDIAIS, PORTAS, SENSOR DE PRESENÇA E DEFUMAÇA; VF | E8: ALESTS/ALESTC | G8: FALHAS FCOM/VCA/VCC | H8: SB/DB | I8: 7 | J8: SEVERIDADE
A9: SC/SO | B9: 6 | C9: SEVERIDADE | D9: ESTADO DJs BC / ESTADO SECCIONADORAS | E9: ALESTS/ALESTC | G9: FUNCÕES/43/PARALELISMO | H9: SS/DS | I9: 8 | J9: SEVERIDADE
A10: SB/DB | B10: 7 | C10: SEVERIDADE | D10: FALHA DE COMUNICAÇÃO (RELÉS); FALHA VF; FALHA VCC | E10: ALESTS
A11: SS/DS | B11: 8 | C11: SEVERIDADE | D11: 43TC, 43LR, PERMISSÃO DE PARALELISMO | E11: ALESTS/ALESTC
A12: ST | B12: 9 | C12: SEVERIDADE | D12: FALHA DE COMUNICAÇÃO (UTR) | E12: UTRRES
D13: COMANDO VARREDURA | E13: CNEXEC
D14: FALHA DE CONEXÃO (LINK) | E14: LNKNR
A15: - | B15: 10 | C15: SEVERIDADE | D15: COMANDOS | E15: COPER
A16: - | D16: LIMITE DE DADOS EMERGENCIAL (Tensões/Corrente) | E16: ALISUP EMER/CEXSIM
A17: - | D17: LIMITE DE DADOS OPERACIONAL (Tensões/Corrente) | E17: ALISUP OPER/CEXSIM
A18: - | D18: ATUALIZAÇÃO DE EQUIPES E PLANOS DE MANOBRAS | E18: -
B19: 11 | C19: SEVERIDADE | D19: EXECUÇÃO DE COMANDOS COM SUCESSO | E19: CEXEC
D20: LIMITE DE DADOS OPERACIONAL (Tensões) | E20: ALISUP EMER
D21: LIMITE DE DADOS EMERGENCIAL (Tensões) | E21: ALISUP OPER
B22: 12 | C22: SEVERIDADE | D22: ALARME OPERACIONAL MUST (95%) | E22: ALISUP OPER MUST
D23: ALARME DE FATOR DE POTÊNCIA | E23: ALIFP
A24: - | B24: 13 | C24: SEVERIDADE | D24: ALARME DE POTÊNCIA (Sobrecarga) | E24: ALISUP EMER/OPER
B25: 14 | C25: SEVERIDADE | D25: Informações dos servidores e máquinas
B26: 15 | C26: SEVERIDADE
A27: - | B27: 16 | C27: SEVERIDADE | D27: RECONHECIMENTO/ARQUIVAMENTO ALARMES

Sheet Information
A1: Signal type | B1: Meas. type | C1: Element | D1: Notes
A2: Custom | B2: (any) | C2: PowerSystemResource | D2: Custom signal types (none of the ADMS-recognized types). Additional enumerations can be used for project-specific purposes, as well as for different message mappings.
A3: Custom1... Custom100
A4: SwitchStatus | B4: SwitchStatus | C4: Switch | D4: Switch or rack status (1=Open, 2=Closed). Initial=Switch.normalValue
A5: Read/Write | C5: PortableCell
A6: Local/Remote | B6: Status | C6: Switch | D6: A switch, tap changer or RTU is switched into local manual control, and cannot be remotely operated (however, its status can be read). (2=Closed=Local, 1=Open=Remote)
A7: Read | C7: CompositeSwitch
C8: TapChanger
C9: RemoteUnit
C10: PortableCell
C11: RegulatingControl
A12: OperationCount | B12: Discrete | C12: Switch | D12: Total count of switch or tap changer operations since last reset. Initial=0
A13: Read | C13: TapChanger
A14: TapPosition | B14: Discrete | C14: TapChanger | D14: Absolute tap position. Initial=TapChanger.neutralStep
A15: Read/Write | C15: PetersenCoil
A16: TapIncrement | B16: Status | C16: TapChanger | D16: Tap position increment: 1/Open=Lower, 2/Close=Raise. Initial=Error=0.
A17: Write | C17: PetersenCoil
A18: Enabled | B18: Status | C18: RegulatingControl | D18: Enabled operation of Sectionalizer, RegulatingControl or RelayStage. (2=Closed=Auto, 1=Open=Manual).
A19: Read/Write | C19: ControlLimit
C20: ControlSettings
C21: ProtectionEquipment
C22: RelayStage
C23: RecloseStage
C24: DistanceRelayStage
C25: Sectionalizer
C26: InterlockingScheme
C27: RegulatingControlGroup
C28: ProtectionGroup
A29: LoadBonus | B29: Status | C29: RegulatingControl | D29: Load bonus activated (2=Closed=On, 1=Open=Off) on a voltage regulator's RegulatingControl. Applicable only when a ControlLimit of type LoadBonus exists.
A30: Read/Write
A31: ReclosingEnabled | B31: Status | C31: ProtectionEquipment (only reclosing) | D31: Enabled (2=Closed) reclosing operation of a ProtectionEquipment which models a reclosing relay.
A32: Read/Write | C32: Breaker
C33: (only reclosing)
A34: RecloserLockout | B34: Status | C34: ProtectionEquipment | D34: Recloser locked out. (1=Open=Not locked, 2=Closed=Locked)
A35: Read | C35: (only reclosing)
A36: ControlActiveSetting | B36: Discrete | C36: RegulatingControl | D36: 1-based index of active relay settings, control settings, or regulating control within a group. Initial=1, except for RegulatingControl where Initial=0 (=ControlSettingType.Normal).
A37: Read/Write | C37: RelayStage
C38: RecloseStage
C39: DistanceRelayStage
C40: ProtectionEquipment
...

Sheet DMS Signal Explanation
A1: MatchingString | B1: DMS Matching template | C1: signalType | D1: measurementType | E1: phaseCode & sideMeasured | G1: signalType | H1: Description | J1: measurementType | K1: Description | M1: PhaseCode | N1: Description | P1: Error Report | S1: Protocols | T1: Unique device | U1: Unique identifier | V1: Choice of Unique device | W1: Choice of Unique identifier | X1: ICCP Point Role | Y1: ICCP INPUT Point Type | Z1: ICCP OUTPUT Point Type | AA1: ICCP Point Scope | AB1: Delete | AC1: Invert In/Out bits | AD1: Point type | AE1: Point category
A2: =CONCATENATE(C2,D2,E2) | B2: SWSABC | C2: SwitchStatus | D2: SwitchStatus | E2: ABC | G2: SwitchStatus | H2: Switch or rack status | J2: SwitchStatus | K2: A discrete signal describing switch status -- open/close/error/transit. | M2: ABC | N2: Phases ABC, side measured : None (No winding is applicable) | P2: Sheet name | Q2: No of errors | S2: DNP_V3.0 | T2: Substation | U2: Name | V2: 1 | W2: 1 | X2: client | Y2: DV_Real | Z2: DEV_Real | AA2: ICC | AC2: yes | AD2: telemetered | AE2: analog
A3: =CONCATENATE(C3,D3,E3) | B3: SWSA | C3: SwitchStatus | D3: SwitchStatus | E3: A | G3: Local | H3: A switch, tap changer or RTU is switched into local manual control, and cannot be remotely operated (however, its status can be read). | J3: Status | K3: A discrete signal with on/off (true/false) value. | M3: A | N3: Phases A, side measured : None (No winding is applicable) | P3: =HYPERLINK("#RTU_IEC104!A1", "RTU_IEC104") | Q3: 1 | S3: IEC 104 | T3: Feeder | U3: Alias | X3: server | Y3: DV_State | Z3: DEV_Command | AA3: VCC | AB3: DELETE | AC3: no | AD3: calculated | AE3: status
A4: =CONCATENATE(C4,D4,E4) | B4: SWSB | C4: SwitchStatus | D4: SwitchStatus | E4: B | G4: OperationCount | H4: Total count of switch or tap changer operations since last reset. | J4: Discrete | K4: A discrete signal with a range of integer values | M4: B | N4: Phases B, side measured : None (No winding is applicable) | S4: ICCP | T4: Feeder Object | X4: client/server | Y4: DV_Discrete | Z4: DEV_Discrete | AD4: manual entry
A5: =CONCATENATE(C5,D5,E5) | B5: SWSC | C5: SwitchStatus | D5: SwitchStatus | E5: C | G5: FaultStatus | H5: Fault current flow is detected (2=Closed) by a fault recorder or fault indicator. | J5: Voltage | K5: Voltage | M5: C | N5: Phases C, side measured : None (No winding is applicable) | T5: Bank | X5: none | Y5: DV_StateSupp | AD5: remote param
A6: =CONCATENATE(C6,D6,E6) | B6: LOCREMABC | C6: Local | D6: Status | E6: ABC | G6: MaxOpCount | H6: Maximal allowed daily count of switch or tap changer operations. If zero, VVO uses value specified in the profile. | J6: VoltageAngle | K6: Voltage angle. Typically, this is not a physical measurement but a pseudo-measurement imported from e.g. EMS estimator. | M6: AB | N6: Phases AB, side measured : None (No winding is applicable) | T6: Bay | Y6: DV_RealQuality
A7: =CONCATENATE(C7,D7,E7) | B7: LOCREMA | C7: Local | D7: Status | E7: A | G7: HourlyOpCount | H7: Hourly count (since x:00 min) of switch or tap changer operations. Initial=0 | J7: Frequency | K7: Frequency | M7: BC | N7: Phases BC, side measured : None (No winding is applicable) | Y7: DV_StateQuality
A8: =CONCATENATE(C8,D8,E8) | B8: LOCREMB | C8: Local | D8: Status | E8: B | G8: DailyOpCount | H8: Daily count (since midnight) of switch or tap changer operations. Initial=0 | J8: RelativeVoltage | K8: Voltage expressed as relative value of base voltage. Default unit is %, other applicable units are p.u and base 120 | M8: AC | N8: Phases AC, side measured : None (No winding is applicable) | Y8: DV_DiscreteQuality
A9: =CONCATENATE(C9,D9,E9) | B9: LOCREMC | C9: Local | D9: Status | E9: C | G9: MonthlyOpCount | H9: Monthly count (since 1st) of switch or tap changer operations. Initial=0 | J9: Current | K9: Current | M9: ABCPrimary | N9: Phases ABC, side measured : Primary (first terminal) | Y9: DV_StateSuppQuality
A10: =CONCATENATE(C10,D10,E10) | B10: OPCNTABC | C10: OperationCount | D10: Discrete | E10: ABC | G10: PowerOn | H10: Indicates presence or absence of voltage at the sensor location. | J10: ActivePower | K10: Active power | M10: ABPrimary | N10: Phases AB, side measured : Primary (first terminal) | Y10: DV_RealQualityTimeTag
A11: =CONCATENATE(C11,D11,E11) | B11: OPCNTA | C11: OperationCount | D11: Discrete | E11: A | G11: Forward | H11: For directable devices, specifies that the current or power flows in "forward" (usually, downstream) direction. | J11: ApparentPower | K11: Apparent power | M11: BCPrimary | N11: Phases BC, side measured : Primary (first terminal) | Y11: DV_StateQualityTimeTag
A12: =CONCATENATE(C12,D12,E12) | B12: OPCNTB | C12: OperationCount | D12: Discrete | E12: B | G12: HotLineTag | H12: For reclosers, specifies that both automatic and manual reclosing are disabled | J12: CosPhi | K12: Power factor (cos(phi)) | M12: ACPrimary | N12: Phases AC, side measured : Primary (first terminal) | Y12: DV_DiscreteQualityTimeTag
A13: =CONCATENATE(C13,D13,E13) | B13: OPCNTC | C13: OperationCount | D13: Discrete | E13: C | G13: DiscreteSignalType.Custom | H13: A custom type (none of the DMS recognized types) | J13: ActiveEnergy | K13: Active energy | M13: APrimary | N13: Phases A, side measured : Primary (first terminal) | Y13: DV_StateSuppQualityTimeTag
A14: =CONCATENATE(C14,D14,E14) | B14: FLTSTABC | C14: FaultStatus | D14: Status | E14: ABC | G14: MeasuredValue | H14: An analog measured value. | J14: ReactiveEnergy | K14: Reactive energy | M14: BPrimary | N14: Phases B, side measured : Primary (first terminal) | Y14: DV_RealExtended
A15: =CONCATENATE(C15,D15,E15) | B15: FLTSTA | C15: FaultStatus | D15: Status | E15: A | G15: FaultRecorder | H15: Recorded value of fault current or voltage | J15: CurrentAngle | K15: Current angle provided from fault recorder or IEDs. Default unit is degree. | M15: CPrimary | N15: Phases C, side measured : Primary (first terminal) | Y15: DV_StateExtended
A16: =CONCATENATE(C16,D16,E16) | B16: FLTSTB | C16: FaultStatus | D16: Status | E16: B | G16: AnalogSignalType.Custom | H16: A custom type (none of the DMS recognized types) | J16: Temperature | K16: Temperature [°C] of an element (for equipment) or of air (for a weather region) | M16: ABCSecondary | N16: Phases ABC, side measured : Secondary (second terminal) | Y16: DV_DiscreteExtended
A17: =CONCATENATE(C17,D17,E17) | B17: FLTSTC | C17: FaultStatus | D17: Status | E17: C | G17: Enabled | H17: Enabled operation of Sectionalizer, RegulatingControl or RelayStage | J17: Unitless | K17: An analog quantity which is unitless, or not otherwise in the list of supported types | M17: ABSecondary | N17: Phases AB, side measured : Secondary (second terminal) | Y17: DV_StateSuppExtended
A18: =CONCATENATE(C18,D18,E18) | B18: MAXOPCNTABC | C18: MaxOpCount | D18: Discrete | E18: ABC | G18: TapPosition | H18: Absolute tap position | J18: ReactivePower | K18: Reactive power | M18: BCSecondary | N18: Phases BC, side measured : Secondary (second terminal) | Y18: DV_RealQualityTimeTagExtended
... A21: =CONCATENATE(C21,D21,E21) | B21: MAXOPCNTC | C21: MaxOpCount | D21: Discrete | E21: C | G21: ReverseMode | H21: Voltage regulators only: Indicates how the regulator behaves in case of reverse power flow | J21: WindSpeed | K21: Wind speed [km/h] | M21: BSecondary | N21: Phases B, side measured : Secondary (second terminal) | Y21: DV_StateSuppQualityTimeTagExtended
A22: =CONCATENATE(C22,D22,E22) | B22: HOUROPCNTABC | C22: HourlyOpCount | D22: Discrete | E22: ABC | G22: Parallel | H22: A voltage regulator is in parallel (slave) operation with another regulator | J22: FeelsLike | K22: Feels like: Equivalent temperature [°C] | M22: CSecondary | N22: Phases C, side measured : Secondary (second terminal)
A23: =CONCATENATE(C23,D23,E23) | B23: HOUROPCNTA | C23: HourlyOpCount | D23: Discrete | E23: A | G23: ControlActiveSetting | H23: Active setting of a relay stage or regulating control. | J23: SunshineMinutes | K23: Sunshine minutes per hour | M23: ABCTertiary | N23: Phases ABC, side measured : Tertiary (applicable on three winding transformer only)
A24: =CONCATENATE(C24,D24,E24) | B24: HOUROPCNTB | C24: HourlyOpCount | D24: Discrete | E24: B | G24: ControlDelay | H24: Initial delay of a regulating control or relay stage | J24: SkyCover | K24: Sky cover [%] | M24: ATertiary | N24: Phases A, side measured : Tertiary (applicable on three winding transformer only)
A25: =CONCATENATE(C25,D25,E25) | B25: HOUROPCNTC | C25: HourlyOpCount | D25: Discrete | E25: C | G25: ControlLimitHigh | H25: High value of a ControlLimit | J25: Length | K25: Physical length | M25: BTertiary | N25: Phases B, side measured : Tertiary (applicable on three winding transformer only)
A26: =CONCATENATE(C26,D26,E26) | B26: DAILYPCNTABC | C26: DailyOpCount | D26: Discrete | E26: ABC | G26: ControlLimitLow | H26: Low value of a ControlLimit | J26: CrossSection | K26: CrossSection | M26: CTertiary | N26: Phases C, side measured : Tertiary (applicable on three winding transformer only)
A27: =CONCATENATE(C27,D27,E27) | B27: DAILYOPCNTA | C27: DailyOpCount | D27: Discrete | E27: A | G27: ControlSetValue | H27: Set point (target) of a RegulatingControl or RelayStage. | J27: Impedance | K27: Impedance, resistance or reactance [Ω] | M27: N | N27: Neutral
A28: =CONCATENATE(C28,D28,E28) | B28: DAILYOPCNTB | C28: DailyOpCount | D28: Discrete | E28: B | G28: ControlBandwidth | H28: Bandwidth of a regulating control. The type must be the same as in the corresponding ControlSetValue signal | J28: Admittance | K28: Admittance, conductance or susceptance [S] | M28: NPrimary | N28: Neutral, side measured : Primary (first terminal)
A29: =CONCATENATE(C29,D29,E29) | B29: DAILYOPCNTC | C29: DailyOpCount | D29: Discrete | E29: C | G29: ControlSubDelay | H29: Subsequent delay of a regulating control | J29: ImpedancePerLength | K29: Impedance, resistance or reactance per unit length [Ω/km] | M29: NSecondary | N29: Neutral, side measured : Secondary (second terminal)
A30: =CONCATENATE(C30,D30,E30) | B30: MONTOPCNTABC | C30: MonthlyOpCount | D30: Discrete | E30: ABC | G30: ControlSlopeReal | H30: Real compensation | J30: AdmittancePerLength | K30: Admittance, conductance or susceptance per unit length [S/km] | M30: Ntertiary | N30: Neutral, side measured : Tertiary (applicable on three winding transformer only)
A31: =CONCATENATE(C31,D31,E31) | B31: MONTOPCNTA | C31: MonthlyOpCount | D31: Discrete | E31: A | G31: ControlSlopeImag | H31: Imaginary compensation | J31: Percent | K31: A percentage value
A32: =CONCATENATE(C32,D32,E32) | B32: MONTOPCNTB | C32: MonthlyOpCount | D32: Discrete | E32: B | G32: RelayTrip | H32: Indicates that a particular relay recorded a fault and caused the breaker to trip | J32: Money | K32: Money unit. The unit symbol is taken from system locale information.
A33: =CONCATENATE(C33,D33,E33) | B33: MONTOPCNTC | C33: MonthlyOpCount | D33: Discrete | E33: C | G33: ReclosingEnabled | H33: Enabled reclosing operation on a ProtectionEquipment | J33: Insolation | K33: Insolation
A34: =CONCATENATE(C34,D34,E34) | B34: PWRONABC | C34: PowerOn | D34: Status | E34: ABC | G34: RecloserLockout | H34: Recloser locked out | J34: RotationSpeed | K34: Speed of a rotational machine
A35: =CONCATENATE(C35,D35,E35) | B35: PWRONA | C35: PowerOn | D35: Status | E35: A | G35: RecloseDelay | H35: Reclosing delay of a reclosing relay stage | J35: Mass | K35: Mass
A36: =CONCATENATE(C36,D36,E36) | B36: PWRONB | C36: PowerOn | D36: Status | E36: B | G36: UnderFrequencyAlarm | H36: An underfrequency alarm was issued for the substation. | J36: FailureRate | K36: Annual number of faults
A37: =CONCATENATE(C37,D37,E37) | B37: PWRONC | C37: PowerOn | D37: Status | E37: C | G37: FanStatus | H37: Status of transformer's cooling fan | J37: SoilTemperature | K37: Soil temperature [°C] at 1m depth. Used for default weather on WeatherRegion.
A38: =CONCATENATE(C38,D38,E38) | B38: FRWRDABC | C38: Forward | D38: Status | E38: ABC | G38: OilPumpStatus | H38: Status of transformer's cooling oil pump | J38: OilTemperature | K38: Oil temperature [°C] of a PowerTransformer.
A39: =CONCATENATE(C39,D39,E39) | B39: FRWRDA | C39: Forward | D39: Status | E39: A | G39: SourceStatus | H39: Energization status of an EnergySource or Interconnection | J39: HotSpotTemperature | K39: Temperature [°C] of a hotspot on a PowerTransformer winding.
A40: =CONCATENATE(C40,D40,E40) | B40: FRWRDB | C40: Forward | D40: Status | E40: B | G40: FaultCurrentSub | H40: Value of subtransient fault current at source, calculated by an external (EMS) system. | J40: AbsoluteDateTime | K40: Date and time expressed in absolute terms. Internally stored as Windows filetime (number of 100-nanosecond since midnight, January 1, 1601 UTC)
A41: =CONCATENATE(C41,D41,E41) | B41: FRWRDC | C41: Forward | D41: Status | E41: C | G41: FaultAngleSub | H41: Angle of subtransient fault current at source, calculated by an external (EMS) system. | J41: LatLong | K41: A pair of latitude/longitude coordinates expressed in degrees
A42: =CONCATENATE(C42,D42,E42) | B42: HLTAGABC | C42: HotLineTag | D42: Status | E42: ABC | G42: FaultCurrentTrans | H42: Value of subtransient fault current at source, calculated by an external (EMS) system.
...

Sheet Message Mapping
A1: Name | B1: Alias | C1: State (Message) | D1: Value | E1: SCADA Value | F1: Commanding message | G1: Color | H1: Abnormal Status | I1: Allow Manual Override | J1: Alarm Catalog | K1: Coluna1 | L1: Severidade
A2: DI_null@null___NORMAL@ATUADO___RelayTrip___INV_S_TS_SEV1 | C2: Transit;NORMAL;ATUADO;Error | D2: 0;1;2;3 | E2: 2;1;0;3 | F2: ;;; | G2: #FF000000;#FF00FF00;#FFFF0000;#FFA9A9A9 | H2: Normal;Normal;Abnormal;Normal | I2: FALSE;TRUE;TRUE;FALSE | J2: Alarme de Estado em Ponto Telessinalizado SEV1 | K2: Alarme de Estado em Ponto Telessinalizado SEV1 | L2: =VLOOKUP(LinkTable6789[[#This Row],[Coluna1]],[4]AlarmCatalog!$A:$M,11,FALSE)
A3: DI_null@null___NORMAL@ATUADO___Custom_S_TS_SEV1 | C3: Transit;NORMAL;ATUADO;Error | D3: 0;1;2;3 | E3: 2;0;1;3 | F3: ;;; | G3: #FF000000;#FF00FF00;#FFFF0000;#FFA9A9A9 | H3: Normal;Normal;Abnormal;Normal | I3: FALSE;TRUE;TRUE;FALSE | J3: Alarme de Estado em Ponto Telessinalizado SEV1 | K3: Alarme de Estado em Ponto Telessinalizado SEV1 | L3: =VLOOKUP(LinkTable6789[[#This Row],[Coluna1]],[4]AlarmCatalog!$A:$M,11,FALSE)
A4: DI_null@null___NORMAL@ATUADO___RelayTrip_S_TS_SEV1 | C4: Transit;NORMAL;ATUADO;Error | D4: 0;1;2;3 | E4: 2;0;1;3 | F4: ;;; | G4: #FF000000;#FF00FF00;#FFFF0000;#FFA9A9A9 | H4: Normal;Normal;Abnormal;Normal | I4: FALSE;TRUE;TRUE;FALSE | J4: Alarme de Estado em Ponto Telessinalizado SEV1 | K4: Alarme de Estado em Ponto Telessinalizado SEV1 | L4: =VLOOKUP(LinkTable6789[[#This Row],[Coluna1]],[4]AlarmCatalog!$A:$M,11,FALSE)
A5: DI_INCLUIR@EXCLUIR___INCLUIDO@EXCLUIDO___Custom___INV_S_TC | C5: Transit;INCLUIDO;EXCLUIDO;Error | D5: 0;1;2;3 | E5: 2;1;0;3 | F5: ;INCLUIR;EXCLUIR; | G5: #FF000000;#FFFF0000;#FF00FF00;#FFA9A9A9 | H5: Abnormal;Auto;Auto;Abnormal | I5: FALSE;TRUE;TRUE;FALSE | J5: Alarme de Estado em Ponto Telecontrolado | K5: Alarme de Estado em Ponto Telecontrolado | L5: =VLOOKUP(LinkTable6789[[#This Row],[Coluna1]],[4]AlarmCatalog!$A:$M,11,FALSE)
A6: DI_INCLUIR@EXCLUIR___INCLUIDO@EXCLUIDO___Custom___INV_S_TC_DS | C6: Transit;INCLUIDO;EXCLUIDO;Error | D6: 0;1;2;3 | E6: 2;1;0;3 | F6: ;INCLUIR;EXCLUIR; | G6: #FF000000;#FFFF0000;#FF00FF00;#FFA9A9A9 | H6: Abnormal;Auto;Auto;Abnormal | I6: FALSE;TRUE;TRUE;FALSE | J6: Alarme de Estado em Ponto Telecontrolado DS | K6: Alarme de Estado em Ponto Telecontrolado DS | L6: =VLOOKUP(LinkTable6789[[#This Row],[Coluna1]],[4]AlarmCatalog!$A:$M,11,FALSE)
A7: LIGAR@null___DESLIGADO@LIGADO___SwitchStatus_D_TC | C7: Error;DESLIGADO;LIGADO;Transit | D7: 0;1;2;3 | E7: 1;0;2;3 | F7: ;LIGAR;null; | G7: #FF000000;#FF00FF00;#FFFF0000;#FFA9A9A9 | H7: Abnormal;Abnormal;Normal;Normal | I7: FALSE;TRUE;TRUE;FALSE | J7: Alarme de Estado em Ponto Telecontrolado | K7: Alarme de Estado em Ponto Telecontrolado | L7: =VLOOKUP(LinkTable6789[[#This Row],[Coluna1]],[4]AlarmCatalog!$A:$M,11,FALSE)
A8: DI_INCLUIR@EXCLUIR___INCLUIDO@EXCLUIDO___Custom___INV_S_TC_DS_AUTO | C8: Transit;INCLUIDO;EXCLUIDO;Error | D8: 0;1;2;3 | E8: 2;1;0;3 | F8: ;INCLUIR;EXCLUIR; | G8: #FF000000;#FFFF0000;#FF00FF00;#FFA9A9A9 | H8: Abnormal;Normal;Normal;Abnormal | I8: FALSE;TRUE;TRUE;FALSE | J8: Alarme de Estado em Ponto Telecontrolado DS | K8: Alarme de Estado em Ponto Telecontrolado DS | L8: =VLOOKUP(LinkTable6789[[#This Row],[Coluna1]],[4]AlarmCatalog!$A:$M,11,FALSE)
A9: DI_INCLUIR@EXCLUIR___INCLUIDO@EXCLUIDO___Enabled___admsINV_S_TC_DS | C9: Transit;INCLUIDO;EXCLUIDO;Error | D9: 0;2;1;3 | E9: 2;0;1;3 | F9: ;INCLUIR;EXCLUIR; | G9: #FF000000;#FFFF0000;#FF00FF00;#FFA9A9A9 | H9: Abnormal;Auto;Auto;Abnormal | I9: FALSE;TRUE;TRUE;FALSE | J9: Alarme de Estado em Ponto Telecontrolado DS | K9: Alarme de Estado em Ponto Telecontrolado DS | L9: =VLOOKUP(LinkTable6789[[#This Row],[Coluna1]],[4]AlarmCatalog!$A:$M,11,FALSE)
A10: ABRIR@null___ABERTO@FECHADO___SwitchStatus_D_TC | C10: Error;ABERTO;FECHADO;Transit | D10: 0;1;2;3 | E10: 1;0;2;3 | F10: ;ABRIR;null; | G10: #FF000000;#FF00FF00;#FFFF0000;#FFA9A9A9 | H10: Abnormal;Auto;Auto;Abnormal | I10: FALSE;TRUE;TRUE;FALSE | J10: Alarme de Estado em Ponto Telecontrolado | K10: Alarme de Estado em Ponto Telecontrolado | L10: =VLOOKUP(LinkTable6789[[#This Row],[Coluna1]],[4]AlarmCatalog!$A:$M,11,FALSE)
A11: DI_INCLUIR@EXCLUIR___INCLUIDO@EXCLUIDO___Enabled___admsINV_S_TC_DS_SGF_DESAB | C11: Transit;INCLUIDO;EXCLUIDO;Error | D11: 0;2;1;3 | E11: 2;0;1;3 | F11: ;INCLUIR;EXCLUIR; | G11: #FF000000;#FFFF0000;#FF00FF00;#FFA9A9A9 | H11: Abnormal;Normal;Normal;Abnormal | I11: FALSE;TRUE;TRUE;FALSE | J11: Alarme de Estado em Ponto Telecontrolado DS | K11: Alarme de Estado em Ponto Telecontrolado DS | L11: =VLOOKUP(LinkTable6789[[#This Row],[Coluna1]],[4]AlarmCatalog!$A:$M,11,FALSE)
A12: LIGAR@null___DESLIGADO@LIGADO___Custom_S_TC | C12: Error;DESLIGADO;LIGADO;Transit | D12: 0;1;2;3 | E12: 1;0;2;3 | F12: ;LIGAR;null; | G12: #FF000000;#FF00FF00;#FFFF0000;#FFA9A9A9 | H12: Normal;Normal;Normal;Normal | I12: FALSE;TRUE;TRUE;FALSE | J12: Alarme de Estado em Ponto Telecontrolado | K12: Alarme de Estado em Ponto Telecontrolado | L12: =VLOOKUP(LinkTable6789[[#This Row],[Coluna1]],[4]AlarmCatalog!$A:$M,11,FALSE)
A13: DI_INCLUIR@EXCLUIR___INCLUIDO@EXCLUIDO___Enabled___admsINV_S_TC_DS_SGF_INC | C13: Transit;INCLUIDO;EXCLUIDO;Error | D13: 0;2;1;3 | E13: 2;0;1;3 | F13: ;INCLUIR;EXCLUIR; | G13: #FF000000;#FFFF0000;#FF00FF00;#FFA9A9A9 | H13: Abnormal;Normal;Abnormal;Abnormal | I13: FALSE;TRUE;TRUE;FALSE | J13: Alarme de Estado em Ponto Telecontrolado DS | K13: Alarme de Estado em Ponto Telecontrolado DS | L13: =VLOOKUP(LinkTable6789[[#This Row],[Coluna1]],[4]AlarmCatalog!$A:$M,11,FALSE)
... A256: null@null___NORMAL@BLOQUEADA___Enabled___INV_S_TS | C256: Transit;NORMAL;BLOQUEADA;Error | D256: 0;1;2;3 | E256: 2;1;0;3 | F256: ;;; | G256: #FF000000;#FF00FF00;#FFFF0000;#FFA9A9A9 | H256: Abnormal;Auto;Auto;Abnormal | I256: FALSE;TRUE;TRUE;FALSE | J256: Alarme de Estado em Ponto Telessinalizado | K256: Alarme de Estado em Ponto Telessinalizado | L256: =VLOOKUP(LinkTable6789[[#This Row],[Coluna1]],[4]AlarmCatalog!$A:$M,11,FALSE)
A257: Habilitar LF | C257: LF Desabilitado;Somente LF Habilitado;LF e ES Habilitados | D257: 0;1;2 | E257: 0;1;2 | F257: Desabilitar LF;Habilitar somente LF;Habilitar LF e ES | G257: #00000000;#00F30C0C;#00000000 | H257: Normal;Normal;Normal | I257: TRUE;TRUE;TRUE | L257: =VLOOKUP(LinkTable6789[[#This Row],[Coluna1]],[4]AlarmCatalog!$A:$M,11,FALSE)
A258: null@null___NORMAL@INIBIDO___Custom___INV_S_TS | C258: Transit;NORMAL;INIBIDO;Error | D258: 0;1;2;3 | E258: 2;1;0;3 | F258: ;;; | G258: #FF000000;#FF00FF00;#FFFF0000;#FFA9A9A9 | H258: Abnormal;Auto;Auto;Abnormal | I258: FALSE;TRUE;TRUE;FALSE | J258: Alarme de Estado em Ponto Telessinalizado | K258: Alarme de Estado em Ponto Telessinalizado | L258: =VLOOKUP(LinkTable6789[[#This Row],[Coluna1]],[4]AlarmCatalog!$A:$M,11,FALSE)
A259: null@null___@___TapIncrement_D_TS | C259: Transit;null;null;Error | D259: 0;1;2;3 | E259: 2;0;1;3 | F259: ;;; | G259: #FF000000;#FF00FF00;#FFFF0000;#FFA9A9A9 | H259: Normal;Normal;Normal;Normal | I259: FALSE;TRUE;TRUE;FALSE | J259: Alarme de Estado em Ponto Telessinalizado | K259: Alarme de Estado em Ponto Telessinalizado | L259: =VLOOKUP(LinkTable6789[[#This Row],[Coluna1]],[4]AlarmCatalog!$A:$M,11,FALSE)
A260: null@null___MANUAL@AUTOMATICO___Custom___INV_S_TS | C260: Transit;MANUAL;AUTOMATICO;Error | D260: 0;1;2;3 | E260: 2;1;0;3 | F260: ;;; | G260: #FF000000;#FF00FF00;#FFFF0000;#FFA9A9A9 | H260: Normal;Normal;Normal;Normal | I260: FALSE;TRUE;TRUE;FALSE | J260: Alarme de Estado em Ponto Telessinalizado | K260: Alarme de Estado em Ponto Telessinalizado | L260: =VLOOKUP(LinkTable6789[[#This Row],[Coluna1]],[4]AlarmCatalog!$A:$M,11,FALSE)
A261: MESTRE@INDIVIDUAL@COMANDO___MESTRE@INDIVIDUAL@COMANDO___Parallel_D_TS_SS | C261: MESTRE;INDIVIDUAL;COMANDADO; | D261: 2;0;1;3 | E261: 0;2;1;3 | F261: MESTRE;INDIVIDUAL;COMANDO; | G261: #FFFF0000;#FF00FF00;#FF00FF00;#FF000000 | H261: Normal;Abnormal;Abnormal;Abnormal | I261: TRUE;TRUE;TRUE;FALSE | J261: Alarme de Estado em Ponto Telessinalizado SS | K261: Alarme de Estado em Ponto Telessinalizado SS | L261: =VLOOKUP(LinkTable6789[[#This Row],[Coluna1]],[4]AlarmCatalog!$A:$M,11,FALSE)
A262: null@null___ATIVOU@INIBIU___Custom_S_TS | C262: Transit;ATIVOU;INIBIU;Error | D262: 0;1;2;3 | E262: 2;0;1;3 | F262: ;;; | G262: #FF000000;#FF00FF00;#FFFF0000;#FFA9A9A9 | H262: Abnormal;Auto;Auto;Abnormal | I262: FALSE;TRUE;TRUE;FALSE | J262: Alarme de Estado em Ponto Telessinalizado | K262: Alarme de Estado em Ponto Telessinalizado | L262: =VLOOKUP(LinkTable6789[[#This Row],[Coluna1]],[4]AlarmCatalog!$A:$M,11,FALSE)
A263: null@null___NORMAL@INCOMPLETA___Custom_S_TS | C263: Transit;NORMAL;INCOMPLETA;Error | D263: 0;1;2;3 | E263: 2;0;1;3 | F263: ;;; | G263: #FF000000;#FF00FF00;#FFFF0000;#FFA9A9A9 | H263: Abnormal;Auto;Auto;Abnormal | I263: FALSE;TRUE;TRUE;FALSE | J263: Alarme de Estado em Ponto Telessinalizado | K263: Alarme de Estado em Ponto Telessinalizado | L263: =VLOOKUP(LinkTable6789[[#This Row],[Coluna1]],[4]AlarmCatalog!$A:$M,11,FALSE)
A264: null@null___FALHA@OPERANDO___Custom___INV_S_TS | C264: Transit;FALHA;OPERANDO;Error | D264: 0;1;2;3 | E264: 2;1;0;3 | F264: ;;; | G264: #FF000000;#FF00FF00;#FFFF0000;#FFA9A9A9 | H264: Abnormal;Auto;Auto;Abnormal | I264: FALSE;TRUE;TRUE;FALSE | J264: Alarme de Estado em Ponto Telessinalizado | K264: Alarme de Estado em Ponto Telessinalizado | L264: =VLOOKUP(LinkTable6789[[#This Row],[Coluna1]],[4]AlarmCatalog!$A:$M,11,FALSE)
A265: null@null___POSICAO 1@POSICAO 2___Custom_S_TS | C265: Transit;POSICAO 1;POSICAO 2;Error | D265: 0;1;2;3 | E265: 2;0;1;3 | F265: ;;; | G265: #FF000000;#FF00FF00;#FFFF0000;#FFA9A9A9 | H265: Abnormal;Auto;Auto;Abnormal | I265: FALSE;TRUE;TRUE;FALSE | J265: Alarme de Estado em Ponto Telessinalizado | K265: Alarme de Estado em Ponto Telessinalizado | L265: =VLOOKUP(LinkTable6789[[#This Row],[Coluna1]],[4]AlarmCatalog!$A:$M,11,FALSE)
A266: null@null___DESLIGADA@LIGADA___Custom___INV_S_TS | C266: Transit;DESLIGADA;LIGADA;Error | D266: 0;1;2;3 | E266: 2;1;0;3 | F266: ;;; | G266: #FF000000;#FF00FF00;#FFFF0000;#FFA9A9A9 | H266: Abnormal;Auto;Auto;Abnormal | I266: FALSE;TRUE;TRUE;FALSE | J266: Alarme de Estado em Ponto Telessinalizado | K266: Alarme de Estado em Ponto Telessinalizado | L266: =VLOOKUP(LinkTable6789[[#This Row],[Coluna1]],[4]AlarmCatalog!$A:$M,11,FALSE)
A267: null@null___NORMAL@ATUADO___RecloserLockout_S_TS_SA | C267: Transit;NORMAL;ATUADO;Error | D267: 0;1;2;3 | E267: 2;0;1;3 | F267: ;;; | G267: #FF000000;#FF00FF00;#FFFF0000;#FFA9A9A9 | H267: Abnormal;Auto;Auto;Abnormal | I267: FALSE;TRUE;TRUE;FALSE | J267: Alarme de Estado em Ponto Telessinalizado | K267: Alarme de Estado em Ponto Telessinalizado | L267: =VLOOKUP(LinkTable6789[[#This Row],[Coluna1]],[4]AlarmCatalog!$A:$M,11,FALSE)
A268: DI_INCLUIR@EXCLUIR___INCLUIDO@EXCLUIDO___ReclosingEnabled_S_TC | C268: Transit;INCLUIDO;EXCLUIDO;Error | D268: 0;1;2;3 | E268: 2;0;1;3 | F268: ;INCLUIR;EXCLUIR; | G268: #FF000000;#FFFF0000;#FF00FF00;#FFA9A9A9 | H268: Abnormal;Auto;Auto;Abnormal | I268: FALSE;TRUE;TRUE;FALSE | J268: Alarme de Estado em Ponto Telecontrolado | K268: Alarme de Estado em Ponto Telecontrolado | L268: =VLOOKUP(LinkTable6789[[#This Row],[Coluna1]],[4]AlarmCatalog!$A:$M,11,FALSE)
A269: null@null___0@EXECUTADO___Custom_S_TS | C269: Transit;0;EXECUTADO;Error | D269: 0;1;2;3 | E269: 2;0;1;3 | F269: ;;; | G269: #FF000000;#FF00FF00;#FFFF0000;#FFA9A9A9 | H269: Abnormal;Auto;Auto;Abnormal | I269: FALSE;TRUE;TRUE;FALSE | J269: Alarme de Estado em Ponto Telessinalizado | K269: Alarme de Estado em Ponto Telessinalizado | L269: =VLOOKUP(LinkTable6789[[#This Row],[Coluna1]],[4]AlarmCatalog!$A:$M,11,FALSE)
... A337: null@null___NORMAL@ATUADO___Custom_S_TC_SA | C337: Transit;NORMAL;ATUADO;Error | D337: 0;1;2;3 | E337: 2;0;1;3 | F337: ;;; | G337: #FF000000;#FF00FF00;#FFFF0000;#FFA9A9A9 | H337: Abnormal;Auto;Auto;Abnormal | I337: FALSE;TRUE;TRUE;FALSE | J337: Alarme de Estado em Ponto Telecontrolado SA | K337: Alarme de Estado em Ponto Telecontrolado SA | L337: =VLOOKUP(LinkTable6789[[#This Row],[Coluna1]],[4]AlarmCatalog!$A:$M,11,FALSE)
A338: null@null___DESINIBIDA@INIBIDA___Custom_S_TS_SA | C338: Transit;DESINIBIDA;INIBIDA;Error | D338: 0;1;2;3 | E338: 2;0;1;3 | F338: ;;; | G338: #FF000000;#FF00FF00;#FFFF0000;#FFA9A9A9 | H338: Abnormal;Auto;Auto;Abnormal | I338: FALSE;TRUE;TRUE;FALSE | K338: Alarme de Estado em Ponto Telessinalizado SA | L338: =VLOOKUP(LinkTable6789[[#This Row],[Coluna1]],[4]AlarmCatalog!$A:$M,11,FALSE)
A339: null@null___LIGADO@DESLIGADO___Custom_S_TS_SA | C339: Transit;LIGADO;DESLIGADO;Error | D339: 0;1;2;3 | E339: 2;0;1;3 | F339: ;;; | G339: #FF000000;#FF00FF00;#FFFF0000;#FFA9A9A9 | H339: Abnormal;Auto;Auto;Abnormal | I339: FALSE;TRUE;TRUE;FALSE | J339: Alarme de Estado em Ponto Telessinalizado SA | K339: Alarme de Estado em Ponto Telessinalizado SA | L339: =VLOOKUP(LinkTable6789[[#This Row],[Coluna1]],[4]AlarmCatalog!$A:$M,11,FALSE)
A340: null@null___DESATRACADO@ATRACADO___Custom___INV_S_TS_SA | C340: Transit;DESATRACADO;ATRACADO;Error | D340: 0;1;2;3 | E340: 2;1;0;3 | F340: ;;; | G340: #FF000000;#FF00FF00;#FFFF0000;#FFA9A9A9 | H340: Abnormal;Auto;Auto;Abnormal | I340: FALSE;TRUE;TRUE;FALSE | J340: Alarme de Estado em Ponto Telessinalizado SA | K340: Alarme de Estado em Ponto Telessinalizado SA | L340: =VLOOKUP(LinkTable6789[[#This Row],[Coluna1]],[4]AlarmCatalog!$A:$M,11,FALSE)
A341: null@null___NORMALIZADO@TENSAO RETORNO___Custom_S_TS_SA | C341: Transit;NORMALIZADO;TENSAO RETORNO;Error | D341: 0;1;2;3 | E341: 2;0;1;3 | F341: ;;; | G341: #FF000000;#FF00FF00;#FFFF0000;#FFA9A9A9 | H341: Abnormal;Auto;Auto;Abnormal | I341: FALSE;TRUE;TRUE;FALSE | J341: Alarme de Estado em Ponto Telessinalizado SA | K341: Alarme de Estado em Ponto Telessinalizado SA | L341: =VLOOKUP(LinkTable6789[[#This Row],[Coluna1]],[4]AlarmCatalog!$A:$M,11,FALSE)
A342: null@null___NORMAL@ATUADO___RelayTrip___INV_S_TS_SA | C342: Transit;NORMAL;ATUADO;Error | D342: 0;1;2;3 | E342: 2;1;0;3 | F342: ;;; | G342: #FF000000;#FF00FF00;#FFFF0000;#FFA9A9A9 | H342: Abnormal;Auto;Auto;Abnormal | I342: FALSE;TRUE;TRUE;FALSE | J342: Alarme de Estado em Ponto Telessinalizado SA | K342: Alarme de Estado em Ponto Telessinalizado SA | L342: =VLOOKUP(LinkTable6789[[#This Row],[Coluna1]],[4]AlarmCatalog!$A:$M,11,FALSE)
A343: RELIGADOR@ALTERNATIVO___null@null___Custom_S_TC_SA | C343: Transit;;;Error | D343: 0;1;2;3 | E343: 2;0;1;3 | F343: ;RELIGADOR;ALTERNATIVO; | G343: #FF000000;#FF00FF00;#FFFF0000;#FFA9A9A9 | H343: Normal;Normal;Normal;Normal | I343: FALSE;TRUE;TRUE;FALSE | J343: Alarme de Estado em Ponto Telecontrolado SA | K343: Alarme de Estado em Ponto Telecontrolado SA | L343: =VLOOKUP(LinkTable6789[[#This Row],[Coluna1]],[4]AlarmCatalog!$A:$M,11,FALSE)
A344: null@null___NORMAL@INTERMITENTE___Custom_S_TS_SA | C344: Transit;NORMAL;INTERMITENTE;Error | D344: 0;1;2;3 | E344: 2;0;1;3 | F344: ;;; | G344: #FF000000;#FF00FF00;#FFFF0000;#FFA9A9A9 | H344: Abnormal;Auto;Auto;Abnormal | I344: FALSE;TRUE;TRUE;FALSE | J344: Alarme de Estado em Ponto Telessinalizado SA | K344: Alarme de Estado em Ponto Telessinalizado SA | L344: =VLOOKUP(LinkTable6789[[#This Row],[Coluna1]],[4]AlarmCatalog!$A:$M,11,FALSE)
A345: null@null___DESABILITADO@HABILITADO___Custom6_S_TS | C345: Transit;DESABILITADO;HABILITADO;Error | D345: 0;1;2;3 | E345: 2;0;1;3 | F345: ;;; | G345: #FF000000;#FF00FF00;#FFFF0000;#FFA9A9A9 | H345: Normal;Normal;Normal;Normal | I345: FALSE;TRUE;TRUE;FALSE | J345: Alarme de Estado em Ponto Telessinalizado | K345: Alarme de Estado em Ponto Telessinalizado | L345: =VLOOKUP(LinkTable6789[[#This Row],[Coluna1]],[4]AlarmCatalog!$A:$M,11,FALSE)
A346: null@null___CARREGADA@DESCARREGADA___Custom_S_TS_SA | C346: Transit;CARREGADA;DESCARREGADA;Error | D346: 0;1;2;3 | E346: 2;0;1;3 | F346: ;;; | G346: #FF000000;#FF00FF00;#FFFF0000;#FFA9A9A9 | H346: Abnormal;Auto;Auto;Abnormal | I346: FALSE;TRUE;TRUE;FALSE | J346: Alarme de Estado em Ponto Telessinalizado SA | K346: Alarme de Estado em Ponto Telessinalizado SA | L346: =VLOOKUP(LinkTable6789[[#This Row],[Coluna1]],[4]AlarmCatalog!$A:$M,11,FALSE)
A347: null@null___NORMAL@ATUADO___RelayTrip_D_TS_SA | C347: Transit;NORMAL;ATUADO;Error | D347: 0;1;2;3 | E347: 2;0;1;3 | F347: ;;; | G347: #FF000000;#FF00FF00;#FFFF0000;#FFA9A9A9 | H347: Abnormal;Normal;Normal;Normal | I347: FALSE;TRUE;TRUE;FALSE | J347: Alarme de Estado em Ponto Telessinalizado SA | K347: Alarme de Estado em Ponto Telessinalizado SA | L347: =VLOOKUP(LinkTable6789[[#This Row],[Coluna1]],[4]AlarmCatalog!$A:$M,11,FALSE)
A348: null@null___NORMAL@INCOMPLETA___Custom_S_TS_SA | C348: Transit;NORMAL;INCOMPLETA;Error | D348: 0;1;2;3 | E348: 2;0;1;3 | F348: ;;; | G348: #FF000000;#FF00FF00;#FFFF0000;#FFA9A9A9 | H348: Abnormal;Auto;Auto;Abnormal | I348: FALSE;TRUE;TRUE;FALSE | J348: Alarme de Estado em Ponto Telessinalizado SA | K348: Alarme de Estado em Ponto Telessinalizado SA | L348: =VLOOKUP(LinkTable6789[[#This Row],[Coluna1]],[4]AlarmCatalog!$A:$M,11,FALSE)
A349: INCLUIR@EXCLUIR___INCLUIDO@EXCLUIDO___Custom_S_TC | C349: Transit;INCLUIDO;EXCLUIDO;Error | D349: 0;1;2;3 | E349: 2;0;1;3 | F349: ;INCLUIR;EXCLUIR; | G349: #FF000000;#FFFF0000;#FF00FF00;#FFA9A9A9 | H349: Abnormal;Auto;Auto;Abnormal | I349: FALSE;TRUE;TRUE;FALSE | J349: Alarme de Estado em Ponto Telecontrolado | K349: Alarme de Estado em Ponto Telecontrolado | L349: =VLOOKUP(LinkTable6789[[#This Row],[Coluna1]],[4]AlarmCatalog!$A:$M,11,FALSE)
...

Sheet MANUT_DiscreteSignals
A1: SINAL | B1: DESCRIÇÃO NOVA | C1: SIGNAL TYPE | D1: TYPE SEVERIDADE | E1: FUNÇÃO | F1: EA | G1: PE | H1: Sinal | I1: Coordenada
A2: 79_L | B2: 79 - RELIGAMENTO LOCAL | C2: Custom | D2: PROT | E2: Transit;NORMAL;ATUADO;Error | F2: CAX; PMI | H2: CLA_AL11_52-3_79_L; BGA_AL11_52-9_79_L | I2: 34502; 34672
A3: J124 | B3: AJUSTE PARA AL1 OU AL2 OU AL4 | C3: Custom | D3: ALARMES PREDIAIS/VF/GRUPO | E3: Transit;DESABILITADO;HABILITADO;Error | F3: VAI | G3: Confirmar o funcionamento. | H3: ENA_TRF2_24-2_J124 | I3: 632
A4: SF6I | B4: INIBIR TRIP POR BAIXA PRESSAO SF6 | C4: Custom | D4: FUNCÕES/43/PARALELISMO | E4: Transit;NORMAL;INIBIDO;Error | F4: VAI | G4: Confirmar o funcionamento. Função inibe o trip por SF6? | H4: ETB_AL11_52-13_SF6I; ETB_AL21_52-12_SF6I | I4: 508; 547
A5: PARALELO | B5: PARALELO | C5: Parallel | D5: FUNCÕES/43/PARALELISMO | E5: Transit;DESATIVADO;ATIVADO;Error | F5: VAI | G5: Confirmar o funcionamento; ponto diferente do padrão. | H5: VNB_TR1_TR1_PARALELO | I5: 266
A6: R90E | B6: RELE 90 EMERGENCIAL | C6: Custom | D6: FUNCÕES/43/PARALELISMO | E6: Transit;INCLUIDO;EXCLUIDO;Error | F6: SMA; ALE | G6: Confirmar o funcionamento. | H6: SSP_TR1_TR1_R90E; SNA_TR2AT_TR2AT_R90E; SGB_TR1AT_52-2_R90E; SFA_TR2AT_TR2AT_R90E; IQB_TR1_TR1_R90E | I6: 170; 847; 664; 152; 652
A7: 90PI | B7: RELE PARALELISMO | C7: Custom | D7: FUNCÕES/43/PARALELISMO | E7: Transit;PARALELO;INDIVIDUAL;Error | F7: SLE | G7: Confirmar o funcionamento. | H7: GTA_TR3_TR3_90PI | I7: 9320
A8: FCMC | B8: FALHA COMUNICACAO MULTIMEDIDOR | C8: Custom | D8: FALHAS FCOM/VCA/VCC | E8: Transit;NORMAL;FALHA;Error | F8: VAI | G8: Confirmar o funcionamento. | H8: ENA_TR1_TR1_FCMC; VNB_TR2_TR2_FCMC | I8: 103; 270
A9: M69C | B9: DJAUX 69 PAINEL | C9: Custom | D9: FALHAS FCOM/VCA/VCC | E9: Transit;LIGADO;DESLIGADO;Error | F9: Automação | G9: Alterar o nome do sinal | I9: OK
A10: MDP1 | B10: DJAUX TP BARRA P1 PAINEL | C10: Custom | D10: FALHAS FCOM/VCA/VCC | E10: Transit;LIGADO;DESLIGADO;Error | F10: Automação | G10: Alterar o nome do sinal | I10: OK
A11: MDP2 | B11: DJAUX TP BARRA P2 PAINEL | C11: Custom | D11: FALHAS FCOM/VCA/VCC | E11: Transit;LIGADO;DESLIGADO;Error | F11: Automação | G11: Alterar o nome do sinal | I11: OK
A12: MDTP1 | B12: DJAUX TP PATIO BARRAP1 | C12: Custom | D12: FALHAS FCOM/VCA/VCC | E12: Transit;LIGADO;DESLIGADO;Error | F12: Automação | G12: Alterar o nome do sinal | I12: OK
A13: MDTP2 | B13: DJAUX TP PATIO BARRAP2 | C13: Custom | D13: FALHAS FCOM/VCA/VCC | E13: Transit;LIGADO;DESLIGADO;Error | F13: Automação | G13: Alterar o nome do sinal | I13: OK
A14: MINC | B14: MINC | C14: Custom | D14: FUNCÕES/43/PARALELISMO | E14: Transit;NORMAL;ATUADO;Error | F14: PFU | G14: Confirmar o funcionamento. | H14: LT800_KECENG_89-2_MINC | I14: 26
A15: VF1I | B15: CHAVE VF1 PRIORITARIO | C15: Custom | D15: FUNCÕES/43/PARALELISMO | E15: Transit;INCLUIDO;EXCLUIDO;Error | F15: CAX | G15: Confirmar o funcionamento. | H15: CXC_TR1_TR1_VF2I; FEL_TR1_TR1_VF2I | I15: 22225; 573
A16: VF1L | B16: CHAVE VF1 POSICAO LOCAL | C16: Custom | D16: FUNCÕES/43/PARALELISMO | E16: Transit;REMOTO;LOCAL;Error | F16: CAX | G16: Confirmar o funcionamento. | H16: VAC_TR1_TR1_VF1L | I16: 16080
A17: VF2I | B17: CHAVE VF2 PRIORITARIO | C17: Custom | D17: FUNCÕES/43/PARALELISMO | E17: Transit;INCLUIDO;EXCLUIDO;Error | F17: CAX | G17: Confirmar o funcionamento. | H17: CXC_TR1_TR1_VF1I; FEL_TR1_TR1_VF1I | I17: 22224; 572
A18: VF2L | B18: CHAVE VF2 POSICAO LOCAL | C18: Custom | D18: FUNCÕES/43/PARALELISMO | E18: Transit;REMOTO;LOCAL;Error | F18: CAX | G18: Confirmar o funcionamento. | H18: TCO_TR2_TR2_VF2L | I18: 16081
A19: 50CD | B19: 50 - SOBRECORRENTE CDC | C19: RelayTrip | D19: PROT | E19: Transit;NORMAL;ATUADO;Error | F19: CAX; ALE | G19: Confirmar o funcionamento. | H19: GMB_TR1_TR1_A_50CD; URI_TR1_TR1_50CD | I19: 471; 227
A20: MTRF | B20: MODULO TRANSFERIDO | C20: Custom | D20: FUNCÕES/43/PARALELISMO | E20: Transit;NORMAL;ATUADO;Error | F20: SMA; PFU | G20: Confirmar o funcionamento. | H20: SMB_LTFXA_LTFXA_MTRF; THA_LTKSM_LTKSM_MTRF | I20: 443; 316
A21: CMDE | B21: PROPRIEDADE DO COMANDO | C21: Custom | D21: ALARMES PREDIAIS/VF/GRUPO | E21: Transit;CEEE;RGE;Error | F21: Automação | G21: Alterar o MM | H21: ERN

Sheet Manut_AnalogSignals
A1: SINAL | B1: DESCRIÇÃO NOVA | C1: Pendência
A2: BIHI | B2: TENSAO DE REFERENCIA ALTA AUXILIAR | C2: Confirmar o funcionamento.
A3: BILO | B3: TENSAO DE REFERENCIA BAIXA AUXILIAR | C3: Confirmar o funcionamento.
A4: I2 | C4: Confirmar o funcionamento.
A5: PCVA | C5: Confirmar o funcionamento.
A6: RTC | C6: Confirmar o funcionamento.
A7: VABL | C7: trocar pra v
A8: VAUX | C8: trocar pra vca
A9: VCA | B9: TENSAO CORRENTE ALTERNADA | C9: trocar para V, nos TSA
A10: VCC1 | B10: TENSAO CORRENTE CONTINUA 1 | C10: ver na UTR
A11: VCC2 | B11: TENSAO CORRENTE CONTINUA 2
A12: FUGA | B12: FUGA A TERRA | C12: Confirmar o funcionamento.
